Workbook
Name cfg_AboveOptimumRatio: _CONFIG_Model_Settings!$B$24
Name cfg_CrisisHighCut: _CONFIG_Model_Settings!$B$17
Name cfg_CrisisMedCut: _CONFIG_Model_Settings!$B$18
Name cfg_IndPriorityHigh: _CONFIG_Model_Settings!$B$19
Name cfg_IndPriorityLow: _CONFIG_Model_Settings!$B$20
Name cfg_RiskFitScale: _CONFIG_Model_Settings!$B$26
Name cfg_RiskSecondaryWeight: _CONFIG_Model_Settings!$B$25
Name cfg_ScenarioFitScale: _CONFIG_Model_Settings!$B$27
Name cfg_TimelineBucket1: _CONFIG_Model_Settings!$B$21
Name cfg_TimelineBucket2: _CONFIG_Model_Settings!$B$22
Name cfg_TimelineBucket3: _CONFIG_Model_Settings!$B$23
Name qn_AssessConf: _DATA_Assessment_Model!$AI$5:$AI$428
Name qn_Comments: _DATA_Assessment_Model!$U$5:$U$428
Name qn_Coverage: _DATA_Assessment_Model!$AU$5:$AU$428
Name qn_Domain: _DATA_Assessment_Model!$AW$5:$AW$428
Name qn_EvidConf: _DATA_Assessment_Model!$AH$5:$AH$428
Name qn_RiskLevel: _DATA_Assessment_Model!$L$5:$L$428
Name qn_Score: _DATA_Assessment_Model!$H$5:$H$428

Sheet ① START HERE
A1: RR-framework v1.992 — Logic Engine Template
A2: Clean workbook architecture: user inputs, consolidated outputs, engine/data layers and incremental safe staging cleanup. | B2: RR-framework v1.992 — crisis/fuzzy staging refactor; clean 20-sheet architecture for Excel logic prototype and future web app backend design.
A4: Recommended flow | B4: Sheet | C4: Purpose
A5: 1 | B5: Company Profile | C5: Enter company context: industry, size, geography, revenue model, critical dependencies.
A6: 2 | B6: Assessment Questions | C6: Complete 424-question assessment. This is the main input source for AS-IS and risk logic.
A7: 3 | B7: AS-IS Assessment | C7: Current state: maturity, diagnostics, gaps and domain-level view.
A8: 4 | B8: Resilience & Risk Scenario | C8: Scenario-adjusted state: crisis, fuzzy posture, resilience and risks.
A9: 5 | B9: Action Plan & Roadmap | C9: What to do next: recommendations, initiatives, P2 WSJF and roadmap waves.
A10: 6 | B10: Model Calibration | C10: Admin/consultant controls and parameter guidance.
A12: Visible sheets in v1.992 | B12: ① START HERE; Release & QA; Methodology, Controls & Std; Company Profile; Assessment Questions; AS-IS Assessment; Resilience & Risk Scenario; Action Plan & Roadmap; Model Calibration
A13: Legacy handling | B13: Legacy presentation/staging tabs have been removed. Consolidated visible workflow sheets now read from hidden data/engine/config layers.
A14: Architecture rule | B14: Visible layer = workflow. Hidden/veryHidden layers = source of truth, engines and configuration.
A18: Current architecture note | B18: v1.99 removes the redundant Executive Dashboard staging sheet. Consolidated visible sheets remain the workflow layer; hidden/veryHidden sheets hold data, config, staging and calculation engines.

Sheet Release & QA
A1: RR-framework v1.992 — Crisis/Fuzzy Staging Refactor
A2: Release status | B2: Clean template / calculation logic preserved / final crisis-fuzzy staging sheet removed
A3: Release status | B3: v1.992
A4: Build ID | B4: RR-FRAMEWORK-v1.992-CRISIS-FUZZY-STAGING-REFACTOR-20260619
A5: Current workbook architecture | B5: 20 sheets: 9 visible workflow sheets, 7 hidden data/config/helper sheets, 4 veryHidden engine sheets.
A6: Calculation policy | B6: Crisis scenario, fuzzy posture and crisis-domain multipliers now read from visible workflow inputs and engine/data layers; full recalculation on open is preserved.
A7: v1.992 refactor summary
A8: Change | B8: Status | C8: Notes
A9: Backlog | B9: Next architecture target: regression-test v1.992 against v1.81/v1.93 and consider optional final cleanup of any non-formula text references or unused hidden helper ranges. | C9: All legacy output/staging sheets have now been removed or absorbed into engine/data layers.
A10: Visible action layer switched to direct engine output | B10: Removed redundant scoring staging sheet; preserved AS-IS calculations through a hidden refactored scoring helper block in _DATA_Dashboard_Facts. | C10: Action Plan & Roadmap now owns initiative status input and reads initiative ranking directly from _ENGINE_Initiatives.
A11: Legacy roadmap staging removed | C11: No formulas, charts or workbook relationships reference Roadmap & Portfolio.
A12: Legacy AS-IS dashboard cleanup | C12: Executive Dashboard and AS-IS scoring staging removed. Crisis/Resilience/Fuzzy retained temporarily as calculation staging only.
A14: Backlog ID | B14: Backlog item | C14: Target release | D14: Acceptance criteria
A15: B-LEGACY-001 | B15: Completed: redundant Executive Dashboard removed after AS-IS Assessment was redirected to _DATA_Dashboard_Facts / engines. | C15: v1.99 done | D15: No formulas reference Executive Dashboard.
A16: B-LEGACY-002 | B16: Completed: Risk & Recommendations refactored into _ENGINE_Risk / _DATA_Mappings and removed. | C16: v1.97 done | D16: Risk-output, recommendation and strategy dependencies migrated before deletion.
A17: B-LEGACY-003 | B17: Completed: Roadmap & Portfolio removed after Action Plan & Roadmap took ownership of action/status workflow. | C17: v1.98 done | D17: Legacy sheet physically removed; Action Plan & Roadmap owns status/action workflow.
A18: B-ARCH-004 | B18: Migrate remaining crisis/resilience/fuzzy staging dependencies into engine/data layers; then move major backend tables to structured tables / ID-driven formulas. | C18: future | D18: Reduced row-offset risk and simpler web-app migration.
A20: QA check | B20: Expected result
A21: XLSX structure | B21: Valid workbook relationships and content types.
A22: Formula errors | B22: No #REF!, #DIV/0!, #VALUE!, #NAME? or #N/A tokens in formulas.
A23: Visible user flow | B23: 9 visible sheets; redundant Executive Dashboard removed; remaining staging tabs are hidden only because active formulas still depend on them.
A24: Recalculation | B24: Full recalculation on open preserved.

Sheet Methodology, Controls & Std
A1: Methodology, Controls & Standards — v1.992
A2: Current-state documentation for the consolidated logic prototype. This workbook is the calculation/methodology layer for the future web app; visual UX will be implemented in the web product. | B2: Current-state methodology for v1.992: 20-sheet architecture with crisis/fuzzy staging migrated into engine/data layers.
A3: Current calculation architecture | B3: AS-IS, crisis/fuzzy, risk, recommendation and roadmap logic now flow through consolidated visible workflow sheets and hidden engine/data layers without legacy presentation staging tabs.
A4: Layer | B4: Visible sheet / engine | C4: Purpose
A5: Risk engine | B5: _DATA_Assessment_Model, _DATA_Dashboard_Facts and _DATA_Mappings provide the normalized data layer for company profile, assessment and output facts. | C5: Capture company context and 424-question assessment data.
A6: Strategy engine | B6: _ENGINE_Risk, _ENGINE_Strategy and _ENGINE_Initiatives are the sources for risk outputs, strategy scoring, recommendations, initiative prioritization and roadmap logic. | C6: Combines executive summary and diagnostics into one current-state assessment layer.
A7: Scenario-adjusted state | B7: Resilience & Risk Scenario | C7: Combines crisis selection, resilience, fuzzy posture and risk exposure into one state interpretation layer.
A8: Action layer | B8: Action Plan & Roadmap | C8: Combines recommendations, initiatives, P2 WSJF and roadmap waves into one execution layer.
A9: Calibration | B9: Model Calibration; _CONFIG_Model_Settings; _CONFIG_Risk_Calibration | C9: Keeps visible controls separate from hidden source-of-truth parameters.
A10: Risk engine | B10: _ENGINE_Risk | C10: Calculates risk states, impact/probability, P1-adjusted risk score and now hosts the consolidated risk-output block used by visible scenario/action sheets.
A11: Initiative engine | B11: _ENGINE_Initiatives | C11: Calculates initiative value, risk reduction, P2 WSJF v3, rank and roadmap wave.
A12: Crisis/fuzzy engine | B12: _ENGINE_Crisis and _ENGINE_Fuzzy_Posture model crisis multipliers, cascade pressure, fuzzy membership and strategic posture. Scenario inputs are owned by Resilience & Risk Scenario. | C12: Models crisis multipliers, cascade pressure and fuzzy strategic posture.
A14: Fuzzy logic summary | B14: Fuzzy logic is an interpretation and prioritization-weighting layer. It converts maturity/risk pressure into membership across Fragile, Exposed, Adaptive, Resilient and Anti-fragile states. It does not overwrite baseline risk scores.
A15: Risk logic summary | B15: Baseline probability/impact are enhanced by P1 calibration: exposure, incident history, evidence uncertainty, dependency/cascade and red-line logic.
A16: WSJF logic summary | B16: P2 WSJF v3 uses fuzzy posture, client objective multipliers, financial value and risk-reduction pressure to prioritize initiatives.
A17: Governance rule | B17: One source of truth per parameter. Visible sheets may summarize or reference parameters, but hidden config/engine sheets own the calculation inputs.
A18: Legacy backlog rule | B18: Legacy deletion rule: physically remove staging sheets only after formulas are rewritten to engine/data layers and audit confirms zero remaining references.

Sheet Company Profile
A1: Company Profile — Assessment Context
A2: Fill this once per organization. This clean template contains no client/test profile data; profile answers drive targets, risk context, crisis interpretation and roadmap priorities.
A3: =HYPERLINK("#'① START HERE'!A1","⌂ START HERE") | C3: ✎ Input: edit coloured cells only — everything else is formula-driven.
A4: Profile field | B4: Value / input | C4: Guidance | D4: Used by | F4: How this sheet is used
A5: Organization name | C5: Legal or commercial name used in the assessment. | D5: Dashboard / executive summary | F5: 1. Define organization context and assessment boundaries. 2. Use Crisis Simulator for active scenario and severity. 3. Use Assessment date as the roadmap start date. 4. Use target scores to calibrate expected maturity level. 5. Keep LLM and financial analysis outside this workbook version.
A6: Assessment date | B6: =TODAY() | C6: Baseline date. Defaults to TODAY() and can be replaced by the actual assessment date. | D6: Gantt Roadmap
A7: Assessment owner | C7: Person responsible for coordinating the assessment. | D7: Quality Control
A8: Executive sponsor | C8: Senior owner who accepts priorities and crisis roadmap. | D8: Roadmap governance
A9: Industry | C9: Primary industry or sector. | D9: Strategy logic
A10: Sub-industry / segment | C10: More specific segment, e.g. manufacturing, SaaS, retail, healthcare. | D10: Strategy logic
A11: Headquarters country | C11: Country where the main legal or management entity is located. | D11: Risk context
A12: Operating countries / regions | C12: List countries, regions and key cities where the company operates. | D12: Geographical exposure
A13: Ownership type | C13: Private, public, state-owned, family-owned, PE-backed, NGO or other. | D13: Governance context
A14: Legal entities | C14: Main legal entities and subsidiaries. | D14: Legal / continuity context
A15: Employee count | C15: Total employees and contractors. | D15: HR / continuity logic
A16: Revenue size band | C16: Annual revenue band. | D16: Financial context, not calculation
A17: Operating model | C17: Centralized, decentralized, hub-and-spoke, remote-first, multi-site, franchise, hybrid. | D17: Crisis exposure
A18: Business model | C18: B2B, B2C, B2B2C, marketplace, subscription, project-based, manufacturing, distribution. | D18: GTM / resilience logic
... A28: Cloud and infrastructure model | C28: On-premise, public cloud, private cloud, hybrid, multi-cloud, SaaS-first. | D28: IT / DR strategy
A29: Primary crisis scenario to test | B29: ='Resilience & Risk Scenario'!$B$6 | C29: Active scenario is selected in Crisis Simulator. | D29: Crisis Simulator
A30: Scenario severity 1-5 | B30: ='Resilience & Risk Scenario'!$B$7 | C30: Active scenario severity is selected in Crisis Simulator. | D30: Crisis Simulator
A31: Target process maturity 0-5 | C31: Target level for process maturity. | D31: Gap analysis
A32: Target digitalization 0-5 | C32: Target level for implementation of digital technologies. | D32: Gap analysis
A33: Target resilience 0-5 | C33: Target level for resilience against relevant risks. | D33: Gap analysis
A34: Assessment cadence | C34: Quarterly, semi-annual, annual, or crisis-triggered review. | D34: Governance
A35: Risk appetite statement | C35: Closed choice: Low / Balanced / High. Low = risk-averse (targets tightened), High = more residual risk accepted (targets relaxed). Adjusts industry maturity targets across the model via _CONFIG_Model_Settings. | D35: Risk treatment
A36: Key assumptions / comments | C36: Context notes, assumptions, excluded scope or special assessment limitations. Leave blank until the real assessment is configured. | D36: All outputs
A38: Industry Template and Improved Scoring Logic
A39: Selected industry template | B39: =B9 | C39: Used as lookup key for domain weights, targets, criticality and recommendations.
A40: Default evidence confidence | B40: Medium | C40: Used when question-level evidence confidence is blank.
A41: Default assessor confidence | B41: Medium | C41: Used when question-level assessor confidence is blank.
A42: Template domains | B42: =COUNTIF(_REF_Model_Content!$A$1:$A$157,$B$9) | C42: Should equal 17 for a valid industry template.
A43: Average target maturity | B43: =IFERROR(ROUND(AVERAGEIFS(_REF_Model_Content!$D$1:$D$157,_REF_Model_Content!$A$1:$A$157,$B$9),2),"") | C43: Average expected maturity for selected industry.
A44: Average criticality multiplier | B44: =IFERROR(ROUND(AVERAGEIFS(_REF_Model_Content!$E$1:$E$157,_REF_Model_Content!$A$1:$A$157,$B$9),2),"") | C44: Higher value means industry makes weaknesses more material.
A45: Critical systems | B45: =IFERROR(INDEX(_REF_Model_Content!$H$1:$H$157,MATCH($B$9,_REF_Model_Content!$A$1:$A$157,0)),"") | C45: Typical systems that should be treated as critical for this industry.
A46: Red-line controls | B46: =IFERROR(INDEX(_REF_Model_Content!$I$1:$I$157,MATCH($B$9,_REF_Model_Content!$A$1:$A$157,0)),"") | C46: Minimum controls that should not be missing even if average maturity looks acceptable.
A47: Preferred strategy logic | B47: =IFERROR(INDEX(_REF_Model_Content!$L$1:$L$157,MATCH($B$9,_REF_Model_Content!$A$1:$A$157,0)),"") | C47: Strategies that receive extra relevance for this industry.
A49: Extended Company Context Inputs (closed answers only)
A50: Revenue model | C50: Primary revenue model used by the company. | D50: Risk, strategy and initiative logic
A51: Secondary revenue model | C51: Secondary or supporting monetization model. | D51: Revenue diversification logic
...

Sheet Assessment Questions
A1: Assessment Questions — Consolidated Input
A2: Main assessment surface with all 424 questions. Use green/input columns for answers, evidence confidence, coverage, owners and comments.
A3: =HYPERLINK("#'① START HERE'!A1","⌂ START HERE") | C3: ✎ Input: edit answer / confidence / comment columns only — the rest is formula-driven.
A4: Domain | B4: Source sheet | C4: Source row | D4: ID | E4: Subdomain | F4: Question | G4: Crisis relevance / why it matters | H4: Standards / frameworks | I4: Evidence to request | J4: Weight 1-5 | K4: Score 0-5 (auto from answer) | L4: Weighted score | M4: Max score | N4: Gap | O4: Risk level | P4: Score 0 criteria | Q4: Score 1 criteria | R4: Score 2 criteria | S4: Score 3 criteria | T4: Score 4 criteria | U4: Score 5 criteria | V4: Crisis scenario tags | W4: Owner / SME | X4: Comments / findings | Y4: Recommended action | Z4: Digitalization relevance 0-5 | AA4: Resilience relevance 0-5 | AB4: Process maturity relevance 0-5 | AC4: Answer - select stage | AD4: Subarea | AE4: Questions | AF4: Avg score 0-5 | AG4: Maturity % | AH4: Critical/High | AI4: Gap to 5 | AJ4: Answered | AK4: Evidence confidence | AL4: Assessor confidence | AM4: Evidence factor | AN4: Assessor factor | AO4: Confidence-adjusted score 0-5 | AP4: Normalized score 0-100 | AQ4: Industry target 0-5 | AR4: Gap to industry target | AS4: Industry criticality multiplier | AT4: Industry-adjusted gap priority | AU4: Improved scoring note | AV4: v2 conf-adj score | AW4: v2 conf factor | AX4: Coverage (how widely deployed) | AY4: Coverage factor
A5: Company Geography | B5: Company Geography | C5: 5 | D5: COMP-001 | E5: Company profile | F5: How mature is the organization in managing legal entity structure, ownership, subsidiaries and operating countries, including ownership, evidence, metrics, fallback procedures and crisis stress testing? | G5: This topic affects exposure to Geopolitical risk; Physical site loss; Regulatory/legal shock. It helps identify how disruption may impact operations, people, revenue, systems, legal exposure or recovery time. | H5: ISO 22301; ISO 31000; ISO 9001; ISO 37000; PESTLE; Business Model Canvas | I5: Policy/SOP; owner/RACI; system report; dashboard; contracts; test records; incident history; interview evidence related to legal entity structure, ownership, subsidiaries and operating countries. | J5: 3 | K5: =_DATA_Assessment_Model!H5 | L5: =_DATA_Assessment_Model!I5 | M5: =_DATA_Assessment_Model!J5 | N5: =_DATA_Assessment_Model!K5 | O5: =_DATA_Assessment_Model!L5 | P5: No reliable evidence that legal entity structure, ownership, subsidiaries and operating countries is defined, owned or managed. | Q5: Legal entity structure, ownership, subsidiaries and operating countries is handled informally and depends on individual knowledge or heroic effort. | R5: Legal entity structure, ownership, subsidiaries and operating countries is partially documented or implemented, but coverage is inconsistent and not crisis-tested. | S5: Legal entity structure, ownership, subsidiaries and operating countries is documented, owned, used in normal operations and supported by basic evidence or metrics. | T5: Legal entity structure, ownership, subsidiaries and operating countries is measured, periodically reviewed, integrated with related processes and tested against relevant disruption scenarios. | U5: Legal entity structure, ownership, subsidiaries and operating countries is optimized, continuously improved, automated where practical and demonstrably supports crisis resilience. | V5: Geopolitical risk; Physical site loss; Regulatory/legal shock | Y5: Use the recommended action generated by the model; validate with domain owner during real assessment. | Z5: 4 | AA5: 5 | AB5: 5 | AD5: Company profile | AE5: =_DATA_Assessment_Model!AB5 | AF5: =_DATA_Assessment_Model!AC5 | AG5: =_DATA_Assessment_Model!AD5 | AH5: =_DATA_Assessment_Model!AE5 | AI5: =_DATA_Assessment_Model!AF5 | AJ5: =_DATA_Assessment_Model!AG5 | AM5: =_DATA_Assessment_Model!AJ5 | AN5: =_DATA_Assessment_Model!AK5 | AO5: =_DATA_Assessment_Model!AL5 | AP5: =_DATA_Assessment_Model!AM5 | AQ5: =_DATA_Assessment_Model!AN5 | AR5: =_DATA_Assessment_Model!AO5 | AS5: =_DATA_Assessment_Model!AP5 | AT5: =_DATA_Assessment_Model!AQ5 | ... AW5: =_DATA_Assessment_Model!AT5 | AY5: =_DATA_Assessment_Model!AV5
A6: Company Geography | B6: Company Geography | C6: 6 | D6: COMP-002 | E6: Company profile | F6: How mature is the organization in managing business model, value proposition, revenue streams and cost drivers, including ownership, evidence, metrics, fallback procedures and crisis stress testing? | G6: This topic affects exposure to Geopolitical risk; Physical site loss; Regulatory/legal shock. It helps identify how disruption may impact operations, people, revenue, systems, legal exposure or recovery time. | H6: ISO 22301; ISO 31000; ISO 9001; ISO 37000; PESTLE; Business Model Canvas | I6: Policy/SOP; owner/RACI; system report; dashboard; contracts; test records; incident history; interview evidence related to business model, value proposition, revenue streams and cost drivers. | J6: 5 | K6: =_DATA_Assessment_Model!H6 | L6: =_DATA_Assessment_Model!I6 | M6: =_DATA_Assessment_Model!J6 | N6: =_DATA_Assessment_Model!K6 | O6: =_DATA_Assessment_Model!L6 | P6: Does not exist; no owner, no documentation, no practice. | Q6: Ad hoc; depends entirely on specific individuals. | R6: Partially documented or implemented; coverage inconsistent; never tested under stress. | S6: Documented, owned, executed consistently; basic evidence and metrics exist. | T6: Measured and periodically tested/audited; integrated with adjacent processes. | U6: Optimized and automated where practical; stress-tested; benchmarked externally. | V6: Geopolitical risk; Physical site loss; Regulatory/legal shock | Y6: Use the recommended action generated by the model; validate with domain owner during real assessment. | Z6: 4 | AA6: 5 | AB6: 5 | AD6: Geographical distribution | AE6: =_DATA_Assessment_Model!AB6 | AF6: =_DATA_Assessment_Model!AC6 | AG6: =_DATA_Assessment_Model!AD6 | AH6: =_DATA_Assessment_Model!AE6 | AI6: =_DATA_Assessment_Model!AF6 | AJ6: =_DATA_Assessment_Model!AG6 | AM6: =_DATA_Assessment_Model!AJ6 | AN6: =_DATA_Assessment_Model!AK6 | AO6: =_DATA_Assessment_Model!AL6 | AP6: =_DATA_Assessment_Model!AM6 | AQ6: =_DATA_Assessment_Model!AN6 | AR6: =_DATA_Assessment_Model!AO6 | AS6: =_DATA_Assessment_Model!AP6 | AT6: =_DATA_Assessment_Model!AQ6 | ... AW6: =_DATA_Assessment_Model!AT6 | AY6: =_DATA_Assessment_Model!AV6
A7: Company Geography | B7: Company Geography | C7: 7 | D7: COMP-003 | E7: Company profile | F7: How mature is the organization in managing critical products and services ranked by revenue, margin and continuity priority, including ownership, evidence, metrics, fallback procedures and crisis stress testing? | G7: This topic affects exposure to Geopolitical risk; Physical site loss; Regulatory/legal shock. It helps identify how disruption may impact operations, people, revenue, systems, legal exposure or recovery time. | H7: ISO 22301; ISO 31000; ISO 9001; ISO 37000; PESTLE; Business Model Canvas | I7: Policy/SOP; owner/RACI; system report; dashboard; contracts; test records; incident history; interview evidence related to critical products and services ranked by revenue, margin and continuity priority. | J7: 5 | K7: =_DATA_Assessment_Model!H7 | L7: =_DATA_Assessment_Model!I7 | M7: =_DATA_Assessment_Model!J7 | N7: =_DATA_Assessment_Model!K7 | O7: =_DATA_Assessment_Model!L7 | P7: Does not exist; no owner, no documentation, no practice. | Q7: Ad hoc; depends entirely on specific individuals. | R7: Partially documented or implemented; coverage inconsistent; never tested under stress. | S7: Documented, owned, executed consistently; basic evidence and metrics exist. | T7: Measured and periodically tested/audited; integrated with adjacent processes. | U7: Optimized and automated where practical; stress-tested; benchmarked externally. | V7: Geopolitical risk; Physical site loss; Regulatory/legal shock | Y7: Use the recommended action generated by the model; validate with domain owner during real assessment. | Z7: 4 | AA7: 5 | AB7: 5 | AD7: Context and dependencies | AE7: =_DATA_Assessment_Model!AB7 | AF7: =_DATA_Assessment_Model!AC7 | AG7: =_DATA_Assessment_Model!AD7 | AH7: =_DATA_Assessment_Model!AE7 | AI7: =_DATA_Assessment_Model!AF7 | AJ7: =_DATA_Assessment_Model!AG7 | AM7: =_DATA_Assessment_Model!AJ7 | AN7: =_DATA_Assessment_Model!AK7 | AO7: =_DATA_Assessment_Model!AL7 | AP7: =_DATA_Assessment_Model!AM7 | AQ7: =_DATA_Assessment_Model!AN7 | AR7: =_DATA_Assessment_Model!AO7 | AS7: =_DATA_Assessment_Model!AP7 | AT7: =_DATA_Assessment_Model!AQ7 | ... AW7: =_DATA_Assessment_Model!AT7 | AY7: =_DATA_Assessment_Model!AV7
A8: Company Geography | B8: Company Geography | C8: 8 | D8: COMP-004 | E8: Company profile | F8: How mature is the organization in managing operating model: centralized, distributed, outsourced, remote or hybrid, including ownership, evidence, metrics, fallback procedures and crisis stress testing? | G8: This topic affects exposure to Geopolitical risk; Physical site loss; Regulatory/legal shock. It helps identify how disruption may impact operations, people, revenue, systems, legal exposure or recovery time. | H8: ISO 22301; ISO 31000; ISO 9001; ISO 37000; PESTLE; Business Model Canvas | I8: Policy/SOP; owner/RACI; system report; dashboard; contracts; test records; incident history; interview evidence related to operating model: centralized, distributed, outsourced, remote or hybrid. | J8: 4 | K8: =_DATA_Assessment_Model!H8 | L8: =_DATA_Assessment_Model!I8 | M8: =_DATA_Assessment_Model!J8 | N8: =_DATA_Assessment_Model!K8 | O8: =_DATA_Assessment_Model!L8 | P8: No reliable evidence that operating model: centralized, distributed, outsourced, remote or hybrid is defined, owned or managed. | Q8: Operating model: centralized, distributed, outsourced, remote or hybrid is handled informally and depends on individual knowledge or heroic effort. | R8: Operating model: centralized, distributed, outsourced, remote or hybrid is partially documented or implemented, but coverage is inconsistent and not crisis-tested. | S8: Operating model: centralized, distributed, outsourced, remote or hybrid is documented, owned, used in normal operations and supported by basic evidence or metrics. | T8: Operating model: centralized, distributed, outsourced, remote or hybrid is measured, periodically reviewed, integrated with related processes and tested against relevant disruption scenarios. | U8: Operating model: centralized, distributed, outsourced, remote or hybrid is optimized, continuously improved, automated where practical and demonstrably supports crisis resilience. | V8: Geopolitical risk; Physical site loss; Regulatory/legal shock | Y8: Use the recommended action generated by the model; validate with domain owner during real assessment. | Z8: 4 | AA8: 5 | AB8: 5 | AM8: =_DATA_Assessment_Model!AJ8 | AN8: =_DATA_Assessment_Model!AK8 | AO8: =_DATA_Assessment_Model!AL8 | AP8: =_DATA_Assessment_Model!AM8 | AQ8: =_DATA_Assessment_Model!AN8 | AR8: =_DATA_Assessment_Model!AO8 | AS8: =_DATA_Assessment_Model!AP8 | AT8: =_DATA_Assessment_Model!AQ8 | ... AW8: =_DATA_Assessment_Model!AT8 | AY8: =_DATA_Assessment_Model!AV8
A9: Company Geography | B9: Company Geography | C9: 9 | D9: COMP-005 | E9: Company profile | F9: How mature is the organization in managing critical assets: people, facilities, systems, data, equipment and intellectual property, including ownership, evidence, metrics, fallback procedures and crisis stress testing? | G9: This topic affects exposure to Geopolitical risk; Physical site loss; Regulatory/legal shock. It helps identify how disruption may impact operations, people, revenue, systems, legal exposure or recovery time. | H9: ISO 22301; ISO 31000; ISO 9001; ISO 37000; PESTLE; Business Model Canvas | I9: Policy/SOP; owner/RACI; system report; dashboard; contracts; test records; incident history; interview evidence related to critical assets: people, facilities, systems, data, equipment and intellectual property. | J9: 5 | K9: =_DATA_Assessment_Model!H9 | L9: =_DATA_Assessment_Model!I9 | M9: =_DATA_Assessment_Model!J9 | N9: =_DATA_Assessment_Model!K9 | O9: =_DATA_Assessment_Model!L9 | P9: Does not exist; no owner, no documentation, no practice. | Q9: Ad hoc; depends entirely on specific individuals. | R9: Partially documented or implemented; coverage inconsistent; never tested under stress. | S9: Documented, owned, executed consistently; basic evidence and metrics exist. | T9: Measured and periodically tested/audited; integrated with adjacent processes. | U9: Optimized and automated where practical; stress-tested; benchmarked externally. | V9: Geopolitical risk; Physical site loss; Regulatory/legal shock | Y9: Use the recommended action generated by the model; validate with domain owner during real assessment. | Z9: 5 | AA9: 5 | AB9: 5 | AM9: =_DATA_Assessment_Model!AJ9 | AN9: =_DATA_Assessment_Model!AK9 | AO9: =_DATA_Assessment_Model!AL9 | AP9: =_DATA_Assessment_Model!AM9 | AQ9: =_DATA_Assessment_Model!AN9 | AR9: =_DATA_Assessment_Model!AO9 | AS9: =_DATA_Assessment_Model!AP9 | AT9: =_DATA_Assessment_Model!AQ9 | ... AW9: =_DATA_Assessment_Model!AT9 | AY9: =_DATA_Assessment_Model!AV9
A10: Company Geography | B10: Company Geography | C10: 10 | D10: COMP-006 | E10: Company profile | F10: How mature is the organization in managing regulatory exposure by country, market, product and customer type, including ownership, evidence, metrics, fallback procedures and crisis stress testing? | G10: This topic affects exposure to Geopolitical risk; Physical site loss; Regulatory/legal shock. It helps identify how disruption may impact operations, people, revenue, systems, legal exposure or recovery time. | H10: ISO 22301; ISO 31000; ISO 9001; ISO 37000; PESTLE; Business Model Canvas | I10: Policy/SOP; owner/RACI; system report; dashboard; contracts; test records; incident history; interview evidence related to regulatory exposure by country, market, product and customer type. | J10: 4 | K10: =_DATA_Assessment_Model!H10 | L10: =_DATA_Assessment_Model!I10 | M10: =_DATA_Assessment_Model!J10 | N10: =_DATA_Assessment_Model!K10 | O10: =_DATA_Assessment_Model!L10 | P10: No reliable evidence that regulatory exposure by country, market, product and customer type is defined, owned or managed. | Q10: Regulatory exposure by country, market, product and customer type is handled informally and depends on individual knowledge or heroic effort. | R10: Regulatory exposure by country, market, product and customer type is partially documented or implemented, but coverage is inconsistent and not crisis-tested. | S10: Regulatory exposure by country, market, product and customer type is documented, owned, used in normal operations and supported by basic evidence or metrics. | T10: Regulatory exposure by country, market, product and customer type is measured, periodically reviewed, integrated with related processes and tested against relevant disruption scenarios. | U10: Regulatory exposure by country, market, product and customer type is optimized, continuously improved, automated where practical and demonstrably supports crisis resilience. | V10: Geopolitical risk; Physical site loss; Regulatory/legal shock | Y10: Use the recommended action generated by the model; validate with domain owner during real assessment. | Z10: 4 | AA10: 5 | AB10: 5 | AM10: =_DATA_Assessment_Model!AJ10 | AN10: =_DATA_Assessment_Model!AK10 | AO10: =_DATA_Assessment_Model!AL10 | AP10: =_DATA_Assessment_Model!AM10 | AQ10: =_DATA_Assessment_Model!AN10 | AR10: =_DATA_Assessment_Model!AO10 | AS10: =_DATA_Assessment_Model!AP10 | AT10: =_DATA_Assessment_Model!AQ10 | ... AW10: =_DATA_Assessment_Model!AT10 | AY10: =_DATA_Assessment_Model!AV10
A11: Company Geography | B11: Company Geography | C11: 11 | D11: COMP-007 | E11: Company profile | F11: How mature is the organization in managing insurance coverage for business interruption, cyber, liability, property and key assets, including ownership, evidence, metrics, fallback procedures and crisis stress testing? | G11: This topic affects exposure to Geopolitical risk; Physical site loss; Regulatory/legal shock. It helps identify how disruption may impact operations, people, revenue, systems, legal exposure or recovery time. | H11: ISO 22301; ISO 31000; ISO 9001; ISO 37000; PESTLE; Business Model Canvas | I11: Policy/SOP; owner/RACI; system report; dashboard; contracts; test records; incident history; interview evidence related to insurance coverage for business interruption, cyber, liability, property and key assets. | J11: 5 | K11: =_DATA_Assessment_Model!H11 | L11: =_DATA_Assessment_Model!I11 | M11: =_DATA_Assessment_Model!J11 | N11: =_DATA_Assessment_Model!K11 | O11: =_DATA_Assessment_Model!L11 | P11: Does not exist; no owner, no documentation, no practice. | Q11: Ad hoc; depends entirely on specific individuals. | R11: Partially documented or implemented; coverage inconsistent; never tested under stress. | S11: Documented, owned, executed consistently; basic evidence and metrics exist. | T11: Measured and periodically tested/audited; integrated with adjacent processes. | U11: Optimized and automated where practical; stress-tested; benchmarked externally. | V11: Geopolitical risk; Physical site loss; Regulatory/legal shock | Y11: Use the recommended action generated by the model; validate with domain owner during real assessment. | Z11: 5 | AA11: 5 | AB11: 5 | AM11: =_DATA_Assessment_Model!AJ11 | AN11: =_DATA_Assessment_Model!AK11 | AO11: =_DATA_Assessment_Model!AL11 | AP11: =_DATA_Assessment_Model!AM11 | AQ11: =_DATA_Assessment_Model!AN11 | AR11: =_DATA_Assessment_Model!AO11 | AS11: =_DATA_Assessment_Model!AP11 | AT11: =_DATA_Assessment_Model!AQ11 | ... AW11: =_DATA_Assessment_Model!AT11 | AY11: =_DATA_Assessment_Model!AV11
A12: Company Geography | B12: Company Geography | C12: 12 | D12: COMP-008 | E12: Geographical distribution | F12: How mature is the organization in managing workforce distribution by country, city, function, contract type and criticality, including ownership, evidence, metrics, fallback procedures and crisis stress testing? | G12: This topic affects exposure to Geopolitical risk; Physical site loss; Regulatory/legal shock. It helps identify how disruption may impact operations, people, revenue, systems, legal exposure or recovery time. | H12: ISO 22301; ISO 31000; ISO 9001; ISO 37000; PESTLE; Business Model Canvas | I12: Policy/SOP; owner/RACI; system report; dashboard; contracts; test records; incident history; interview evidence related to workforce distribution by country, city, function, contract type and criticality. | J12: 5 | K12: =_DATA_Assessment_Model!H12 | L12: =_DATA_Assessment_Model!I12 | M12: =_DATA_Assessment_Model!J12 | N12: =_DATA_Assessment_Model!K12 | O12: =_DATA_Assessment_Model!L12 | P12: Does not exist; no owner, no documentation, no practice. | Q12: Ad hoc; depends entirely on specific individuals. | R12: Partially documented or implemented; coverage inconsistent; never tested under stress. | S12: Documented, owned, executed consistently; basic evidence and metrics exist. | T12: Measured and periodically tested/audited; integrated with adjacent processes. | U12: Optimized and automated where practical; stress-tested; benchmarked externally. | V12: Geopolitical risk; Physical site loss; Regulatory/legal shock | Y12: Use the recommended action generated by the model; validate with domain owner during real assessment. | Z12: 4 | AA12: 5 | AB12: 5 | AM12: =_DATA_Assessment_Model!AJ12 | AN12: =_DATA_Assessment_Model!AK12 | AO12: =_DATA_Assessment_Model!AL12 | AP12: =_DATA_Assessment_Model!AM12 | AQ12: =_DATA_Assessment_Model!AN12 | AR12: =_DATA_Assessment_Model!AO12 | AS12: =_DATA_Assessment_Model!AP12 | AT12: =_DATA_Assessment_Model!AQ12 | ... AW12: =_DATA_Assessment_Model!AT12 | AY12: =_DATA_Assessment_Model!AV12
A13: Company Geography | B13: Company Geography | C13: 13 | D13: COMP-009 | E13: Geographical distribution | F13: How mature is the organization in managing site distribution across offices, plants, warehouses, stores, labs and data centers, including ownership, evidence, metrics, fallback procedures and crisis stress testing? | G13: This topic affects exposure to Geopolitical risk; Physical site loss; Regulatory/legal shock. It helps identify how disruption may impact operations, people, revenue, systems, legal exposure or recovery time. | H13: ISO 22301; ISO 31000; ISO 9001; ISO 37000; PESTLE; Business Model Canvas | I13: Policy/SOP; owner/RACI; system report; dashboard; contracts; test records; incident history; interview evidence related to site distribution across offices, plants, warehouses, stores, labs and data centers. | J13: 5 | K13: =_DATA_Assessment_Model!H13 | L13: =_DATA_Assessment_Model!I13 | M13: =_DATA_Assessment_Model!J13 | N13: =_DATA_Assessment_Model!K13 | O13: =_DATA_Assessment_Model!L13 | P13: No plan or procedure exists. | Q13: Knowledge lives with individuals; nothing usable is written down. | R13: Drafted but outdated, not approved, or unknown to the people who must use it. | S13: Approved and current; owners assigned; affected staff know it exists and where to find it. | T13: Tested against realistic scenarios; updated after each test or real incident. | U13: Exercised regularly including external parties; readiness measured; continuously improved. | V13: Geopolitical risk; Physical site loss; Regulatory/legal shock | Y13: Use the recommended action generated by the model; validate with domain owner during real assessment. | Z13: 5 | AA13: 5 | AB13: 5 | AM13: =_DATA_Assessment_Model!AJ13 | AN13: =_DATA_Assessment_Model!AK13 | AO13: =_DATA_Assessment_Model!AL13 | AP13: =_DATA_Assessment_Model!AM13 | AQ13: =_DATA_Assessment_Model!AN13 | AR13: =_DATA_Assessment_Model!AO13 | AS13: =_DATA_Assessment_Model!AP13 | AT13: =_DATA_Assessment_Model!AQ13 | ... AW13: =_DATA_Assessment_Model!AT13 | AY13: =_DATA_Assessment_Model!AV13
A14: Company Geography | B14: Company Geography | C14: 14 | D14: COMP-010 | E14: Geographical distribution | F14: How mature is the organization in managing revenue distribution by country, currency, customer geography and market exposure, including ownership, evidence, metrics, fallback procedures and crisis stress testing? | G14: This topic affects exposure to Geopolitical risk; Physical site loss; Regulatory/legal shock. It helps identify how disruption may impact operations, people, revenue, systems, legal exposure or recovery time. | H14: ISO 22301; ISO 31000; ISO 9001; ISO 37000; PESTLE; Business Model Canvas | I14: Policy/SOP; owner/RACI; system report; dashboard; contracts; test records; incident history; interview evidence related to revenue distribution by country, currency, customer geography and market exposure. | J14: 4 | K14: =_DATA_Assessment_Model!H14 | L14: =_DATA_Assessment_Model!I14 | M14: =_DATA_Assessment_Model!J14 | N14: =_DATA_Assessment_Model!K14 | O14: =_DATA_Assessment_Model!L14 | P14: No reliable evidence that revenue distribution by country, currency, customer geography and market exposure is defined, owned or managed. | Q14: Revenue distribution by country, currency, customer geography and market exposure is handled informally and depends on individual knowledge or heroic effort. | R14: Revenue distribution by country, currency, customer geography and market exposure is partially documented or implemented, but coverage is inconsistent and not crisis-tested. | S14: Revenue distribution by country, currency, customer geography and market exposure is documented, owned, used in normal operations and supported by basic evidence or metrics. | T14: Revenue distribution by country, currency, customer geography and market exposure is measured, periodically reviewed, integrated with related processes and tested against relevant disruption scenarios. | U14: Revenue distribution by country, currency, customer geography and market exposure is optimized, continuously improved, automated where practical and demonstrably supports crisis resilience. | V14: Geopolitical risk; Physical site loss; Regulatory/legal shock | Y14: Use the recommended action generated by the model; validate with domain owner during real assessment. | Z14: 4 | AA14: 5 | AB14: 5 | AM14: =_DATA_Assessment_Model!AJ14 | AN14: =_DATA_Assessment_Model!AK14 | AO14: =_DATA_Assessment_Model!AL14 | AP14: =_DATA_Assessment_Model!AM14 | AQ14: =_DATA_Assessment_Model!AN14 | AR14: =_DATA_Assessment_Model!AO14 | AS14: =_DATA_Assessment_Model!AP14 | AT14: =_DATA_Assessment_Model!AQ14 | ... AW14: =_DATA_Assessment_Model!AT14 | AY14: =_DATA_Assessment_Model!AV14
A15: Company Geography | B15: Company Geography | C15: 15 | D15: COMP-011 | E15: Geographical distribution | F15: How mature is the organization in managing supplier distribution by country, tier, criticality and replacement options, including ownership, evidence, metrics, fallback procedures and crisis stress testing? | G15: This topic affects exposure to Geopolitical risk; Physical site loss; Regulatory/legal shock. It helps identify how disruption may impact operations, people, revenue, systems, legal exposure or recovery time. | H15: ISO 22301; ISO 31000; ISO 9001; ISO 37000; PESTLE; Business Model Canvas | I15: Policy/SOP; owner/RACI; system report; dashboard; contracts; test records; incident history; interview evidence related to supplier distribution by country, tier, criticality and replacement options. | J15: 5 | K15: =_DATA_Assessment_Model!H15 | L15: =_DATA_Assessment_Model!I15 | M15: =_DATA_Assessment_Model!J15 | N15: =_DATA_Assessment_Model!K15 | O15: =_DATA_Assessment_Model!L15 | P15: Does not exist; no owner, no documentation, no practice. | Q15: Ad hoc; depends entirely on specific individuals. | R15: Partially documented or implemented; coverage inconsistent; never tested under stress. | S15: Documented, owned, executed consistently; basic evidence and metrics exist. | T15: Measured and periodically tested/audited; integrated with adjacent processes. | U15: Optimized and automated where practical; stress-tested; benchmarked externally. | V15: Geopolitical risk; Physical site loss; Regulatory/legal shock | Y15: Use the recommended action generated by the model; validate with domain owner during real assessment. | Z15: 4 | AA15: 5 | AB15: 5 | AM15: =_DATA_Assessment_Model!AJ15 | AN15: =_DATA_Assessment_Model!AK15 | AO15: =_DATA_Assessment_Model!AL15 | AP15: =_DATA_Assessment_Model!AM15 | AQ15: =_DATA_Assessment_Model!AN15 | AR15: =_DATA_Assessment_Model!AO15 | AS15: =_DATA_Assessment_Model!AP15 | AT15: =_DATA_Assessment_Model!AQ15 | ... AW15: =_DATA_Assessment_Model!AT15 | AY15: =_DATA_Assessment_Model!AV15
A16: Company Geography | B16: Company Geography | C16: 16 | D16: COMP-012 | E16: Geographical distribution | F16: How mature is the organization in managing customer distribution by geography, industry, contract and crisis sensitivity, including ownership, evidence, metrics, fallback procedures and crisis stress testing? | G16: This topic affects exposure to Geopolitical risk; Physical site loss; Regulatory/legal shock. It helps identify how disruption may impact operations, people, revenue, systems, legal exposure or recovery time. | H16: ISO 22301; ISO 31000; ISO 9001; ISO 37000; PESTLE; Business Model Canvas | I16: Policy/SOP; owner/RACI; system report; dashboard; contracts; test records; incident history; interview evidence related to customer distribution by geography, industry, contract and crisis sensitivity. | J16: 5 | K16: =_DATA_Assessment_Model!H16 | L16: =_DATA_Assessment_Model!I16 | M16: =_DATA_Assessment_Model!J16 | N16: =_DATA_Assessment_Model!K16 | O16: =_DATA_Assessment_Model!L16 | P16: Does not exist; no owner, no documentation, no practice. | Q16: Ad hoc; depends entirely on specific individuals. | R16: Partially documented or implemented; coverage inconsistent; never tested under stress. | S16: Documented, owned, executed consistently; basic evidence and metrics exist. | T16: Measured and periodically tested/audited; integrated with adjacent processes. | U16: Optimized and automated where practical; stress-tested; benchmarked externally. | V16: Geopolitical risk; Physical site loss; Regulatory/legal shock | Y16: Use the recommended action generated by the model; validate with domain owner during real assessment. | Z16: 4 | AA16: 5 | AB16: 5 | AM16: =_DATA_Assessment_Model!AJ16 | AN16: =_DATA_Assessment_Model!AK16 | AO16: =_DATA_Assessment_Model!AL16 | AP16: =_DATA_Assessment_Model!AM16 | AQ16: =_DATA_Assessment_Model!AN16 | AR16: =_DATA_Assessment_Model!AO16 | AS16: =_DATA_Assessment_Model!AP16 | AT16: =_DATA_Assessment_Model!AQ16 | ... AW16: =_DATA_Assessment_Model!AT16 | AY16: =_DATA_Assessment_Model!AV16
A17: Company Geography | B17: Company Geography | C17: 17 | D17: COMP-013 | E17: Geographical distribution | F17: How mature is the organization in managing country risk monitoring for war, sanctions, political instability, natural disaster and energy risks, including ownership, evidence, metrics, fallback procedures and crisis stress testing? | G17: This topic affects exposure to Geopolitical risk; Physical site loss; Regulatory/legal shock. It helps identify how disruption may impact operations, people, revenue, systems, legal exposure or recovery time. | H17: ISO 22301; ISO 31000; ISO 9001; ISO 37000; PESTLE; Business Model Canvas | I17: Policy/SOP; owner/RACI; system report; dashboard; contracts; test records; incident history; interview evidence related to country risk monitoring for war, sanctions, political instability, natural disaster and energy risks. | J17: 4 | K17: =_DATA_Assessment_Model!H17 | L17: =_DATA_Assessment_Model!I17 | M17: =_DATA_Assessment_Model!J17 | N17: =_DATA_Assessment_Model!K17 | O17: =_DATA_Assessment_Model!L17 | P17: No reliable evidence that country risk monitoring for war, sanctions, political instability, natural disaster and energy risks is defined, owned or managed. | Q17: Country risk monitoring for war, sanctions, political instability, natural disaster and energy risks is handled informally and depends on individual knowledge or heroic effort. | R17: Country risk monitoring for war, sanctions, political instability, natural disaster and energy risks is partially documented or implemented, but coverage is inconsistent and not crisis-tested. | S17: Country risk monitoring for war, sanctions, political instability, natural disaster and energy risks is documented, owned, used in normal operations and supported by basic evidence or metrics. | T17: Country risk monitoring for war, sanctions, political instability, natural disaster and energy risks is measured, periodically reviewed, integrated with related processes and tested against relevant disruption scenarios. | U17: Country risk monitoring for war, sanctions, political instability, natural disaster and energy risks is optimized, continuously improved, automated where practical and demonstrably supports crisis resilience. | V17: Geopolitical risk; Physical site loss; Regulatory/legal shock | Y17: Use the recommended action generated by the model; validate with domain owner during real assessment. | Z17: 4 | AA17: 5 | AB17: 5 | AM17: =_DATA_Assessment_Model!AJ17 | AN17: =_DATA_Assessment_Model!AK17 | AO17: =_DATA_Assessment_Model!AL17 | AP17: =_DATA_Assessment_Model!AM17 | AQ17: =_DATA_Assessment_Model!AN17 | AR17: =_DATA_Assessment_Model!AO17 | AS17: =_DATA_Assessment_Model!AP17 | AT17: =_DATA_Assessment_Model!AQ17 | ... AW17: =_DATA_Assessment_Model!AT17 | AY17: =_DATA_Assessment_Model!AV17
A18: Company Geography | B18: Company Geography | C18: 18 | D18: COMP-014 | E18: Geographical distribution | F18: How mature is the organization in managing relocation and alternative location options for critical teams and operations, including ownership, evidence, metrics, fallback procedures and crisis stress testing? | G18: This topic affects exposure to Geopolitical risk; Physical site loss; Regulatory/legal shock. It helps identify how disruption may impact operations, people, revenue, systems, legal exposure or recovery time. | H18: ISO 22301; ISO 31000; ISO 9001; ISO 37000; PESTLE; Business Model Canvas | I18: Policy/SOP; owner/RACI; system report; dashboard; contracts; test records; incident history; interview evidence related to relocation and alternative location options for critical teams and operations. | J18: 5 | K18: =_DATA_Assessment_Model!H18 | L18: =_DATA_Assessment_Model!I18 | M18: =_DATA_Assessment_Model!J18 | N18: =_DATA_Assessment_Model!K18 | O18: =_DATA_Assessment_Model!L18 | P18: Does not exist; no owner, no documentation, no practice. | Q18: Ad hoc; depends entirely on specific individuals. | R18: Partially documented or implemented; coverage inconsistent; never tested under stress. | S18: Documented, owned, executed consistently; basic evidence and metrics exist. | T18: Measured and periodically tested/audited; integrated with adjacent processes. | U18: Optimized and automated where practical; stress-tested; benchmarked externally. | V18: Geopolitical risk; Physical site loss; Regulatory/legal shock | Y18: Use the recommended action generated by the model; validate with domain owner during real assessment. | Z18: 4 | AA18: 5 | AB18: 5 | AM18: =_DATA_Assessment_Model!AJ18 | AN18: =_DATA_Assessment_Model!AK18 | AO18: =_DATA_Assessment_Model!AL18 | AP18: =_DATA_Assessment_Model!AM18 | AQ18: =_DATA_Assessment_Model!AN18 | AR18: =_DATA_Assessment_Model!AO18 | AS18: =_DATA_Assessment_Model!AP18 | AT18: =_DATA_Assessment_Model!AQ18 | ... AW18: =_DATA_Assessment_Model!AT18 | AY18: =_DATA_Assessment_Model!AV18
A19: Company Geography | B19: Company Geography | C19: 19 | D19: COMP-016 | E19: Context and dependencies | F19: How mature is the organization in managing single-country, single-site and single-provider concentration risks, including ownership, evidence, metrics, fallback procedures and crisis stress testing? | G19: This topic affects exposure to Geopolitical risk; Physical site loss; Regulatory/legal shock. It helps identify how disruption may impact operations, people, revenue, systems, legal exposure or recovery time. | H19: ISO 22301; ISO 31000; ISO 9001; ISO 37000; PESTLE; Business Model Canvas | I19: Policy/SOP; owner/RACI; system report; dashboard; contracts; test records; incident history; interview evidence related to single-country, single-site and single-provider concentration risks. | J19: 5 | K19: =_DATA_Assessment_Model!H19 | L19: =_DATA_Assessment_Model!I19 | M19: =_DATA_Assessment_Model!J19 | N19: =_DATA_Assessment_Model!K19 | O19: =_DATA_Assessment_Model!L19 | P19: Does not exist; no owner, no documentation, no practice. | Q19: Ad hoc; depends entirely on specific individuals. | R19: Partially documented or implemented; coverage inconsistent; never tested under stress. | S19: Documented, owned, executed consistently; basic evidence and metrics exist. | T19: Measured and periodically tested/audited; integrated with adjacent processes. | U19: Optimized and automated where practical; stress-tested; benchmarked externally. | V19: Geopolitical risk; Physical site loss; Regulatory/legal shock | Y19: Use the recommended action generated by the model; validate with domain owner during real assessment. | Z19: 4 | AA19: 5 | AB19: 5 | AM19: =_DATA_Assessment_Model!AJ19 | AN19: =_DATA_Assessment_Model!AK19 | AO19: =_DATA_Assessment_Model!AL19 | AP19: =_DATA_Assessment_Model!AM19 | AQ19: =_DATA_Assessment_Model!AN19 | AR19: =_DATA_Assessment_Model!AO19 | AS19: =_DATA_Assessment_Model!AP19 | AT19: =_DATA_Assessment_Model!AQ19 | ... AW19: =_DATA_Assessment_Model!AT19 | AY19: =_DATA_Assessment_Model!AV19
... A23: Company Geography | B23: Company Geography | C23: 23 | D23: COMP-021 | E23: Context and dependencies | F23: How mature is the organization in managing critical infrastructure status and government emergency obligations across operating geographies, including ownership, evidence, metrics, fallback procedures and crisis stress testing? | G23: This topic affects exposure to War/security crisis; Energy/utilities outage; Regulatory/legal shock. It helps identify how disruption may impact operations, people, revenue, systems, legal exposure or recovery time. | H23: ISO 22301; NIS2; national critical infrastructure regulation | I23: Policy/SOP; owner/RACI; system report; dashboard; contracts; test records; incident history; interview evidence | J23: 3 | K23: =_DATA_Assessment_Model!H23 | L23: =_DATA_Assessment_Model!I23 | M23: =_DATA_Assessment_Model!J23 | N23: =_DATA_Assessment_Model!K23 | O23: =_DATA_Assessment_Model!L23 | P23: No reliable evidence that critical infrastructure status and government emergency obligations across operating geographies is defined, owned or managed. | Q23: Critical infrastructure status and government emergency obligations across operating geographies is handled informally and depends on individual knowledge or heroic effort. | R23: Critical infrastructure status and government emergency obligations across operating geographies is partially documented or implemented, but coverage is inconsistent and not crisis-tested. | S23: Critical infrastructure status and government emergency obligations across operating geographies is documented, owned, used in normal operations and supported by basic evidence or metrics. | T23: Critical infrastructure status and government emergency obligations across operating geographies is measured, periodically reviewed, integrated with related processes and tested against relevant disruption scenarios. | U23: Critical infrastructure status and government emergency obligations across operating geographies is optimized, continuously improved, automated where practical and demonstrably supports crisis resilience. | V23: War/security crisis; Energy/utilities outage; Regulatory/legal shock | Y23: Use the recommended action generated by the model; validate with domain owner during real assessment. | Z23: 2 | AA23: 4 | AB23: 4 | AM23: =_DATA_Assessment_Model!AJ23 | AN23: =_DATA_Assessment_Model!AK23 | AO23: =_DATA_Assessment_Model!AL23 | AP23: =_DATA_Assessment_Model!AM23 | AQ23: =_DATA_Assessment_Model!AN23 | AR23: =_DATA_Assessment_Model!AO23 | AS23: =_DATA_Assessment_Model!AP23 | AT23: =_DATA_Assessment_Model!AQ23 | ... AW23: =_DATA_Assessment_Model!AT23 | AY23: =_DATA_Assessment_Model!AV23
A24: Strategy GTM | B24: Strategy GTM | C24: 5 | D24: STRA-001 | E24: Corporate strategy | F24: How mature is the organization in managing documented strategy translated into objectives, KPIs, budgets and accountable owners, including ownership, evidence, metrics, fallback procedures and crisis stress testing? | G24: This topic affects exposure to Demand shock; Financial liquidity crisis; Reputation crisis. It helps identify how disruption may impact operations, people, revenue, systems, legal exposure or recovery time. | H24: ISO 9001; ISO 31000; ISO 37000; McKinsey 7S; OHI; Bain Elements of Value; Jobs-to-be-Done; Porter Five Forces; OKR | I24: Policy/SOP; owner/RACI; system report; dashboard; contracts; test records; incident history; interview evidence related to documented strategy translated into objectives, KPIs, budgets and accountable owners. | J24: 4 | K24: =_DATA_Assessment_Model!H24 | L24: =_DATA_Assessment_Model!I24 | M24: =_DATA_Assessment_Model!J24 | N24: =_DATA_Assessment_Model!K24 | O24: =_DATA_Assessment_Model!L24 | P24: No reliable evidence that documented strategy translated into objectives, kpis, budgets and accountable owners is defined, owned or managed. | Q24: Documented strategy translated into objectives, KPIs, budgets and accountable owners is handled informally and depends on individual knowledge or heroic effort. | R24: Documented strategy translated into objectives, KPIs, budgets and accountable owners is partially documented or implemented, but coverage is inconsistent and not crisis-tested. | S24: Documented strategy translated into objectives, KPIs, budgets and accountable owners is documented, owned, used in normal operations and supported by basic evidence or metrics. | T24: Documented strategy translated into objectives, KPIs, budgets and accountable owners is measured, periodically reviewed, integrated with related processes and tested against relevant disruption scenarios. | U24: Documented strategy translated into objectives, KPIs, budgets and accountable owners is optimized, continuously improved, automated where practical and demonstrably supports crisis resilience. | V24: Demand shock; Financial liquidity crisis; Reputation crisis | Y24: Use the recommended action generated by the model; validate with domain owner during real assessment. | Z24: 4 | AA24: 5 | AB24: 5 | AD24: Corporate strategy | AE24: =_DATA_Assessment_Model!AB24 | AF24: =_DATA_Assessment_Model!AC24 | AG24: =_DATA_Assessment_Model!AD24 | AH24: =_DATA_Assessment_Model!AE24 | AI24: =_DATA_Assessment_Model!AF24 | AJ24: =_DATA_Assessment_Model!AG24 | AM24: =_DATA_Assessment_Model!AJ24 | AN24: =_DATA_Assessment_Model!AK24 | AO24: =_DATA_Assessment_Model!AL24 | AP24: =_DATA_Assessment_Model!AM24 | AQ24: =_DATA_Assessment_Model!AN24 | AR24: =_DATA_Assessment_Model!AO24 | AS24: =_DATA_Assessment_Model!AP24 | AT24: =_DATA_Assessment_Model!AQ24 | ... AW24: =_DATA_Assessment_Model!AT24 | AY24: =_DATA_Assessment_Model!AV24
A25: Strategy GTM | B25: Strategy GTM | C25: 6 | D25: STRA-002 | E25: Corporate strategy | F25: How mature is the organization in managing explicit strategic assumptions and periodic challenge of those assumptions, including ownership, evidence, metrics, fallback procedures and crisis stress testing? | G25: This topic affects exposure to Demand shock; Financial liquidity crisis; Reputation crisis. It helps identify how disruption may impact operations, people, revenue, systems, legal exposure or recovery time. | H25: ISO 9001; ISO 31000; ISO 37000; McKinsey 7S; OHI; Bain Elements of Value; Jobs-to-be-Done; Porter Five Forces; OKR | I25: Policy/SOP; owner/RACI; system report; dashboard; contracts; test records; incident history; interview evidence related to explicit strategic assumptions and periodic challenge of those assumptions. | J25: 3 | K25: =_DATA_Assessment_Model!H25 | L25: =_DATA_Assessment_Model!I25 | M25: =_DATA_Assessment_Model!J25 | N25: =_DATA_Assessment_Model!K25 | O25: =_DATA_Assessment_Model!L25 | P25: No reliable evidence that explicit strategic assumptions and periodic challenge of those assumptions is defined, owned or managed. | Q25: Explicit strategic assumptions and periodic challenge of those assumptions is handled informally and depends on individual knowledge or heroic effort. | R25: Explicit strategic assumptions and periodic challenge of those assumptions is partially documented or implemented, but coverage is inconsistent and not crisis-tested. | S25: Explicit strategic assumptions and periodic challenge of those assumptions is documented, owned, used in normal operations and supported by basic evidence or metrics. | T25: Explicit strategic assumptions and periodic challenge of those assumptions is measured, periodically reviewed, integrated with related processes and tested against relevant disruption scenarios. | U25: Explicit strategic assumptions and periodic challenge of those assumptions is optimized, continuously improved, automated where practical and demonstrably supports crisis resilience. | V25: Demand shock; Financial liquidity crisis; Reputation crisis | Y25: Use the recommended action generated by the model; validate with domain owner during real assessment. | Z25: 4 | AA25: 5 | AB25: 5 | AD25: Market and ICP | AE25: =_DATA_Assessment_Model!AB25 | AF25: =_DATA_Assessment_Model!AC25 | AG25: =_DATA_Assessment_Model!AD25 | AH25: =_DATA_Assessment_Model!AE25 | AI25: =_DATA_Assessment_Model!AF25 | AJ25: =_DATA_Assessment_Model!AG25 | AM25: =_DATA_Assessment_Model!AJ25 | AN25: =_DATA_Assessment_Model!AK25 | AO25: =_DATA_Assessment_Model!AL25 | AP25: =_DATA_Assessment_Model!AM25 | AQ25: =_DATA_Assessment_Model!AN25 | AR25: =_DATA_Assessment_Model!AO25 | AS25: =_DATA_Assessment_Model!AP25 | AT25: =_DATA_Assessment_Model!AQ25 | ... AW25: =_DATA_Assessment_Model!AT25 | AY25: =_DATA_Assessment_Model!AV25
