Workbook
Name cfg_AboveOptimumRatio: _CONFIG_Model_Settings!$B$24
Name cfg_CrisisHighCut: _CONFIG_Model_Settings!$B$17
Name cfg_CrisisMedCut: _CONFIG_Model_Settings!$B$18
Name cfg_IndPriorityHigh: _CONFIG_Model_Settings!$B$19
Name cfg_IndPriorityLow: _CONFIG_Model_Settings!$B$20
Name cfg_RiskFitScale: _CONFIG_Model_Settings!$B$26
Name cfg_RiskSecondaryWeight: _CONFIG_Model_Settings!$B$25
Name cfg_ScenarioFitScale: _CONFIG_Model_Settings!$B$27
Name cfg_TimelineBucket1: _CONFIG_Model_Settings!$B$21
Name cfg_TimelineBucket2: _CONFIG_Model_Settings!$B$22
Name cfg_TimelineBucket3: _CONFIG_Model_Settings!$B$23
Name CTX_Rules: _REF_Context_Relevance!$A$1:$K$25
Name DV_ASSESSMENT_CADENCE: _REF_Dropdowns!$K$3:$K$7
Name DV_ASSESSOR_CONFIDENCE: _REF_Dropdowns!$L$3:$L$5
Name DV_BUSINESS_MODEL: _REF_Dropdowns!$M$3:$M$10
Name DV_CASH_RUNWAY_BAND: _REF_Dropdowns!$N$3:$N$7
Name DV_CHANGE_CAPACITY_BAND: _REF_Dropdowns!$O$3:$O$13
Name DV_CLOUD_MODEL: _REF_Dropdowns!$P$3:$P$11
Name DV_COMPANY_SIZE_BAND: _REF_Dropdowns!$Q$3:$Q$7
Name DV_CONCENTRATION_BAND: _REF_Dropdowns!$R$3:$R$8
Name DV_CONFIDENCE_LEVEL: _REF_Dropdowns!$S$3:$S$5
Name DV_CONTINUITY_OPTION: _REF_Dropdowns!$T$3:$T$7
Name DV_CORE_SYSTEM_FAMILY: _REF_Dropdowns!$U$3:$U$22
Name DV_COUNTRY: _REF_Dropdowns!$V$3:$V$20
Name DV_CRISIS_HISTORY_IMPACT: _REF_Dropdowns!$W$3:$W$8
Name DV_CRITICAL_PEOPLE_DEPENDENCY: _REF_Dropdowns!$X$3:$X$6
Name DV_CRITICAL_PROCESS_FAMILY: _REF_Dropdowns!$Y$3:$Y$14
Name DV_CRITICAL_PRODUCT_SERVICE_TYPE: _REF_Dropdowns!$Z$3:$Z$12
Name DV_DATA_CRITICALITY: _REF_Dropdowns!$AA$3:$AA$6
Name DV_DEBT_LOAD: _REF_Dropdowns!$AB$3:$AB$7
Name DV_DIGITAL_DEPENDENCY: _REF_Dropdowns!$AC$3:$AC$6
Name DV_DISRUPTION_IMPACT: _REF_Dropdowns!$AD$3:$AD$7
Name DV_EVIDENCE_CONFIDENCE: _REF_Dropdowns!$AE$3:$AE$5
Name DV_FX_EXPOSURE_BAND: _REF_Dropdowns!$AF$3:$AF$7
Name DV_GEOGRAPHIC_FOOTPRINT: _REF_Dropdowns!$AG$3:$AG$7
Name DV_ICP_SEGMENT: _REF_Dropdowns!$AH$3:$AH$11
Name DV_INDUSTRY_ALIAS: _REF_Dropdowns!$AI$3:$AI$14
Name DV_INDUSTRY_CANONICAL: _REF_Dropdowns!$AJ$3:$AJ$11
Name DV_INDUSTRY_TEMPLATE_LEGACY: _REF_Dropdowns!$AK$3:$AK$11
Name DV_LEGAL_ENTITY_COMPLEXITY: _REF_Dropdowns!$AL$3:$AL$8
Name DV_LOCATION_CRITICALITY: _REF_Dropdowns!$AM$3:$AM$7
Name DV_MARKET_CONCENTRATION: _REF_Dropdowns!$AN$3:$AN$8
Name DV_MATURITY_TARGET: _REF_Dropdowns!$AO$3:$AO$8
Name DV_MOBILITY_SUPPORT: _REF_Dropdowns!$AP$3:$AP$8
Name DV_OPERATING_MODEL: _REF_Dropdowns!$AQ$3:$AQ$12
Name DV_OWNERSHIP_TYPE: _REF_Dropdowns!$AR$3:$AR$10
Name DV_PHYSICAL_FOOTPRINT_INTENSITY: _REF_Dropdowns!$AS$3:$AS$7
Name DV_REGULATION_FAMILY: _REF_Dropdowns!$AT$3:$AT$14
Name DV_REGULATORY_INTENSITY: _REF_Dropdowns!$AU$3:$AU$7
Name DV_REMOTE_WORK_READINESS: _REF_Dropdowns!$AV$3:$AV$8
Name DV_REVENUE_BAND: _REF_Dropdowns!$AW$3:$AW$7
Name DV_REVENUE_MODEL: _REF_Dropdowns!$AX$3:$AX$13
Name DV_REVENUE_RECURRENCE: _REF_Dropdowns!$AY$3:$AY$9
Name DV_RISK_APPETITE: _REF_Dropdowns!$AZ$3:$AZ$5
Name DV_SALES_MOTION: _REF_Dropdowns!$BA$3:$BA$11
Name DV_SUB_INDUSTRY_BY_INDUSTRY: _REF_Dropdowns!$BB$3:$BB$22
Name DV_SUPPLIER_SUBSTITUTABILITY: _REF_Dropdowns!$BC$3:$BC$9
Name DV_TRANSFORMATION_EXPERIENCE: _REF_Dropdowns!$BD$3:$BD$6
Name DV_YES_NO_PLANNED_UNKNOWN: _REF_Dropdowns!$BE$3:$BE$6
Name IW_Canonical_Industry: _REF_Industry_Wording!$C$2:$C$70

Sheet Guidelines
A1: RR Framework — Guidelines
A2: Consolidated user guide, methodology, model calibration, workbook map, and change history for the RR-framework Excel tool.
A4: Workbook status
A5: Workbook version | B5: v3.0 | C5: Static audit fixes: hardened visible crisis fallback, cleaned initiative QIDs, aligned risk→initiative coverage, normalized dropdown registry.
A6: Build ID | B6: ="RR-FRAMEWORK-"&$B$5&"-20260624" -> RR-FRAMEWORK-v3.0-20260624 | C6: Build ID derives from Guidelines!B5 so the current version is maintained in one place.
A7: Recommended audience | B7: CEO / COO / CTO / CIO / CFO / CHRO / Consultant / Analyst | C7: Business users should focus on visible workflow sheets; model owners may use calibration/config sheets.
A8: Monte Carlo mode | B8: =_CONFIG_Model_Settings!B178 -> Frozen | C8: Default should be Frozen for public templates and formal reports.
A9: Live seed / Frozen seed | C9: Change mc_live_seed only for intentional reruns; copy to mc_frozen_seed when freezing a scenario.
A11: 0. Quick navigation
A12: Section | B12: Action | C12: Purpose | D12: Internal link
A13: How to use this file | B13: Go to section 1 | C13: Step-by-step workflow from company profile to roadmap. | D13: #Guidelines!A18 | F13: Quick menu | G13: Select a topic | H13: Use the table links or Excel outline +/- controls to expand/collapse sections.
A14: Methodology & calculations | B14: Go to section 2 | C14: Scoring, risk engine, crisis simulation, MC VaR/CVaR, WSJF. | D14: #Guidelines!A39
A15: Calibration & weights | B15: Go to section 3 | C15: Which parameters can be tuned and where they live. | D15: #Guidelines!A70
A16: Workbook tabs | B16: Go to section 4 | C16: Visible, hidden, and veryHidden sheets with edit policy. | D16: #Guidelines!A98
A17: Change history | B17: Go to section 5 | C17: Release notes from v2.0 to current release. | D17: #Guidelines!A140
A18: 1. How to use this file
A19: Step | B19: What to do | C19: Description | D19: Primary sheet
A20: 1 | B20: Start with Company Profile | C20: Enter company size, industry, geography, revenue model, location criticality, crisis exposure, concentration risks, and operational context. | D20: Company Profile
A21: 2 | B21: Complete the assessment | C21: Use Assessment Questions / AS-IS Assessment to evaluate digitalization, process maturity, organizational resilience, crisis readiness, and domain capabilities. | D21: Assessment Questions; AS-IS Assessment
A22: 3 | B22: Review AS-IS diagnostics | C22: Check maturity gaps, weak domains, scoring distribution, and management-level interpretation before moving to risk and strategy. | D22: AS-IS Assessment
A23: 4 | B23: Run risk and crisis scenario review | C23: Use Resilience & Risk Scenario to review risk exposure, crisis amplification, Indexed VaR/CVaR, and top areas of vulnerability. | D23: Resilience & Risk Scenario
A24: 5 | B24: Build action plan and roadmap | C24: Review prioritized initiatives, WSJF, strategic alignment, risk pressure, financial value, and roadmap waves. | D24: Action Plan & Roadmap
A25: 6 | B25: Calibrate only when needed | C25: Consultants/model owners can adjust weights and assumptions in config sheets. Always document changes and rerun QA checks. | D25: Guidelines + hidden config sheets
A27: Operating principles
A28: Principle | B28: Guidance
A29: Client-facing use | B29: Use the six visible workflow sheets. Hidden/veryHidden sheets are calculation and configuration layers.
A30: Public template mode | B30: Public templates should ship with Monte Carlo in Frozen mode and with one visible documentation hub: Guidelines.
A31: Formal report mode | B31: Record selected crisis scenario, mc_mode, active seed, date/time of run, and any calibration changes.
A32: Excel limitation | B32: The RR-framework Excel file is a calculation/model prototype. The future web-app should implement governed backend calculation, audit logs, and deterministic simulation runs.
A39: 2. Methodology & calculations
A40: Logic block | B40: How it works | C40: Important note
A41: Assessment scoring | B41: Question-level scores are aggregated into maturity, process, digitalization and resilience views. | C41: Input: Assessment Questions. Output: _DATA_Assessment_Model / dashboard facts.
A42: Profile Vector | B42: Company Profile values are normalized into canonical model fields such as Canonical Industry, Org Type, cloud dependency, data criticality, supplier dependency, physical footprint and selected crisis. | C42: Downstream logic should consume PV_* named outputs, not raw profile cells.
A43: Relevance Engine | B43: Applicability gates, context multipliers and crisis dominance determine whether a capability/risk/initiative is relevant for the company. | C43: Hard exclusions must be applied before ranking; they are not merely low weights.
A44: Capability Bridge | B44: Broad domains and subdomains are mapped to Capability_ID so SaaS, Banking, Retail and Manufacturing can share the same engine without misleading labels. | C44: Use Capability_ID for ranking and wording; do not rely on text labels alone.
A45: Risk engine | B45: Assessment gaps and scenario pressure become capability-adjusted risk exposure and prioritized risk items. | C45: Risk ontology sheets document the canonical output schema.
A46: Treatment Library | B46: Current maturity band selects the appropriate action style: establish, standardize, integrate, optimize or stress-test. | C46: High maturity companies should receive evidence/proof/stress-test treatments, not beginner recommendations.
A47: Industry Wording | B47: The same capability receives different risk/recommendation wording by industry. | C47: Prevents MES/WMS/TMS wording for SaaS/Banking and core banking wording for Manufacturing.
A48: Crisis simulation | B48: Selected crisis and severity apply dominance multipliers and cascade logic. | C48: Ransomware should prioritize cyber/DR/data/legal/system themes; cloud outage should prioritize platform/cloud/SRE/customer communication.
A49: Monte Carlo / indexed exposure | B49: Deterministic seed-based Monte Carlo and analytic VaR/CVaR remain directional indexed outputs unless calibrated with financial loss data. | C49: Keep Frozen mode for formal reports.
...

Sheet Company Profile
A1: Company Profile
A2: Fill controlled inputs once per organization. Duplicate summary fields are now formula-derived; Profile Vector preview shows canonical values used by engines.
A3: =HYPERLINK("#'Guidelines'!A1","⌂ Guidelines") -> ⌂ Guidelines | C3: ✎ Input: edit coloured dropdown cells only. Grey/formula rows are derived or compatibility-only.
A4: Profile field | B4: Value / input | C4: Guidance | D4: Used by | F4: How this sheet is used
A5: Organization name | C5: Legal or commercial name used in the assessment. | D5: Dashboard / executive summary | F5: 1. Define organization context and assessment boundaries. 2. Use Crisis Simulator for active scenario and severity. 3. Use Assessment date as the roadmap start date. 4. Use target scores to calibrate expected maturity level. 5. Keep LLM and financial analysis outside this workbook version.
A6: Assessment date | B6: =TODAY() -> 46197 | C6: Baseline date. Defaults to TODAY() and can be replaced by the actual assessment date. | D6: Gantt Roadmap
A7: Assessment owner | C7: Person responsible for coordinating the assessment. | D7: Quality Control
A8: Executive sponsor | C8: Senior owner who accepts priorities and crisis roadmap. | D8: Roadmap governance
A9: Industry | C9: Primary industry or sector. | D9: Strategy logic
A10: Sub-industry / segment | C10: More specific segment, e.g. manufacturing, SaaS, retail, healthcare. | D10: Strategy logic
A11: Headquarters country | C11: Country where the main legal or management entity is located. | D11: Risk context
A12: Operating countries / regions | C12: List countries, regions and key cities where the company operates. | D12: Geographical exposure
A13: Ownership type | C13: Private, public, state-owned, family-owned, PE-backed, NGO or other. | D13: Governance context
A14: Legal entities | C14: Main legal entities and subsidiaries. | D14: Legal / continuity context
A15: Employee count | C15: Total employees and contractors. | D15: HR / continuity logic
A16: Revenue size band (derived) | B16: =IF($B$108<>"",$B$108,"") | C16: Derived from Annual revenue band in Financial Anchors. Do not edit here. | D16: Derived summary / compatibility
A17: Operating model | C17: Centralized, decentralized, hub-and-spoke, remote-first, multi-site, franchise, hybrid. | D17: Crisis exposure
A18: Business model | C18: B2B, B2C, B2B2C, marketplace, subscription, project-based, manufacturing, distribution. | D18: GTM / resilience logic
A19: Critical products / services (derived) | B19: =IF($B$87<>"",$B$87&" | ","")&IF($B$88<>"",$B$88&" | ","")&IF($B$89<>"",$B$89&" | ","")&IF($B$90<>"",$B$90&" | ","")&IF($B$91<>"",$B$91&" | ","") | C19: Derived from structured Critical Product / Service List rows 87–91. Do not edit here. | D19: Continuity summary
A20: ICP / key customer segments | C20: Ideal customer profiles and most important customer groups. | D20: GTM / revenue resilience
A21: Top markets by revenue | C21: Countries, regions or customer segments with highest revenue share. | D21: Revenue concentration
A22: Customer concentration (derived) | B22: =IF(IF($B$54<>"","Top 1: "&$B$54,"")<>"",IF($B$54<>"","Top 1: "&$B$54,"")&" | ","")&IF(IF($B$55<>"","Top 5: "&$B$55,"")<>"",IF($B$55<>"","Top 5: "&$B$55,"")&" | ","")&IF(IF($B$56<>"","Top 10: "&$B$56,"")<>"",IF($B$56<>"","Top 10: "&$B$56,"")&" | ","") | C22: Derived from top 1 / top 5 / top 10 structured concentration bands. Do not edit here. | D22: Revenue concentration summary
A23: Critical sites / facilities (derived) | B23: =IF(IF($B$63<>"",$A$63&": "&$B$63,"")<>"",IF($B$63<>"",$A$63&": "&$B$63,"")&" | ","")&IF(IF($B$64<>"",$A$64&": "&$B$64,"")<>"",IF($B$64<>"",$A$64&": "&$B$64,"")&" | ","")&IF(IF($B$65<>"",$A$65&": "&$B$65,"")<>"",IF($B$65<>"",$A$65&": "&$B$65,"")&" | ","")&IF(IF($B$66<>"",$A$66&": "&$B$66,"")<>"",IF($B$66<>"",$A$66&": "&$B$66,"")&" | ","")&IF(IF($B$67<>"",$A$67&": "&$B$67,"")<>"",IF($B$67<>"",$A$67&": "&$B$67,"")&" | ","")&IF(IF($B$68<>"",$A$68&": "&$B$68,"")<>"",IF($B$68<>"",$A$68&": "&$B$68,"")&" | ","")&IF(IF($B$69<>"",$A$69&": "&$B$69,"")<>"",IF($B$69<>"",$A$69&": "&$B$69,"")&" | ","")&IF(IF($B$70<>"",$A$70&": "&$B$70,"")<>"",IF($B$70<>"",$A$70&": "&$B$70,"")&" | ","") | C23: Derived from Business Criticality of Locations table rows 63–70. Do not edit here. | D23: Physical footprint summary
A24: Critical people / roles | C24: Roles where loss of individuals creates continuity risk. | D24: Workforce resilience
A25: Regulatory exposure level | C25: Low, medium, high or critical regulatory exposure. | D25: Legal / compliance risk
A26: Main regulations / obligations | C26: Examples: GDPR, NIS2, HIPAA, SOX, ISO, industry licenses, customer audit obligations. | D26: Compliance context
A27: Core business systems | C27: ERP, CRM, MES, HRMS, BI, WMS, SCM, billing, support desk, data warehouse. | D27: Digital maturity
A28: Cloud and infrastructure model | C28: On-premise, public cloud, private cloud, hybrid, multi-cloud, SaaS-first. | D28: IT / DR strategy
A29: Primary crisis scenario to test | B29: ='Resilience & Risk Scenario'!$B$6 -> 0 | C29: Active scenario is selected in Crisis Simulator. | D29: Crisis Simulator
A30: Scenario severity 1-5 | B30: ='Resilience & Risk Scenario'!$B$7 -> 0 | C30: Active scenario severity is selected in Crisis Simulator. | D30: Crisis Simulator
A31: Target process maturity 0-5 | C31: Target level for process maturity. | D31: Gap analysis
A32: Target digitalization 0-5 | C32: Target level for implementation of digital technologies. | D32: Gap analysis
A33: Target resilience 0-5 | C33: Target level for resilience against relevant risks. | D33: Gap analysis
A34: Assessment cadence | C34: Quarterly, semi-annual, annual, or crisis-triggered review. | D34: Governance
A35: Risk appetite statement | C35: Closed choice: Low / Balanced / High. Low = risk-averse (targets tightened), High = more residual risk accepted (targets relaxed). Adjusts industry maturity targets across the model via _CONFIG_Model_Settings. | D35: Risk treatment
A36: Key assumptions / comments | C36: Context notes, assumptions, excluded scope or special assessment limitations. Leave blank until the real assessment is configured. | D36: All outputs
A38: Industry Template and Improved Scoring Logic
A39: Selected industry template | B39: =PV_Canonical_Industry -> 0 | C39: Derived from _ENGINE_Profile_Vector. Compatibility display only; not an active input.
A40: Default evidence confidence | B40: Medium | C40: Used when question-level evidence confidence is blank.
A41: Default assessor confidence | B41: Medium | C41: Used when question-level assessor confidence is blank.
...

Sheet Assessment Questions
A1: Assessment Questions
A2: Main assessment surface with all 424 questions. Use green/input columns for answers, evidence confidence, coverage, owners and comments.
A3: =HYPERLINK("#'Guidelines'!A1","⌂ Guidelines") -> ⌂ Guidelines | C3: ✎ Input: edit answer / confidence / comment columns only — the rest is formula-driven.
A4: Domain | B4: Source sheet | C4: Source row | D4: ID | E4: Subdomain | F4: Question | G4: Crisis relevance / why it matters | H4: Standards / frameworks | I4: Evidence to request | J4: Weight 1-5 | K4: Score 0-5 (auto from answer) | L4: Weighted score | M4: Max score | N4: Gap | O4: Risk level | P4: Score 0 criteria | Q4: Score 1 criteria | R4: Score 2 criteria | S4: Score 3 criteria | T4: Score 4 criteria | U4: Score 5 criteria | V4: Crisis scenario tags | W4: Owner / SME | X4: Comments / findings | Y4: Recommended action | Z4: Digitalization relevance 0-5 | AA4: Resilience relevance 0-5 | AB4: Process maturity relevance 0-5 | AC4: Answer (0–5) — select stage | AD4: Subarea | AE4: Questions | AF4: Avg score 0-5 | AG4: Maturity % | AH4: Critical/High | AI4: Gap to 5 | AJ4: Answered | AK4: Evidence confidence | AL4: Assessor confidence | AM4: Evidence factor | AN4: Assessor factor | AO4: Confidence-adjusted score 0-5 | AP4: Normalized score 0-100 | AQ4: Industry target 0-5 | AR4: Gap to industry target | AS4: Industry criticality multiplier | AT4: Industry-adjusted gap priority | AU4: Improved scoring note | AV4: v2 conf-adj score | AW4: v2 conf factor | AX4: Coverage (how widely deployed) | AY4: Coverage factor
A5: Company Geography | B5: Company Geography | C5: 5 | D5: COMP-001 | E5: Company profile | F5: How mature is the organization in managing legal entity structure, ownership, subsidiaries and operating countries, including ownership, evidence, metrics, fallback procedures and crisis stress testing? | G5: This topic affects exposure to Geopolitical risk; Physical site loss; Regulatory/legal shock. It helps identify how disruption may impact operations, people, revenue, systems, legal exposure or recovery time. | H5: ISO 22301; ISO 31000; ISO 9001; ISO 37000; PESTLE; Business Model Canvas | I5: Policy/SOP; owner/RACI; system report; dashboard; contracts; test records; incident history; interview evidence related to legal entity structure, ownership, subsidiaries and operating countries. | J5: 3 | K5: =_DATA_Assessment_Model!H5 -> 0 | L5: =_DATA_Assessment_Model!I5 -> 0 | M5: =_DATA_Assessment_Model!J5 -> 3 | N5: =_DATA_Assessment_Model!K5 -> 3 | O5: =_DATA_Assessment_Model!L5 -> Critical | P5: No reliable evidence that legal entity structure, ownership, subsidiaries and operating countries is defined, owned or managed. | Q5: Legal entity structure, ownership, subsidiaries and operating countries is handled informally and depends on individual knowledge or heroic effort. | R5: Legal entity structure, ownership, subsidiaries and operating countries is partially documented or implemented, but coverage is inconsistent and not crisis-tested. | S5: Legal entity structure, ownership, subsidiaries and operating countries is documented, owned, used in normal operations and supported by basic evidence or metrics. | T5: Legal entity structure, ownership, subsidiaries and operating countries is measured, periodically reviewed, integrated with related processes and tested against relevant disruption scenarios. | U5: Legal entity structure, ownership, subsidiaries and operating countries is optimized, continuously improved, automated where practical and demonstrably supports crisis resilience. | V5: Geopolitical risk; Physical site loss; Regulatory/legal shock | Y5: Use the recommended action generated by the model; validate with domain owner during real assessment. | Z5: 4 | AA5: 5 | AB5: 5 | AD5: Company profile | AE5: =_DATA_Assessment_Model!AB5 -> 7 | AF5: =_DATA_Assessment_Model!AC5 -> 0 | AG5: =_DATA_Assessment_Model!AD5 -> 0 | AH5: =_DATA_Assessment_Model!AE5 -> 7 | AI5: =_DATA_Assessment_Model!AF5 -> 5 | AJ5: =_DATA_Assessment_Model!AG5 -> 7 | AM5: =_DATA_Assessment_Model!AJ5 -> 0.9 | AN5: =_DATA_Assessment_Model!AK5 -> 0.9 | AO5: =_DATA_Assessment_Model!AL5 -> 0 | AP5: =_DATA_Assessment_Model!AM5 -> 0 | AQ5: =_DATA_Assessment_Model!AN5 -> 0 | AR5: =_DATA_Assessment_Model!AO5 -> 0 | AS5: =_DATA_Assessment_Model!AP5 -> 0 | AT5: =_DATA_Assessment_Model!AQ5 -> 0 | ... AW5: =_DATA_Assessment_Model!AT5 -> 0.9 | AY5: =_DATA_Assessment_Model!AV5 -> 0.9
A6: Company Geography | B6: Company Geography | C6: 6 | D6: COMP-002 | E6: Company profile | F6: How mature is the organization in managing business model, value proposition, revenue streams and cost drivers, including ownership, evidence, metrics, fallback procedures and crisis stress testing? | G6: This topic affects exposure to Geopolitical risk; Physical site loss; Regulatory/legal shock. It helps identify how disruption may impact operations, people, revenue, systems, legal exposure or recovery time. | H6: ISO 22301; ISO 31000; ISO 9001; ISO 37000; PESTLE; Business Model Canvas | I6: Policy/SOP; owner/RACI; system report; dashboard; contracts; test records; incident history; interview evidence related to business model, value proposition, revenue streams and cost drivers. | J6: 5 | K6: =_DATA_Assessment_Model!H6 -> 0 | L6: =_DATA_Assessment_Model!I6 -> 0 | M6: =_DATA_Assessment_Model!J6 -> 5 | N6: =_DATA_Assessment_Model!K6 -> 5 | O6: =_DATA_Assessment_Model!L6 -> Critical | P6: Does not exist; no owner, no documentation, no practice. | Q6: Ad hoc; depends entirely on specific individuals. | R6: Partially documented or implemented; coverage inconsistent; never tested under stress. | S6: Documented, owned, executed consistently; basic evidence and metrics exist. | T6: Measured and periodically tested/audited; integrated with adjacent processes. | U6: Optimized and automated where practical; stress-tested; benchmarked externally. | V6: Geopolitical risk; Physical site loss; Regulatory/legal shock | Y6: Use the recommended action generated by the model; validate with domain owner during real assessment. | Z6: 4 | AA6: 5 | AB6: 5 | AD6: Geographical distribution | AE6: =_DATA_Assessment_Model!AB6 -> 7 | AF6: =_DATA_Assessment_Model!AC6 -> 0 | AG6: =_DATA_Assessment_Model!AD6 -> 0 | AH6: =_DATA_Assessment_Model!AE6 -> 7 | AI6: =_DATA_Assessment_Model!AF6 -> 5 | AJ6: =_DATA_Assessment_Model!AG6 -> 7 | AM6: =_DATA_Assessment_Model!AJ6 -> 0.9 | AN6: =_DATA_Assessment_Model!AK6 -> 0.9 | AO6: =_DATA_Assessment_Model!AL6 -> 0 | AP6: =_DATA_Assessment_Model!AM6 -> 0 | AQ6: =_DATA_Assessment_Model!AN6 -> 0 | AR6: =_DATA_Assessment_Model!AO6 -> 0 | AS6: =_DATA_Assessment_Model!AP6 -> 0 | AT6: =_DATA_Assessment_Model!AQ6 -> 0 | ... AW6: =_DATA_Assessment_Model!AT6 -> 0.9 | AY6: =_DATA_Assessment_Model!AV6 -> 0.9
A7: Company Geography | B7: Company Geography | C7: 7 | D7: COMP-003 | E7: Company profile | F7: How mature is the organization in managing critical products and services ranked by revenue, margin and continuity priority, including ownership, evidence, metrics, fallback procedures and crisis stress testing? | G7: This topic affects exposure to Geopolitical risk; Physical site loss; Regulatory/legal shock. It helps identify how disruption may impact operations, people, revenue, systems, legal exposure or recovery time. | H7: ISO 22301; ISO 31000; ISO 9001; ISO 37000; PESTLE; Business Model Canvas | I7: Policy/SOP; owner/RACI; system report; dashboard; contracts; test records; incident history; interview evidence related to critical products and services ranked by revenue, margin and continuity priority. | J7: 5 | K7: =_DATA_Assessment_Model!H7 -> 0 | L7: =_DATA_Assessment_Model!I7 -> 0 | M7: =_DATA_Assessment_Model!J7 -> 5 | N7: =_DATA_Assessment_Model!K7 -> 5 | O7: =_DATA_Assessment_Model!L7 -> Critical | P7: Does not exist; no owner, no documentation, no practice. | Q7: Ad hoc; depends entirely on specific individuals. | R7: Partially documented or implemented; coverage inconsistent; never tested under stress. | S7: Documented, owned, executed consistently; basic evidence and metrics exist. | T7: Measured and periodically tested/audited; integrated with adjacent processes. | U7: Optimized and automated where practical; stress-tested; benchmarked externally. | V7: Geopolitical risk; Physical site loss; Regulatory/legal shock | Y7: Use the recommended action generated by the model; validate with domain owner during real assessment. | Z7: 4 | AA7: 5 | AB7: 5 | AD7: Context and dependencies | AE7: =_DATA_Assessment_Model!AB7 -> 5 | AF7: =_DATA_Assessment_Model!AC7 -> 0 | AG7: =_DATA_Assessment_Model!AD7 -> 0 | AH7: =_DATA_Assessment_Model!AE7 -> 5 | AI7: =_DATA_Assessment_Model!AF7 -> 5 | AJ7: =_DATA_Assessment_Model!AG7 -> 5 | AM7: =_DATA_Assessment_Model!AJ7 -> 0.9 | AN7: =_DATA_Assessment_Model!AK7 -> 0.9 | AO7: =_DATA_Assessment_Model!AL7 -> 0 | AP7: =_DATA_Assessment_Model!AM7 -> 0 | AQ7: =_DATA_Assessment_Model!AN7 -> 0 | AR7: =_DATA_Assessment_Model!AO7 -> 0 | AS7: =_DATA_Assessment_Model!AP7 -> 0 | AT7: =_DATA_Assessment_Model!AQ7 -> 0 | ... AW7: =_DATA_Assessment_Model!AT7 -> 0.9 | AY7: =_DATA_Assessment_Model!AV7 -> 0.9
A8: Company Geography | B8: Company Geography | C8: 8 | D8: COMP-004 | E8: Company profile | F8: How mature is the organization in managing operating model: centralized, distributed, outsourced, remote or hybrid, including ownership, evidence, metrics, fallback procedures and crisis stress testing? | G8: This topic affects exposure to Geopolitical risk; Physical site loss; Regulatory/legal shock. It helps identify how disruption may impact operations, people, revenue, systems, legal exposure or recovery time. | H8: ISO 22301; ISO 31000; ISO 9001; ISO 37000; PESTLE; Business Model Canvas | I8: Policy/SOP; owner/RACI; system report; dashboard; contracts; test records; incident history; interview evidence related to operating model: centralized, distributed, outsourced, remote or hybrid. | J8: 4 | K8: =_DATA_Assessment_Model!H8 -> 0 | L8: =_DATA_Assessment_Model!I8 -> 0 | M8: =_DATA_Assessment_Model!J8 -> 4 | N8: =_DATA_Assessment_Model!K8 -> 4 | O8: =_DATA_Assessment_Model!L8 -> Critical | P8: No reliable evidence that operating model: centralized, distributed, outsourced, remote or hybrid is defined, owned or managed. | Q8: Operating model: centralized, distributed, outsourced, remote or hybrid is handled informally and depends on individual knowledge or heroic effort. | R8: Operating model: centralized, distributed, outsourced, remote or hybrid is partially documented or implemented, but coverage is inconsistent and not crisis-tested. | S8: Operating model: centralized, distributed, outsourced, remote or hybrid is documented, owned, used in normal operations and supported by basic evidence or metrics. | T8: Operating model: centralized, distributed, outsourced, remote or hybrid is measured, periodically reviewed, integrated with related processes and tested against relevant disruption scenarios. | U8: Operating model: centralized, distributed, outsourced, remote or hybrid is optimized, continuously improved, automated where practical and demonstrably supports crisis resilience. | V8: Geopolitical risk; Physical site loss; Regulatory/legal shock | Y8: Use the recommended action generated by the model; validate with domain owner during real assessment. | Z8: 4 | AA8: 5 | AB8: 5 | AM8: =_DATA_Assessment_Model!AJ8 -> 0.9 | AN8: =_DATA_Assessment_Model!AK8 -> 0.9 | AO8: =_DATA_Assessment_Model!AL8 -> 0 | AP8: =_DATA_Assessment_Model!AM8 -> 0 | AQ8: =_DATA_Assessment_Model!AN8 -> 0 | AR8: =_DATA_Assessment_Model!AO8 -> 0 | AS8: =_DATA_Assessment_Model!AP8 -> 0 | AT8: =_DATA_Assessment_Model!AQ8 -> 0 | ... AW8: =_DATA_Assessment_Model!AT8 -> 0.9 | AY8: =_DATA_Assessment_Model!AV8 -> 0.9
A9: Company Geography | B9: Company Geography | C9: 9 | D9: COMP-005 | E9: Company profile | F9: How mature is the organization in managing critical assets: people, facilities, systems, data, equipment and intellectual property, including ownership, evidence, metrics, fallback procedures and crisis stress testing? | G9: This topic affects exposure to Geopolitical risk; Physical site loss; Regulatory/legal shock. It helps identify how disruption may impact operations, people, revenue, systems, legal exposure or recovery time. | H9: ISO 22301; ISO 31000; ISO 9001; ISO 37000; PESTLE; Business Model Canvas | I9: Policy/SOP; owner/RACI; system report; dashboard; contracts; test records; incident history; interview evidence related to critical assets: people, facilities, systems, data, equipment and intellectual property. | J9: 5 | K9: =_DATA_Assessment_Model!H9 -> 0 | L9: =_DATA_Assessment_Model!I9 -> 0 | M9: =_DATA_Assessment_Model!J9 -> 5 | N9: =_DATA_Assessment_Model!K9 -> 5 | O9: =_DATA_Assessment_Model!L9 -> Critical | P9: Does not exist; no owner, no documentation, no practice. | Q9: Ad hoc; depends entirely on specific individuals. | R9: Partially documented or implemented; coverage inconsistent; never tested under stress. | S9: Documented, owned, executed consistently; basic evidence and metrics exist. | T9: Measured and periodically tested/audited; integrated with adjacent processes. | U9: Optimized and automated where practical; stress-tested; benchmarked externally. | V9: Geopolitical risk; Physical site loss; Regulatory/legal shock | Y9: Use the recommended action generated by the model; validate with domain owner during real assessment. | Z9: 5 | AA9: 5 | AB9: 5 | AM9: =_DATA_Assessment_Model!AJ9 -> 0.9 | AN9: =_DATA_Assessment_Model!AK9 -> 0.9 | AO9: =_DATA_Assessment_Model!AL9 -> 0 | AP9: =_DATA_Assessment_Model!AM9 -> 0 | AQ9: =_DATA_Assessment_Model!AN9 -> 0 | AR9: =_DATA_Assessment_Model!AO9 -> 0 | AS9: =_DATA_Assessment_Model!AP9 -> 0 | AT9: =_DATA_Assessment_Model!AQ9 -> 0 | ... AW9: =_DATA_Assessment_Model!AT9 -> 0.9 | AY9: =_DATA_Assessment_Model!AV9 -> 0.9
A10: Company Geography | B10: Company Geography | C10: 10 | D10: COMP-006 | E10: Company profile | F10: How mature is the organization in managing regulatory exposure by country, market, product and customer type, including ownership, evidence, metrics, fallback procedures and crisis stress testing? | G10: This topic affects exposure to Geopolitical risk; Physical site loss; Regulatory/legal shock. It helps identify how disruption may impact operations, people, revenue, systems, legal exposure or recovery time. | H10: ISO 22301; ISO 31000; ISO 9001; ISO 37000; PESTLE; Business Model Canvas | I10: Policy/SOP; owner/RACI; system report; dashboard; contracts; test records; incident history; interview evidence related to regulatory exposure by country, market, product and customer type. | J10: 4 | K10: =_DATA_Assessment_Model!H10 -> 0 | L10: =_DATA_Assessment_Model!I10 -> 0 | M10: =_DATA_Assessment_Model!J10 -> 4 | N10: =_DATA_Assessment_Model!K10 -> 4 | O10: =_DATA_Assessment_Model!L10 -> Critical | P10: No reliable evidence that regulatory exposure by country, market, product and customer type is defined, owned or managed. | Q10: Regulatory exposure by country, market, product and customer type is handled informally and depends on individual knowledge or heroic effort. | R10: Regulatory exposure by country, market, product and customer type is partially documented or implemented, but coverage is inconsistent and not crisis-tested. | S10: Regulatory exposure by country, market, product and customer type is documented, owned, used in normal operations and supported by basic evidence or metrics. | T10: Regulatory exposure by country, market, product and customer type is measured, periodically reviewed, integrated with related processes and tested against relevant disruption scenarios. | U10: Regulatory exposure by country, market, product and customer type is optimized, continuously improved, automated where practical and demonstrably supports crisis resilience. | V10: Geopolitical risk; Physical site loss; Regulatory/legal shock | Y10: Use the recommended action generated by the model; validate with domain owner during real assessment. | Z10: 4 | AA10: 5 | AB10: 5 | AM10: =_DATA_Assessment_Model!AJ10 -> 0.9 | AN10: =_DATA_Assessment_Model!AK10 -> 0.9 | AO10: =_DATA_Assessment_Model!AL10 -> 0 | AP10: =_DATA_Assessment_Model!AM10 -> 0 | AQ10: =_DATA_Assessment_Model!AN10 -> 0 | AR10: =_DATA_Assessment_Model!AO10 -> 0 | AS10: =_DATA_Assessment_Model!AP10 -> 0 | AT10: =_DATA_Assessment_Model!AQ10 -> 0 | ... AW10: =_DATA_Assessment_Model!AT10 -> 0.9 | AY10: =_DATA_Assessment_Model!AV10 -> 0.9
A11: Company Geography | B11: Company Geography | C11: 11 | D11: COMP-007 | E11: Company profile | F11: How mature is the organization in managing insurance coverage for business interruption, cyber, liability, property and key assets, including ownership, evidence, metrics, fallback procedures and crisis stress testing? | G11: This topic affects exposure to Geopolitical risk; Physical site loss; Regulatory/legal shock. It helps identify how disruption may impact operations, people, revenue, systems, legal exposure or recovery time. | H11: ISO 22301; ISO 31000; ISO 9001; ISO 37000; PESTLE; Business Model Canvas | I11: Policy/SOP; owner/RACI; system report; dashboard; contracts; test records; incident history; interview evidence related to insurance coverage for business interruption, cyber, liability, property and key assets. | J11: 5 | K11: =_DATA_Assessment_Model!H11 -> 0 | L11: =_DATA_Assessment_Model!I11 -> 0 | M11: =_DATA_Assessment_Model!J11 -> 5 | N11: =_DATA_Assessment_Model!K11 -> 5 | O11: =_DATA_Assessment_Model!L11 -> Critical | P11: Does not exist; no owner, no documentation, no practice. | Q11: Ad hoc; depends entirely on specific individuals. | R11: Partially documented or implemented; coverage inconsistent; never tested under stress. | S11: Documented, owned, executed consistently; basic evidence and metrics exist. | T11: Measured and periodically tested/audited; integrated with adjacent processes. | U11: Optimized and automated where practical; stress-tested; benchmarked externally. | V11: Geopolitical risk; Physical site loss; Regulatory/legal shock | Y11: Use the recommended action generated by the model; validate with domain owner during real assessment. | Z11: 5 | AA11: 5 | AB11: 5 | AM11: =_DATA_Assessment_Model!AJ11 -> 0.9 | AN11: =_DATA_Assessment_Model!AK11 -> 0.9 | AO11: =_DATA_Assessment_Model!AL11 -> 0 | AP11: =_DATA_Assessment_Model!AM11 -> 0 | AQ11: =_DATA_Assessment_Model!AN11 -> 0 | AR11: =_DATA_Assessment_Model!AO11 -> 0 | AS11: =_DATA_Assessment_Model!AP11 -> 0 | AT11: =_DATA_Assessment_Model!AQ11 -> 0 | ... AW11: =_DATA_Assessment_Model!AT11 -> 0.9 | AY11: =_DATA_Assessment_Model!AV11 -> 0.9
A12: Company Geography | B12: Company Geography | C12: 12 | D12: COMP-008 | E12: Geographical distribution | F12: How mature is the organization in managing workforce distribution by country, city, function, contract type and criticality, including ownership, evidence, metrics, fallback procedures and crisis stress testing? | G12: This topic affects exposure to Geopolitical risk; Physical site loss; Regulatory/legal shock. It helps identify how disruption may impact operations, people, revenue, systems, legal exposure or recovery time. | H12: ISO 22301; ISO 31000; ISO 9001; ISO 37000; PESTLE; Business Model Canvas | I12: Policy/SOP; owner/RACI; system report; dashboard; contracts; test records; incident history; interview evidence related to workforce distribution by country, city, function, contract type and criticality. | J12: 5 | K12: =_DATA_Assessment_Model!H12 -> 0 | L12: =_DATA_Assessment_Model!I12 -> 0 | M12: =_DATA_Assessment_Model!J12 -> 5 | N12: =_DATA_Assessment_Model!K12 -> 5 | O12: =_DATA_Assessment_Model!L12 -> Critical | P12: Does not exist; no owner, no documentation, no practice. | Q12: Ad hoc; depends entirely on specific individuals. | R12: Partially documented or implemented; coverage inconsistent; never tested under stress. | S12: Documented, owned, executed consistently; basic evidence and metrics exist. | T12: Measured and periodically tested/audited; integrated with adjacent processes. | U12: Optimized and automated where practical; stress-tested; benchmarked externally. | V12: Geopolitical risk; Physical site loss; Regulatory/legal shock | Y12: Use the recommended action generated by the model; validate with domain owner during real assessment. | Z12: 4 | AA12: 5 | AB12: 5 | AM12: =_DATA_Assessment_Model!AJ12 -> 0.9 | AN12: =_DATA_Assessment_Model!AK12 -> 0.9 | AO12: =_DATA_Assessment_Model!AL12 -> 0 | AP12: =_DATA_Assessment_Model!AM12 -> 0 | AQ12: =_DATA_Assessment_Model!AN12 -> 0 | AR12: =_DATA_Assessment_Model!AO12 -> 0 | AS12: =_DATA_Assessment_Model!AP12 -> 0 | AT12: =_DATA_Assessment_Model!AQ12 -> 0 | ... AW12: =_DATA_Assessment_Model!AT12 -> 0.9 | AY12: =_DATA_Assessment_Model!AV12 -> 0.9
A13: Company Geography | B13: Company Geography | C13: 13 | D13: COMP-009 | E13: Geographical distribution | F13: How mature is the organization in managing site distribution across offices, plants, warehouses, stores, labs and data centers, including ownership, evidence, metrics, fallback procedures and crisis stress testing? | G13: This topic affects exposure to Geopolitical risk; Physical site loss; Regulatory/legal shock. It helps identify how disruption may impact operations, people, revenue, systems, legal exposure or recovery time. | H13: ISO 22301; ISO 31000; ISO 9001; ISO 37000; PESTLE; Business Model Canvas | I13: Policy/SOP; owner/RACI; system report; dashboard; contracts; test records; incident history; interview evidence related to site distribution across offices, plants, warehouses, stores, labs and data centers. | J13: 5 | K13: =_DATA_Assessment_Model!H13 -> 0 | L13: =_DATA_Assessment_Model!I13 -> 0 | M13: =_DATA_Assessment_Model!J13 -> 5 | N13: =_DATA_Assessment_Model!K13 -> 5 | O13: =_DATA_Assessment_Model!L13 -> Critical | P13: No plan or procedure exists. | Q13: Knowledge lives with individuals; nothing usable is written down. | R13: Drafted but outdated, not approved, or unknown to the people who must use it. | S13: Approved and current; owners assigned; affected staff know it exists and where to find it. | T13: Tested against realistic scenarios; updated after each test or real incident. | U13: Exercised regularly including external parties; readiness measured; continuously improved. | V13: Geopolitical risk; Physical site loss; Regulatory/legal shock | Y13: Use the recommended action generated by the model; validate with domain owner during real assessment. | Z13: 5 | AA13: 5 | AB13: 5 | AM13: =_DATA_Assessment_Model!AJ13 -> 0.9 | AN13: =_DATA_Assessment_Model!AK13 -> 0.9 | AO13: =_DATA_Assessment_Model!AL13 -> 0 | AP13: =_DATA_Assessment_Model!AM13 -> 0 | AQ13: =_DATA_Assessment_Model!AN13 -> 0 | AR13: =_DATA_Assessment_Model!AO13 -> 0 | AS13: =_DATA_Assessment_Model!AP13 -> 0 | AT13: =_DATA_Assessment_Model!AQ13 -> 0 | ... AW13: =_DATA_Assessment_Model!AT13 -> 0.9 | AY13: =_DATA_Assessment_Model!AV13 -> 0.9
A14: Company Geography | B14: Company Geography | C14: 14 | D14: COMP-010 | E14: Geographical distribution | F14: How mature is the organization in managing revenue distribution by country, currency, customer geography and market exposure, including ownership, evidence, metrics, fallback procedures and crisis stress testing? | G14: This topic affects exposure to Geopolitical risk; Physical site loss; Regulatory/legal shock. It helps identify how disruption may impact operations, people, revenue, systems, legal exposure or recovery time. | H14: ISO 22301; ISO 31000; ISO 9001; ISO 37000; PESTLE; Business Model Canvas | I14: Policy/SOP; owner/RACI; system report; dashboard; contracts; test records; incident history; interview evidence related to revenue distribution by country, currency, customer geography and market exposure. | J14: 4 | K14: =_DATA_Assessment_Model!H14 -> 0 | L14: =_DATA_Assessment_Model!I14 -> 0 | M14: =_DATA_Assessment_Model!J14 -> 4 | N14: =_DATA_Assessment_Model!K14 -> 4 | O14: =_DATA_Assessment_Model!L14 -> Critical | P14: No reliable evidence that revenue distribution by country, currency, customer geography and market exposure is defined, owned or managed. | Q14: Revenue distribution by country, currency, customer geography and market exposure is handled informally and depends on individual knowledge or heroic effort. | R14: Revenue distribution by country, currency, customer geography and market exposure is partially documented or implemented, but coverage is inconsistent and not crisis-tested. | S14: Revenue distribution by country, currency, customer geography and market exposure is documented, owned, used in normal operations and supported by basic evidence or metrics. | T14: Revenue distribution by country, currency, customer geography and market exposure is measured, periodically reviewed, integrated with related processes and tested against relevant disruption scenarios. | U14: Revenue distribution by country, currency, customer geography and market exposure is optimized, continuously improved, automated where practical and demonstrably supports crisis resilience. | V14: Geopolitical risk; Physical site loss; Regulatory/legal shock | Y14: Use the recommended action generated by the model; validate with domain owner during real assessment. | Z14: 4 | AA14: 5 | AB14: 5 | AM14: =_DATA_Assessment_Model!AJ14 -> 0.9 | AN14: =_DATA_Assessment_Model!AK14 -> 0.9 | AO14: =_DATA_Assessment_Model!AL14 -> 0 | AP14: =_DATA_Assessment_Model!AM14 -> 0 | AQ14: =_DATA_Assessment_Model!AN14 -> 0 | AR14: =_DATA_Assessment_Model!AO14 -> 0 | AS14: =_DATA_Assessment_Model!AP14 -> 0 | AT14: =_DATA_Assessment_Model!AQ14 -> 0 | ... AW14: =_DATA_Assessment_Model!AT14 -> 0.9 | AY14: =_DATA_Assessment_Model!AV14 -> 0.9
A15: Company Geography | B15: Company Geography | C15: 15 | D15: COMP-011 | E15: Geographical distribution | F15: How mature is the organization in managing supplier distribution by country, tier, criticality and replacement options, including ownership, evidence, metrics, fallback procedures and crisis stress testing? | G15: This topic affects exposure to Geopolitical risk; Physical site loss; Regulatory/legal shock. It helps identify how disruption may impact operations, people, revenue, systems, legal exposure or recovery time. | H15: ISO 22301; ISO 31000; ISO 9001; ISO 37000; PESTLE; Business Model Canvas | I15: Policy/SOP; owner/RACI; system report; dashboard; contracts; test records; incident history; interview evidence related to supplier distribution by country, tier, criticality and replacement options. | J15: 5 | K15: =_DATA_Assessment_Model!H15 -> 0 | L15: =_DATA_Assessment_Model!I15 -> 0 | M15: =_DATA_Assessment_Model!J15 -> 5 | N15: =_DATA_Assessment_Model!K15 -> 5 | O15: =_DATA_Assessment_Model!L15 -> Critical | P15: Does not exist; no owner, no documentation, no practice. | Q15: Ad hoc; depends entirely on specific individuals. | R15: Partially documented or implemented; coverage inconsistent; never tested under stress. | S15: Documented, owned, executed consistently; basic evidence and metrics exist. | T15: Measured and periodically tested/audited; integrated with adjacent processes. | U15: Optimized and automated where practical; stress-tested; benchmarked externally. | V15: Geopolitical risk; Physical site loss; Regulatory/legal shock | Y15: Use the recommended action generated by the model; validate with domain owner during real assessment. | Z15: 4 | AA15: 5 | AB15: 5 | AM15: =_DATA_Assessment_Model!AJ15 -> 0.9 | AN15: =_DATA_Assessment_Model!AK15 -> 0.9 | AO15: =_DATA_Assessment_Model!AL15 -> 0 | AP15: =_DATA_Assessment_Model!AM15 -> 0 | AQ15: =_DATA_Assessment_Model!AN15 -> 0 | AR15: =_DATA_Assessment_Model!AO15 -> 0 | AS15: =_DATA_Assessment_Model!AP15 -> 0 | AT15: =_DATA_Assessment_Model!AQ15 -> 0 | ... AW15: =_DATA_Assessment_Model!AT15 -> 0.9 | AY15: =_DATA_Assessment_Model!AV15 -> 0.9
A16: Company Geography | B16: Company Geography | C16: 16 | D16: COMP-012 | E16: Geographical distribution | F16: How mature is the organization in managing customer distribution by geography, industry, contract and crisis sensitivity, including ownership, evidence, metrics, fallback procedures and crisis stress testing? | G16: This topic affects exposure to Geopolitical risk; Physical site loss; Regulatory/legal shock. It helps identify how disruption may impact operations, people, revenue, systems, legal exposure or recovery time. | H16: ISO 22301; ISO 31000; ISO 9001; ISO 37000; PESTLE; Business Model Canvas | I16: Policy/SOP; owner/RACI; system report; dashboard; contracts; test records; incident history; interview evidence related to customer distribution by geography, industry, contract and crisis sensitivity. | J16: 5 | K16: =_DATA_Assessment_Model!H16 -> 0 | L16: =_DATA_Assessment_Model!I16 -> 0 | M16: =_DATA_Assessment_Model!J16 -> 5 | N16: =_DATA_Assessment_Model!K16 -> 5 | O16: =_DATA_Assessment_Model!L16 -> Critical | P16: Does not exist; no owner, no documentation, no practice. | Q16: Ad hoc; depends entirely on specific individuals. | R16: Partially documented or implemented; coverage inconsistent; never tested under stress. | S16: Documented, owned, executed consistently; basic evidence and metrics exist. | T16: Measured and periodically tested/audited; integrated with adjacent processes. | U16: Optimized and automated where practical; stress-tested; benchmarked externally. | V16: Geopolitical risk; Physical site loss; Regulatory/legal shock | Y16: Use the recommended action generated by the model; validate with domain owner during real assessment. | Z16: 4 | AA16: 5 | AB16: 5 | AM16: =_DATA_Assessment_Model!AJ16 -> 0.9 | AN16: =_DATA_Assessment_Model!AK16 -> 0.9 | AO16: =_DATA_Assessment_Model!AL16 -> 0 | AP16: =_DATA_Assessment_Model!AM16 -> 0 | AQ16: =_DATA_Assessment_Model!AN16 -> 0 | AR16: =_DATA_Assessment_Model!AO16 -> 0 | AS16: =_DATA_Assessment_Model!AP16 -> 0 | AT16: =_DATA_Assessment_Model!AQ16 -> 0 | ... AW16: =_DATA_Assessment_Model!AT16 -> 0.9 | AY16: =_DATA_Assessment_Model!AV16 -> 0.9
A17: Company Geography | B17: Company Geography | C17: 17 | D17: COMP-013 | E17: Geographical distribution | F17: How mature is the organization in managing country risk monitoring for war, sanctions, political instability, natural disaster and energy risks, including ownership, evidence, metrics, fallback procedures and crisis stress testing? | G17: This topic affects exposure to Geopolitical risk; Physical site loss; Regulatory/legal shock. It helps identify how disruption may impact operations, people, revenue, systems, legal exposure or recovery time. | H17: ISO 22301; ISO 31000; ISO 9001; ISO 37000; PESTLE; Business Model Canvas | I17: Policy/SOP; owner/RACI; system report; dashboard; contracts; test records; incident history; interview evidence related to country risk monitoring for war, sanctions, political instability, natural disaster and energy risks. | J17: 4 | K17: =_DATA_Assessment_Model!H17 -> 0 | L17: =_DATA_Assessment_Model!I17 -> 0 | M17: =_DATA_Assessment_Model!J17 -> 4 | N17: =_DATA_Assessment_Model!K17 -> 4 | O17: =_DATA_Assessment_Model!L17 -> Critical | P17: No reliable evidence that country risk monitoring for war, sanctions, political instability, natural disaster and energy risks is defined, owned or managed. | Q17: Country risk monitoring for war, sanctions, political instability, natural disaster and energy risks is handled informally and depends on individual knowledge or heroic effort. | R17: Country risk monitoring for war, sanctions, political instability, natural disaster and energy risks is partially documented or implemented, but coverage is inconsistent and not crisis-tested. | S17: Country risk monitoring for war, sanctions, political instability, natural disaster and energy risks is documented, owned, used in normal operations and supported by basic evidence or metrics. | T17: Country risk monitoring for war, sanctions, political instability, natural disaster and energy risks is measured, periodically reviewed, integrated with related processes and tested against relevant disruption scenarios. | U17: Country risk monitoring for war, sanctions, political instability, natural disaster and energy risks is optimized, continuously improved, automated where practical and demonstrably supports crisis resilience. | V17: Geopolitical risk; Physical site loss; Regulatory/legal shock | Y17: Use the recommended action generated by the model; validate with domain owner during real assessment. | Z17: 4 | AA17: 5 | AB17: 5 | AM17: =_DATA_Assessment_Model!AJ17 -> 0.9 | AN17: =_DATA_Assessment_Model!AK17 -> 0.9 | AO17: =_DATA_Assessment_Model!AL17 -> 0 | AP17: =_DATA_Assessment_Model!AM17 -> 0 | AQ17: =_DATA_Assessment_Model!AN17 -> 0 | AR17: =_DATA_Assessment_Model!AO17 -> 0 | AS17: =_DATA_Assessment_Model!AP17 -> 0 | AT17: =_DATA_Assessment_Model!AQ17 -> 0 | ... AW17: =_DATA_Assessment_Model!AT17 -> 0.9 | AY17: =_DATA_Assessment_Model!AV17 -> 0.9
A18: Company Geography | B18: Company Geography | C18: 18 | D18: COMP-014 | E18: Geographical distribution | F18: How mature is the organization in managing relocation and alternative location options for critical teams and operations, including ownership, evidence, metrics, fallback procedures and crisis stress testing? | G18: This topic affects exposure to Geopolitical risk; Physical site loss; Regulatory/legal shock. It helps identify how disruption may impact operations, people, revenue, systems, legal exposure or recovery time. | H18: ISO 22301; ISO 31000; ISO 9001; ISO 37000; PESTLE; Business Model Canvas | I18: Policy/SOP; owner/RACI; system report; dashboard; contracts; test records; incident history; interview evidence related to relocation and alternative location options for critical teams and operations. | J18: 5 | K18: =_DATA_Assessment_Model!H18 -> 0 | L18: =_DATA_Assessment_Model!I18 -> 0 | M18: =_DATA_Assessment_Model!J18 -> 5 | N18: =_DATA_Assessment_Model!K18 -> 5 | O18: =_DATA_Assessment_Model!L18 -> Critical | P18: Does not exist; no owner, no documentation, no practice. | Q18: Ad hoc; depends entirely on specific individuals. | R18: Partially documented or implemented; coverage inconsistent; never tested under stress. | S18: Documented, owned, executed consistently; basic evidence and metrics exist. | T18: Measured and periodically tested/audited; integrated with adjacent processes. | U18: Optimized and automated where practical; stress-tested; benchmarked externally. | V18: Geopolitical risk; Physical site loss; Regulatory/legal shock | Y18: Use the recommended action generated by the model; validate with domain owner during real assessment. | Z18: 4 | AA18: 5 | AB18: 5 | AM18: =_DATA_Assessment_Model!AJ18 -> 0.9 | AN18: =_DATA_Assessment_Model!AK18 -> 0.9 | AO18: =_DATA_Assessment_Model!AL18 -> 0 | AP18: =_DATA_Assessment_Model!AM18 -> 0 | AQ18: =_DATA_Assessment_Model!AN18 -> 0 | AR18: =_DATA_Assessment_Model!AO18 -> 0 | AS18: =_DATA_Assessment_Model!AP18 -> 0 | AT18: =_DATA_Assessment_Model!AQ18 -> 0 | ... AW18: =_DATA_Assessment_Model!AT18 -> 0.9 | AY18: =_DATA_Assessment_Model!AV18 -> 0.9
A19: Company Geography | B19: Company Geography | C19: 19 | D19: COMP-016 | E19: Context and dependencies | F19: How mature is the organization in managing single-country, single-site and single-provider concentration risks, including ownership, evidence, metrics, fallback procedures and crisis stress testing? | G19: This topic affects exposure to Geopolitical risk; Physical site loss; Regulatory/legal shock. It helps identify how disruption may impact operations, people, revenue, systems, legal exposure or recovery time. | H19: ISO 22301; ISO 31000; ISO 9001; ISO 37000; PESTLE; Business Model Canvas | I19: Policy/SOP; owner/RACI; system report; dashboard; contracts; test records; incident history; interview evidence related to single-country, single-site and single-provider concentration risks. | J19: 5 | K19: =_DATA_Assessment_Model!H19 -> 0 | L19: =_DATA_Assessment_Model!I19 -> 0 | M19: =_DATA_Assessment_Model!J19 -> 5 | N19: =_DATA_Assessment_Model!K19 -> 5 | O19: =_DATA_Assessment_Model!L19 -> Critical | P19: Does not exist; no owner, no documentation, no practice. | Q19: Ad hoc; depends entirely on specific individuals. | R19: Partially documented or implemented; coverage inconsistent; never tested under stress. | S19: Documented, owned, executed consistently; basic evidence and metrics exist. | T19: Measured and periodically tested/audited; integrated with adjacent processes. | U19: Optimized and automated where practical; stress-tested; benchmarked externally. | V19: Geopolitical risk; Physical site loss; Regulatory/legal shock | Y19: Use the recommended action generated by the model; validate with domain owner during real assessment. | Z19: 4 | AA19: 5 | AB19: 5 | AM19: =_DATA_Assessment_Model!AJ19 -> 0.9 | AN19: =_DATA_Assessment_Model!AK19 -> 0.9 | AO19: =_DATA_Assessment_Model!AL19 -> 0 | AP19: =_DATA_Assessment_Model!AM19 -> 0 | AQ19: =_DATA_Assessment_Model!AN19 -> 0 | AR19: =_DATA_Assessment_Model!AO19 -> 0 | AS19: =_DATA_Assessment_Model!AP19 -> 0 | AT19: =_DATA_Assessment_Model!AQ19 -> 0 | ... AW19: =_DATA_Assessment_Model!AT19 -> 0.9 | AY19: =_DATA_Assessment_Model!AV19 -> 0.9
... A23: Company Geography | B23: Company Geography | C23: 23 | D23: COMP-021 | E23: Context and dependencies | F23: How mature is the organization in managing critical infrastructure status and government emergency obligations across operating geographies, including ownership, evidence, metrics, fallback procedures and crisis stress testing? | G23: This topic affects exposure to War/security crisis; Energy/utilities outage; Regulatory/legal shock. It helps identify how disruption may impact operations, people, revenue, systems, legal exposure or recovery time. | H23: ISO 22301; NIS2; national critical infrastructure regulation | I23: Policy/SOP; owner/RACI; system report; dashboard; contracts; test records; incident history; interview evidence | J23: 3 | K23: =_DATA_Assessment_Model!H23 -> 0 | L23: =_DATA_Assessment_Model!I23 -> 0 | M23: =_DATA_Assessment_Model!J23 -> 3 | N23: =_DATA_Assessment_Model!K23 -> 3 | O23: =_DATA_Assessment_Model!L23 -> Critical | P23: No reliable evidence that critical infrastructure status and government emergency obligations across operating geographies is defined, owned or managed. | Q23: Critical infrastructure status and government emergency obligations across operating geographies is handled informally and depends on individual knowledge or heroic effort. | R23: Critical infrastructure status and government emergency obligations across operating geographies is partially documented or implemented, but coverage is inconsistent and not crisis-tested. | S23: Critical infrastructure status and government emergency obligations across operating geographies is documented, owned, used in normal operations and supported by basic evidence or metrics. | T23: Critical infrastructure status and government emergency obligations across operating geographies is measured, periodically reviewed, integrated with related processes and tested against relevant disruption scenarios. | U23: Critical infrastructure status and government emergency obligations across operating geographies is optimized, continuously improved, automated where practical and demonstrably supports crisis resilience. | V23: War/security crisis; Energy/utilities outage; Regulatory/legal shock | Y23: Use the recommended action generated by the model; validate with domain owner during real assessment. | Z23: 2 | AA23: 4 | AB23: 4 | AM23: =_DATA_Assessment_Model!AJ23 -> 0.9 | AN23: =_DATA_Assessment_Model!AK23 -> 0.9 | AO23: =_DATA_Assessment_Model!AL23 -> 0 | AP23: =_DATA_Assessment_Model!AM23 -> 0 | AQ23: =_DATA_Assessment_Model!AN23 -> 0 | AR23: =_DATA_Assessment_Model!AO23 -> 0 | AS23: =_DATA_Assessment_Model!AP23 -> 0 | AT23: =_DATA_Assessment_Model!AQ23 -> 0 | ... AW23: =_DATA_Assessment_Model!AT23 -> 0.9 | AY23: =_DATA_Assessment_Model!AV23 -> 0.9
A24: Strategy GTM | B24: Strategy GTM | C24: 5 | D24: STRA-001 | E24: Corporate strategy | F24: How mature is the organization in managing documented strategy translated into objectives, KPIs, budgets and accountable owners, including ownership, evidence, metrics, fallback procedures and crisis stress testing? | G24: This topic affects exposure to Demand shock; Financial / liquidity shock; Reputation crisis. It helps identify how disruption may impact operations, people, revenue, systems, legal exposure or recovery time. | H24: ISO 9001; ISO 31000; ISO 37000; McKinsey 7S; OHI; Bain Elements of Value; Jobs-to-be-Done; Porter Five Forces; OKR | I24: Policy/SOP; owner/RACI; system report; dashboard; contracts; test records; incident history; interview evidence related to documented strategy translated into objectives, KPIs, budgets and accountable owners. | J24: 4 | K24: =_DATA_Assessment_Model!H24 -> 0 | L24: =_DATA_Assessment_Model!I24 -> 0 | M24: =_DATA_Assessment_Model!J24 -> 4 | N24: =_DATA_Assessment_Model!K24 -> 4 | O24: =_DATA_Assessment_Model!L24 -> Critical | P24: No reliable evidence that documented strategy translated into objectives, kpis, budgets and accountable owners is defined, owned or managed. | Q24: Documented strategy translated into objectives, KPIs, budgets and accountable owners is handled informally and depends on individual knowledge or heroic effort. | R24: Documented strategy translated into objectives, KPIs, budgets and accountable owners is partially documented or implemented, but coverage is inconsistent and not crisis-tested. | S24: Documented strategy translated into objectives, KPIs, budgets and accountable owners is documented, owned, used in normal operations and supported by basic evidence or metrics. | T24: Documented strategy translated into objectives, KPIs, budgets and accountable owners is measured, periodically reviewed, integrated with related processes and tested against relevant disruption scenarios. | U24: Documented strategy translated into objectives, KPIs, budgets and accountable owners is optimized, continuously improved, automated where practical and demonstrably supports crisis resilience. | V24: Demand shock; Financial / liquidity shock; Reputation crisis | Y24: Use the recommended action generated by the model; validate with domain owner during real assessment. | Z24: 4 | AA24: 5 | AB24: 5 | AD24: Corporate strategy | AE24: =_DATA_Assessment_Model!AB24 -> 6 | AF24: =_DATA_Assessment_Model!AC24 -> 0 | AG24: =_DATA_Assessment_Model!AD24 -> 0 | AH24: =_DATA_Assessment_Model!AE24 -> 6 | AI24: =_DATA_Assessment_Model!AF24 -> 5 | AJ24: =_DATA_Assessment_Model!AG24 -> 6 | AM24: =_DATA_Assessment_Model!AJ24 -> 0.9 | AN24: =_DATA_Assessment_Model!AK24 -> 0.9 | AO24: =_DATA_Assessment_Model!AL24 -> 0 | AP24: =_DATA_Assessment_Model!AM24 -> 0 | AQ24: =_DATA_Assessment_Model!AN24 -> 0 | AR24: =_DATA_Assessment_Model!AO24 -> 0 | AS24: =_DATA_Assessment_Model!AP24 -> 0 | AT24: =_DATA_Assessment_Model!AQ24 -> 0 | ... AW24: =_DATA_Assessment_Model!AT24 -> 0.9 | AY24: =_DATA_Assessment_Model!AV24 -> 0.9
