Workbook

Sheet ① START HERE
B1: Business Resilience Workbook — Start Here
B2: How to read this file, what to fill in, and where to look for answers.
B4: TAB COLOUR LEGEND (see the coloured tabs at the bottom)
C5: Start / guide — This sheet.
C6: Green = Executive insight — Outputs to read & present. Do NOT type here — they update automatically.
C7: Orange = Your input — Fill these in. Assessment scores, company profile, crisis selection.
C8: Gold = Calibration (careful) — Weights / pairwise judgements. Powerful — change deliberately, watch the consistency check.
C9: Blue = Reference / guide — Read-only explanations, scoring scales, standards, methodology.
C10: Grey = Internal engine — Hidden calculation libraries. Don't edit unless you know the model. Right-click a tab > Unhide to view.
B12: CELL COLOUR LEGEND
C13: Enter a value — Yellow cells are inputs — type your answer / number here.
C14: Adjust carefully — Light-orange cells are weights or parameters. Sensible defaults are set; change deliberately.
C15: Optional input — Pale-yellow cells are optional refinements (e.g., evidence/assessor confidence).
C16: No fill = automatic — Uncoloured cells are formula-driven. Don't type over them or you'll break the logic.
B18: RECOMMENDED WORKFLOW
B19: 1. Company Profile | C19: Fill the orange cells: industry, size, geography, concentration, critical processes. This drives targets, SPOF and strategy logic.
B20: 2. Score the 17 domains | C20: On each orange domain tab (Company Geography … Cyber Privacy), enter a 0–5 score in the yellow Score column. Use the Scoring Guide (blue) for the scale. Optionally set evidence/assessor confidence.
B21: 3. Pick a crisis | C21: On Crisis Simulator choose a scenario and severity (1–5).
B22: 4. Calibrate weights (optional) | C22: On AHP Domain Weights (gold) adjust the pillar pairwise judgements; keep the Consistency Ratio < 0.10.
B23: 5. Read the outputs | C23: Green tabs: Dashboard, Scoring Model v2, Resilience Engine (Cascade), Risk Summary, Executive Recommendations, Initiative Economics, Gantt Roadmap.
B24: 6. Quality check | C24: Quality Control (blue) flags missing/low-confidence answers before you present.
B26: GOOD TO KNOW
C27: • Unanswered domains are treated as blank (not zero) and excluded from averages — fill what's relevant, mark the rest N/A.
C28: • Two maturity views exist: the original Dashboard (simple weighted average) and Scoring Model v2 (confidence-adjusted, with additive / geometric / penalty aggregation). Geometric & penalty punish weak links.
C29: • Risk has a cross-domain Cascade view (Resilience Engine) — a failure in one domain raises risk in coupled domains.
C30: • Initiative Economics needs you to enter € investment/benefit (yellow) for ROI/NPV and budget selection to mean anything.
C31: • Methodology tabs (blue) explain every formula. Internal grey _TECH_ tabs are the engine — leave them alone.

Sheet Dashboard
A1: Crisis Management Assessment Dashboard
A2: How to use: fill Score 0-5 or N/A in each domain tab; add evidence and comments; review Critical/High gaps; then build crisis-specific mitigation roadmaps. The focus is crisis impact across people, geography, physical safety, suppliers, manufacturing, systems, cloud, data, cybersecurity, strategy and GTM.
A4: Domain | B4: Questions | C4: Answered | D4: Completion % | E4: Weighted score | F4: Max score | G4: Maturity % | H4: Maturity 0-5 | I4: Gap | J4: Critical | K4: High | L4: Medium | M4: Low | N4: Resilient | O4: Priority note | Q4: Overall metric | R4: Value | S4: Interpretation
A5: Company Geography | B5: 20 | C5: =COUNTIF('Company Geography'!$H$5:$H$24,"N/A")+COUNTIF('Company Geography'!$H$5:$H$24,"0")+COUNTIF('Company Geography'!$H$5:$H$24,"1")+COUNTIF('Company Geography'!$H$5:$H$24,"2")+COUNTIF('Company Geography'!$H$5:$H$24,"3")+COUNTIF('Company Geography'!$H$5:$H$24,"4")+COUNTIF('Company Geography'!$H$5:$H$24,"5") -> 0 | D5: =IFERROR(C5/B5,0) -> 0 | E5: =SUM('Company Geography'!$I$5:$I$24) -> 0 | F5: =SUM('Company Geography'!$J$5:$J$24) -> 0 | G5: =IFERROR(E5/F5,0) -> 0 | H5: =G5*5 -> 0 | I5: =SUM('Company Geography'!$K$5:$K$24) -> 0 | J5: =COUNTIF('Company Geography'!$L$5:$L$24,"Critical") -> 0 | K5: =COUNTIF('Company Geography'!$L$5:$L$24,"High") -> 0 | L5: =COUNTIF('Company Geography'!$L$5:$L$24,"Medium") -> 0 | M5: =COUNTIF('Company Geography'!$L$5:$L$24,"Low") -> 0 | N5: =COUNTIF('Company Geography'!$L$5:$L$24,"Resilient") -> 0 | O5: =IF(J5+K5>0,"Review critical/high-risk gaps",IF(D5<1,"Complete assessment","Monitor and improve")) -> Complete assessment | Q5: Total questions | R5: =SUM(B5:B21) -> 407 | S5: Total number of questions across all domains.
A6: Strategy GTM | B6: 24 | C6: =COUNTIF('Strategy GTM'!$H$5:$H$28,"N/A")+COUNTIF('Strategy GTM'!$H$5:$H$28,"0")+COUNTIF('Strategy GTM'!$H$5:$H$28,"1")+COUNTIF('Strategy GTM'!$H$5:$H$28,"2")+COUNTIF('Strategy GTM'!$H$5:$H$28,"3")+COUNTIF('Strategy GTM'!$H$5:$H$28,"4")+COUNTIF('Strategy GTM'!$H$5:$H$28,"5") -> 0 | D6: =IFERROR(C6/B6,0) -> 0 | E6: =SUM('Strategy GTM'!$I$5:$I$28) -> 0 | F6: =SUM('Strategy GTM'!$J$5:$J$28) -> 0 | G6: =IFERROR(E6/F6,0) -> 0 | H6: =G6*5 -> 0 | I6: =SUM('Strategy GTM'!$K$5:$K$28) -> 0 | J6: =COUNTIF('Strategy GTM'!$L$5:$L$28,"Critical") -> 0 | K6: =COUNTIF('Strategy GTM'!$L$5:$L$28,"High") -> 0 | L6: =COUNTIF('Strategy GTM'!$L$5:$L$28,"Medium") -> 0 | M6: =COUNTIF('Strategy GTM'!$L$5:$L$28,"Low") -> 0 | N6: =COUNTIF('Strategy GTM'!$L$5:$L$28,"Resilient") -> 0 | O6: =IF(J6+K6>0,"Review critical/high-risk gaps",IF(D6<1,"Complete assessment","Monitor and improve")) -> Complete assessment | Q6: Answered questions | R6: =SUM(C5:C21) -> 0 | S6: Includes N/A as answered.
A7: Governance Crisis | B7: 19 | C7: =COUNTIF('Governance Crisis'!$H$5:$H$23,"N/A")+COUNTIF('Governance Crisis'!$H$5:$H$23,"0")+COUNTIF('Governance Crisis'!$H$5:$H$23,"1")+COUNTIF('Governance Crisis'!$H$5:$H$23,"2")+COUNTIF('Governance Crisis'!$H$5:$H$23,"3")+COUNTIF('Governance Crisis'!$H$5:$H$23,"4")+COUNTIF('Governance Crisis'!$H$5:$H$23,"5") -> 0 | D7: =IFERROR(C7/B7,0) -> 0 | E7: =SUM('Governance Crisis'!$I$5:$I$23) -> 0 | F7: =SUM('Governance Crisis'!$J$5:$J$23) -> 0 | G7: =IFERROR(E7/F7,0) -> 0 | H7: =G7*5 -> 0 | I7: =SUM('Governance Crisis'!$K$5:$K$23) -> 0 | J7: =COUNTIF('Governance Crisis'!$L$5:$L$23,"Critical") -> 0 | K7: =COUNTIF('Governance Crisis'!$L$5:$L$23,"High") -> 0 | L7: =COUNTIF('Governance Crisis'!$L$5:$L$23,"Medium") -> 0 | M7: =COUNTIF('Governance Crisis'!$L$5:$L$23,"Low") -> 0 | N7: =COUNTIF('Governance Crisis'!$L$5:$L$23,"Resilient") -> 0 | O7: =IF(J7+K7>0,"Review critical/high-risk gaps",IF(D7<1,"Complete assessment","Monitor and improve")) -> Complete assessment | Q7: Overall completion | R7: =IFERROR(R6/R5,0) -> 0 | S7: Target: 100% before final diagnosis.
A8: HR Workforce | B8: 24 | C8: =COUNTIF('HR Workforce'!$H$5:$H$28,"N/A")+COUNTIF('HR Workforce'!$H$5:$H$28,"0")+COUNTIF('HR Workforce'!$H$5:$H$28,"1")+COUNTIF('HR Workforce'!$H$5:$H$28,"2")+COUNTIF('HR Workforce'!$H$5:$H$28,"3")+COUNTIF('HR Workforce'!$H$5:$H$28,"4")+COUNTIF('HR Workforce'!$H$5:$H$28,"5") -> 0 | D8: =IFERROR(C8/B8,0) -> 0 | E8: =SUM('HR Workforce'!$I$5:$I$28) -> 0 | F8: =SUM('HR Workforce'!$J$5:$J$28) -> 0 | G8: =IFERROR(E8/F8,0) -> 0 | H8: =G8*5 -> 0 | I8: =SUM('HR Workforce'!$K$5:$K$28) -> 0 | J8: =COUNTIF('HR Workforce'!$L$5:$L$28,"Critical") -> 0 | K8: =COUNTIF('HR Workforce'!$L$5:$L$28,"High") -> 0 | L8: =COUNTIF('HR Workforce'!$L$5:$L$28,"Medium") -> 0 | M8: =COUNTIF('HR Workforce'!$L$5:$L$28,"Low") -> 0 | N8: =COUNTIF('HR Workforce'!$L$5:$L$28,"Resilient") -> 0 | O8: =IF(J8+K8>0,"Review critical/high-risk gaps",IF(D8<1,"Complete assessment","Monitor and improve")) -> Complete assessment | Q8: Overall maturity % | R8: =IFERROR(SUM(E5:E21)/SUM(F5:F21),0) -> 0 | S8: Weighted resilience maturity across answered items.
A9: Finance Procurement | B9: 24 | C9: =COUNTIF('Finance Procurement'!$H$5:$H$28,"N/A")+COUNTIF('Finance Procurement'!$H$5:$H$28,"0")+COUNTIF('Finance Procurement'!$H$5:$H$28,"1")+COUNTIF('Finance Procurement'!$H$5:$H$28,"2")+COUNTIF('Finance Procurement'!$H$5:$H$28,"3")+COUNTIF('Finance Procurement'!$H$5:$H$28,"4")+COUNTIF('Finance Procurement'!$H$5:$H$28,"5") -> 0 | D9: =IFERROR(C9/B9,0) -> 0 | E9: =SUM('Finance Procurement'!$I$5:$I$28) -> 0 | F9: =SUM('Finance Procurement'!$J$5:$J$28) -> 0 | G9: =IFERROR(E9/F9,0) -> 0 | H9: =G9*5 -> 0 | I9: =SUM('Finance Procurement'!$K$5:$K$28) -> 0 | J9: =COUNTIF('Finance Procurement'!$L$5:$L$28,"Critical") -> 0 | K9: =COUNTIF('Finance Procurement'!$L$5:$L$28,"High") -> 0 | L9: =COUNTIF('Finance Procurement'!$L$5:$L$28,"Medium") -> 0 | M9: =COUNTIF('Finance Procurement'!$L$5:$L$28,"Low") -> 0 | N9: =COUNTIF('Finance Procurement'!$L$5:$L$28,"Resilient") -> 0 | O9: =IF(J9+K9>0,"Review critical/high-risk gaps",IF(D9<1,"Complete assessment","Monitor and improve")) -> Complete assessment | Q9: Overall maturity 0-5 | R9: =R8*5 -> 0 | S9: 0 = absent, 5 = optimized/resilient.
A10: Legal Risk | B10: 20 | C10: =COUNTIF('Legal Risk'!$H$5:$H$24,"N/A")+COUNTIF('Legal Risk'!$H$5:$H$24,"0")+COUNTIF('Legal Risk'!$H$5:$H$24,"1")+COUNTIF('Legal Risk'!$H$5:$H$24,"2")+COUNTIF('Legal Risk'!$H$5:$H$24,"3")+COUNTIF('Legal Risk'!$H$5:$H$24,"4")+COUNTIF('Legal Risk'!$H$5:$H$24,"5") -> 0 | D10: =IFERROR(C10/B10,0) -> 0 | E10: =SUM('Legal Risk'!$I$5:$I$24) -> 0 | F10: =SUM('Legal Risk'!$J$5:$J$24) -> 0 | G10: =IFERROR(E10/F10,0) -> 0 | H10: =G10*5 -> 0 | I10: =SUM('Legal Risk'!$K$5:$K$24) -> 0 | J10: =COUNTIF('Legal Risk'!$L$5:$L$24,"Critical") -> 0 | K10: =COUNTIF('Legal Risk'!$L$5:$L$24,"High") -> 0 | L10: =COUNTIF('Legal Risk'!$L$5:$L$24,"Medium") -> 0 | M10: =COUNTIF('Legal Risk'!$L$5:$L$24,"Low") -> 0 | N10: =COUNTIF('Legal Risk'!$L$5:$L$24,"Resilient") -> 0 | O10: =IF(J10+K10>0,"Review critical/high-risk gaps",IF(D10<1,"Complete assessment","Monitor and improve")) -> Complete assessment | Q10: Critical items | R10: =SUM(J5:J21) -> 0 | S10: Immediate action required.
A11: Physical Safety | B11: 28 | C11: =COUNTIF('Physical Safety'!$H$5:$H$32,"N/A")+COUNTIF('Physical Safety'!$H$5:$H$32,"0")+COUNTIF('Physical Safety'!$H$5:$H$32,"1")+COUNTIF('Physical Safety'!$H$5:$H$32,"2")+COUNTIF('Physical Safety'!$H$5:$H$32,"3")+COUNTIF('Physical Safety'!$H$5:$H$32,"4")+COUNTIF('Physical Safety'!$H$5:$H$32,"5") -> 0 | D11: =IFERROR(C11/B11,0) -> 0 | E11: =SUM('Physical Safety'!$I$5:$I$32) -> 0 | F11: =SUM('Physical Safety'!$J$5:$J$32) -> 0 | G11: =IFERROR(E11/F11,0) -> 0 | H11: =G11*5 -> 0 | I11: =SUM('Physical Safety'!$K$5:$K$32) -> 0 | J11: =COUNTIF('Physical Safety'!$L$5:$L$32,"Critical") -> 0 | K11: =COUNTIF('Physical Safety'!$L$5:$L$32,"High") -> 0 | L11: =COUNTIF('Physical Safety'!$L$5:$L$32,"Medium") -> 0 | M11: =COUNTIF('Physical Safety'!$L$5:$L$32,"Low") -> 0 | N11: =COUNTIF('Physical Safety'!$L$5:$L$32,"Resilient") -> 0 | O11: =IF(J11+K11>0,"Review critical/high-risk gaps",IF(D11<1,"Complete assessment","Monitor and improve")) -> Complete assessment | Q11: High-risk items | R11: =SUM(K5:K21) -> 0 | S11: Near-term mitigation required.
A12: Delivery Ops | B12: 24 | C12: =COUNTIF('Delivery Ops'!$H$5:$H$28,"N/A")+COUNTIF('Delivery Ops'!$H$5:$H$28,"0")+COUNTIF('Delivery Ops'!$H$5:$H$28,"1")+COUNTIF('Delivery Ops'!$H$5:$H$28,"2")+COUNTIF('Delivery Ops'!$H$5:$H$28,"3")+COUNTIF('Delivery Ops'!$H$5:$H$28,"4")+COUNTIF('Delivery Ops'!$H$5:$H$28,"5") -> 0 | D12: =IFERROR(C12/B12,0) -> 0 | E12: =SUM('Delivery Ops'!$I$5:$I$28) -> 0 | F12: =SUM('Delivery Ops'!$J$5:$J$28) -> 0 | G12: =IFERROR(E12/F12,0) -> 0 | H12: =G12*5 -> 0 | I12: =SUM('Delivery Ops'!$K$5:$K$28) -> 0 | J12: =COUNTIF('Delivery Ops'!$L$5:$L$28,"Critical") -> 0 | K12: =COUNTIF('Delivery Ops'!$L$5:$L$28,"High") -> 0 | L12: =COUNTIF('Delivery Ops'!$L$5:$L$28,"Medium") -> 0 | M12: =COUNTIF('Delivery Ops'!$L$5:$L$28,"Low") -> 0 | N12: =COUNTIF('Delivery Ops'!$L$5:$L$28,"Resilient") -> 0 | O12: =IF(J12+K12>0,"Review critical/high-risk gaps",IF(D12<1,"Complete assessment","Monitor and improve")) -> Complete assessment | Q12: Total weighted gap | R12: =SUM(I5:I21) -> 0 | S12: Weighted improvement opportunity.
A13: Supply Chain | B13: 25 | C13: =COUNTIF('Supply Chain'!$H$5:$H$29,"N/A")+COUNTIF('Supply Chain'!$H$5:$H$29,"0")+COUNTIF('Supply Chain'!$H$5:$H$29,"1")+COUNTIF('Supply Chain'!$H$5:$H$29,"2")+COUNTIF('Supply Chain'!$H$5:$H$29,"3")+COUNTIF('Supply Chain'!$H$5:$H$29,"4")+COUNTIF('Supply Chain'!$H$5:$H$29,"5") -> 0 | D13: =IFERROR(C13/B13,0) -> 0 | E13: =SUM('Supply Chain'!$I$5:$I$29) -> 0 | F13: =SUM('Supply Chain'!$J$5:$J$29) -> 0 | G13: =IFERROR(E13/F13,0) -> 0 | H13: =G13*5 -> 0 | I13: =SUM('Supply Chain'!$K$5:$K$29) -> 0 | J13: =COUNTIF('Supply Chain'!$L$5:$L$29,"Critical") -> 0 | K13: =COUNTIF('Supply Chain'!$L$5:$L$29,"High") -> 0 | L13: =COUNTIF('Supply Chain'!$L$5:$L$29,"Medium") -> 0 | M13: =COUNTIF('Supply Chain'!$L$5:$L$29,"Low") -> 0 | N13: =COUNTIF('Supply Chain'!$L$5:$L$29,"Resilient") -> 0 | O13: =IF(J13+K13>0,"Review critical/high-risk gaps",IF(D13<1,"Complete assessment","Monitor and improve")) -> Complete assessment | Q13: Selected crisis scenario | R13: ='Crisis Simulator'!$B$4 -> War / security crisis | S13: Used by scenario-adjusted risk and strategy logic.
A14: Manufacturing MES | B14: 28 | C14: =COUNTIF('Manufacturing MES'!$H$5:$H$32,"N/A")+COUNTIF('Manufacturing MES'!$H$5:$H$32,"0")+COUNTIF('Manufacturing MES'!$H$5:$H$32,"1")+COUNTIF('Manufacturing MES'!$H$5:$H$32,"2")+COUNTIF('Manufacturing MES'!$H$5:$H$32,"3")+COUNTIF('Manufacturing MES'!$H$5:$H$32,"4")+COUNTIF('Manufacturing MES'!$H$5:$H$32,"5") -> 0 | D14: =IFERROR(C14/B14,0) -> 0 | E14: =SUM('Manufacturing MES'!$I$5:$I$32) -> 0 | F14: =SUM('Manufacturing MES'!$J$5:$J$32) -> 0 | G14: =IFERROR(E14/F14,0) -> 0 | H14: =G14*5 -> 0 | I14: =SUM('Manufacturing MES'!$K$5:$K$32) -> 0 | J14: =COUNTIF('Manufacturing MES'!$L$5:$L$32,"Critical") -> 0 | K14: =COUNTIF('Manufacturing MES'!$L$5:$L$32,"High") -> 0 | L14: =COUNTIF('Manufacturing MES'!$L$5:$L$32,"Medium") -> 0 | M14: =COUNTIF('Manufacturing MES'!$L$5:$L$32,"Low") -> 0 | N14: =COUNTIF('Manufacturing MES'!$L$5:$L$32,"Resilient") -> 0 | O14: =IF(J14+K14>0,"Review critical/high-risk gaps",IF(D14<1,"Complete assessment","Monitor and improve")) -> Complete assessment | Q14: Crisis severity | R14: ='Crisis Simulator'!$B$5 -> 3 | S14: 1 mild; 3 base; 5 severe.
A15: Sales CRM | B15: 21 | C15: =COUNTIF('Sales CRM'!$H$5:$H$25,"N/A")+COUNTIF('Sales CRM'!$H$5:$H$25,"0")+COUNTIF('Sales CRM'!$H$5:$H$25,"1")+COUNTIF('Sales CRM'!$H$5:$H$25,"2")+COUNTIF('Sales CRM'!$H$5:$H$25,"3")+COUNTIF('Sales CRM'!$H$5:$H$25,"4")+COUNTIF('Sales CRM'!$H$5:$H$25,"5") -> 0 | D15: =IFERROR(C15/B15,0) -> 0 | E15: =SUM('Sales CRM'!$I$5:$I$25) -> 0 | F15: =SUM('Sales CRM'!$J$5:$J$25) -> 0 | G15: =IFERROR(E15/F15,0) -> 0 | H15: =G15*5 -> 0 | I15: =SUM('Sales CRM'!$K$5:$K$25) -> 0 | J15: =COUNTIF('Sales CRM'!$L$5:$L$25,"Critical") -> 0 | K15: =COUNTIF('Sales CRM'!$L$5:$L$25,"High") -> 0 | L15: =COUNTIF('Sales CRM'!$L$5:$L$25,"Medium") -> 0 | M15: =COUNTIF('Sales CRM'!$L$5:$L$25,"Low") -> 0 | N15: =COUNTIF('Sales CRM'!$L$5:$L$25,"Resilient") -> 0 | O15: =IF(J15+K15>0,"Review critical/high-risk gaps",IF(D15<1,"Complete assessment","Monitor and improve")) -> Complete assessment | Q15: Top exposed domain | R15: ='Crisis Simulator'!$O$7 | S15: Domain with highest scenario-adjusted exposure.
A16: Marketing Comms | B16: 17 | C16: =COUNTIF('Marketing Comms'!$H$5:$H$21,"N/A")+COUNTIF('Marketing Comms'!$H$5:$H$21,"0")+COUNTIF('Marketing Comms'!$H$5:$H$21,"1")+COUNTIF('Marketing Comms'!$H$5:$H$21,"2")+COUNTIF('Marketing Comms'!$H$5:$H$21,"3")+COUNTIF('Marketing Comms'!$H$5:$H$21,"4")+COUNTIF('Marketing Comms'!$H$5:$H$21,"5") -> 0 | D16: =IFERROR(C16/B16,0) -> 0 | E16: =SUM('Marketing Comms'!$I$5:$I$21) -> 0 | F16: =SUM('Marketing Comms'!$J$5:$J$21) -> 0 | G16: =IFERROR(E16/F16,0) -> 0 | H16: =G16*5 -> 0 | I16: =SUM('Marketing Comms'!$K$5:$K$21) -> 0 | J16: =COUNTIF('Marketing Comms'!$L$5:$L$21,"Critical") -> 0 | K16: =COUNTIF('Marketing Comms'!$L$5:$L$21,"High") -> 0 | L16: =COUNTIF('Marketing Comms'!$L$5:$L$21,"Medium") -> 0 | M16: =COUNTIF('Marketing Comms'!$L$5:$L$21,"Low") -> 0 | N16: =COUNTIF('Marketing Comms'!$L$5:$L$21,"Resilient") -> 0 | O16: =IF(J16+K16>0,"Review critical/high-risk gaps",IF(D16<1,"Complete assessment","Monitor and improve")) -> Complete assessment | Q16: Primary strategy | R16: ='Strategy Selection'!$B$6 | S16: Highest-scoring strategy under the selected crisis scenario.
A17: IT Cloud DR | B17: 29 | C17: =COUNTIF('IT Cloud DR'!$H$5:$H$33,"N/A")+COUNTIF('IT Cloud DR'!$H$5:$H$33,"0")+COUNTIF('IT Cloud DR'!$H$5:$H$33,"1")+COUNTIF('IT Cloud DR'!$H$5:$H$33,"2")+COUNTIF('IT Cloud DR'!$H$5:$H$33,"3")+COUNTIF('IT Cloud DR'!$H$5:$H$33,"4")+COUNTIF('IT Cloud DR'!$H$5:$H$33,"5") -> 0 | D17: =IFERROR(C17/B17,0) -> 0 | E17: =SUM('IT Cloud DR'!$I$5:$I$33) -> 0 | F17: =SUM('IT Cloud DR'!$J$5:$J$33) -> 0 | G17: =IFERROR(E17/F17,0) -> 0 | H17: =G17*5 -> 0 | I17: =SUM('IT Cloud DR'!$K$5:$K$33) -> 0 | J17: =COUNTIF('IT Cloud DR'!$L$5:$L$33,"Critical") -> 0 | K17: =COUNTIF('IT Cloud DR'!$L$5:$L$33,"High") -> 0 | L17: =COUNTIF('IT Cloud DR'!$L$5:$L$33,"Medium") -> 0 | M17: =COUNTIF('IT Cloud DR'!$L$5:$L$33,"Low") -> 0 | N17: =COUNTIF('IT Cloud DR'!$L$5:$L$33,"Resilient") -> 0 | O17: =IF(J17+K17>0,"Review critical/high-risk gaps",IF(D17<1,"Complete assessment","Monitor and improve")) -> Complete assessment
A18: Business Systems | B18: 23 | C18: =COUNTIF('Business Systems'!$H$5:$H$27,"N/A")+COUNTIF('Business Systems'!$H$5:$H$27,"0")+COUNTIF('Business Systems'!$H$5:$H$27,"1")+COUNTIF('Business Systems'!$H$5:$H$27,"2")+COUNTIF('Business Systems'!$H$5:$H$27,"3")+COUNTIF('Business Systems'!$H$5:$H$27,"4")+COUNTIF('Business Systems'!$H$5:$H$27,"5") -> 0 | D18: =IFERROR(C18/B18,0) -> 0 | E18: =SUM('Business Systems'!$I$5:$I$27) -> 0 | F18: =SUM('Business Systems'!$J$5:$J$27) -> 0 | G18: =IFERROR(E18/F18,0) -> 0 | H18: =G18*5 -> 0 | I18: =SUM('Business Systems'!$K$5:$K$27) -> 0 | J18: =COUNTIF('Business Systems'!$L$5:$L$27,"Critical") -> 0 | K18: =COUNTIF('Business Systems'!$L$5:$L$27,"High") -> 0 | L18: =COUNTIF('Business Systems'!$L$5:$L$27,"Medium") -> 0 | M18: =COUNTIF('Business Systems'!$L$5:$L$27,"Low") -> 0 | N18: =COUNTIF('Business Systems'!$L$5:$L$27,"Resilient") -> 0 | O18: =IF(J18+K18>0,"Review critical/high-risk gaps",IF(D18<1,"Complete assessment","Monitor and improve")) -> Complete assessment
A19: Data BI AI | B19: 27 | C19: =COUNTIF('Data BI AI'!$H$5:$H$31,"N/A")+COUNTIF('Data BI AI'!$H$5:$H$31,"0")+COUNTIF('Data BI AI'!$H$5:$H$31,"1")+COUNTIF('Data BI AI'!$H$5:$H$31,"2")+COUNTIF('Data BI AI'!$H$5:$H$31,"3")+COUNTIF('Data BI AI'!$H$5:$H$31,"4")+COUNTIF('Data BI AI'!$H$5:$H$31,"5") -> 0 | D19: =IFERROR(C19/B19,0) -> 0 | E19: =SUM('Data BI AI'!$I$5:$I$31) -> 0 | F19: =SUM('Data BI AI'!$J$5:$J$31) -> 0 | G19: =IFERROR(E19/F19,0) -> 0 | H19: =G19*5 -> 0 | I19: =SUM('Data BI AI'!$K$5:$K$31) -> 0 | J19: =COUNTIF('Data BI AI'!$L$5:$L$31,"Critical") -> 0 | K19: =COUNTIF('Data BI AI'!$L$5:$L$31,"High") -> 0 | L19: =COUNTIF('Data BI AI'!$L$5:$L$31,"Medium") -> 0 | M19: =COUNTIF('Data BI AI'!$L$5:$L$31,"Low") -> 0 | N19: =COUNTIF('Data BI AI'!$L$5:$L$31,"Resilient") -> 0 | O19: =IF(J19+K19>0,"Review critical/high-risk gaps",IF(D19<1,"Complete assessment","Monitor and improve")) -> Complete assessment
A20: Cyber Privacy | B20: 34 | C20: =COUNTIF('Cyber Privacy'!$H$5:$H$38,"N/A")+COUNTIF('Cyber Privacy'!$H$5:$H$38,"0")+COUNTIF('Cyber Privacy'!$H$5:$H$38,"1")+COUNTIF('Cyber Privacy'!$H$5:$H$38,"2")+COUNTIF('Cyber Privacy'!$H$5:$H$38,"3")+COUNTIF('Cyber Privacy'!$H$5:$H$38,"4")+COUNTIF('Cyber Privacy'!$H$5:$H$38,"5") -> 0 | D20: =IFERROR(C20/B20,0) -> 0 | E20: =SUM('Cyber Privacy'!$I$5:$I$38) -> 0 | F20: =SUM('Cyber Privacy'!$J$5:$J$38) -> 0 | G20: =IFERROR(E20/F20,0) -> 0 | H20: =G20*5 -> 0 | I20: =SUM('Cyber Privacy'!$K$5:$K$38) -> 0 | J20: =COUNTIF('Cyber Privacy'!$L$5:$L$38,"Critical") -> 0 | K20: =COUNTIF('Cyber Privacy'!$L$5:$L$38,"High") -> 0 | L20: =COUNTIF('Cyber Privacy'!$L$5:$L$38,"Medium") -> 0 | M20: =COUNTIF('Cyber Privacy'!$L$5:$L$38,"Low") -> 0 | N20: =COUNTIF('Cyber Privacy'!$L$5:$L$38,"Resilient") -> 0 | O20: =IF(J20+K20>0,"Review critical/high-risk gaps",IF(D20<1,"Complete assessment","Monitor and improve")) -> Complete assessment
A21: Quality Portfolio | B21: 20 | C21: =COUNTIF('Quality Portfolio'!$H$5:$H$24,"N/A")+COUNTIF('Quality Portfolio'!$H$5:$H$24,"0")+COUNTIF('Quality Portfolio'!$H$5:$H$24,"1")+COUNTIF('Quality Portfolio'!$H$5:$H$24,"2")+COUNTIF('Quality Portfolio'!$H$5:$H$24,"3")+COUNTIF('Quality Portfolio'!$H$5:$H$24,"4")+COUNTIF('Quality Portfolio'!$H$5:$H$24,"5") -> 0 | D21: =IFERROR(C21/B21,0) -> 0 | E21: =SUM('Quality Portfolio'!$I$5:$I$24) -> 0 | F21: =SUM('Quality Portfolio'!$J$5:$J$24) -> 0 | G21: =IFERROR(E21/F21,0) -> 0 | H21: =G21*5 -> 0 | I21: =SUM('Quality Portfolio'!$K$5:$K$24) -> 0 | J21: =COUNTIF('Quality Portfolio'!$L$5:$L$24,"Critical") -> 0 | K21: =COUNTIF('Quality Portfolio'!$L$5:$L$24,"High") -> 0 | L21: =COUNTIF('Quality Portfolio'!$L$5:$L$24,"Medium") -> 0 | M21: =COUNTIF('Quality Portfolio'!$L$5:$L$24,"Low") -> 0 | N21: =COUNTIF('Quality Portfolio'!$L$5:$L$24,"Resilient") -> 0 | O21: =IF(J21+K21>0,"Review critical/high-risk gaps",IF(D21<1,"Complete assessment","Monitor and improve")) -> Complete assessment
Q40: Crisis scenario | R40: Primary diagnostic tabs | S40: Typical management output
Q41: War / security crisis | R41: Company Geography; Physical Safety; HR Workforce; Supply Chain; IT Cloud DR | S41: Employee safety map; site recovery plan; relocation options; logistics fallback; remote operations plan
Q42: Physical site loss | R42: Physical Safety; Delivery Ops; Manufacturing MES; IT Cloud DR; Business Systems | S42: Alternative site plan; production/service transfer plan; insurance/evidence package; recovery sequencing
Q43: Cyberattack / ransomware | R43: Cyber Privacy; IT Cloud DR; Business Systems; Legal Risk; Marketing Comms | S43: Incident response plan; isolation and restore runbook; notification workflow; customer communication pack
Q44: Cloud / SaaS outage | R44: IT Cloud DR; Business Systems; Data BI AI; Sales CRM | S44: Cloud/SaaS dependency map; RTO/RPO gaps; backup/export strategy; failover exercise
Q45: Supplier / logistics disruption | R45: Supply Chain; Finance Procurement; Manufacturing MES; Delivery Ops | S45: Critical supplier map; alternate suppliers; inventory buffer model; customer allocation rules
Q46: Energy / utilities outage | R46: Physical Safety; Manufacturing MES; IT Cloud DR; Delivery Ops | S46: Backup power/fuel plan; utility dependency map; minimum viable operations
Q47: Financial liquidity crisis | R47: Finance Procurement; Strategy GTM; Sales CRM; Governance Crisis | S47: Cash-flow stress test; payment priority rules; revenue defense plan; emergency budget actions
Q48: Demand shock | R48: Strategy GTM; Sales CRM; Marketing Comms; Finance Procurement | S48: ICP/offering review; pipeline stress test; pricing response; market pivot options
Q49: Pandemic / health crisis | R49: HR Workforce; Physical Safety; IT Cloud DR; Delivery Ops | S49: Remote operating model; absence plan; health protocols; minimum staffing
Q50: Regulatory / legal shock | R50: Legal Risk; Data BI AI; Cyber Privacy; Finance Procurement | S50: Compliance gap map; contract/legal exposure; data/privacy remediation plan
Q51: Reputation crisis | R51: Marketing Comms; Sales CRM; Legal Risk; Cyber Privacy | S51: Crisis communication playbook; customer notification plan; spokesperson matrix
Q52: Natural disaster / climate event | R52: Physical Safety; Supply Chain; HR Workforce; Delivery Ops | S52: Site risk map; emergency supplies; alternate routes; employee notification
A55: Initiative roadmap summary
A56: Metric | B56: Value | C56: How it is calculated | D56: Action
A57: Primary strategy | B57: ='Strategy Selection'!$B$6 | C57: Top-ranked strategy from Strategy Selection. | D57: Use as portfolio theme.
A58: Selected crisis | B58: ='Crisis Simulator'!$B$4 -> War / security crisis | C58: Scenario selected in Crisis Simulator. | D58: Review if scenario changed.
A59: Active / triggered initiatives | B59: ='Initiatives Roadmap'!$E$5 -> 0 | C59: Initiatives ranked into 0-90 days through 6-12 months. | D59: Start with top 10.
A60: Top WSJF | B60: ='Initiatives Roadmap'!$G$5 | C60: Highest WSJF across initiative library. | D60: Use for first wave.
A61: 0-90 days initiatives | B61: ='Initiatives Roadmap'!$H$5 -> 0 | C61: Roadmap wave based on rank and WSJF. | D61: Assign owners.
...

Sheet Heatmaps
A1: Crisis and Risk Heatmaps
A2: Visual heatmaps to help executives see which domains are most exposed to selected crisis scenarios, risk categories and roadmap workload. Values recalculate when the questionnaire, crisis scenario or industry template changes.
A4: Selected industry | B4: ='Company Profile'!$B$9 -> IT Services | C4: Selected crisis | D4: ='Crisis Simulator'!$B$4 -> War / security crisis | E4: Severity | F4: ='Crisis Simulator'!$B$5 -> 3
A5: Primary strategy | B5: ='Strategy Selection'!$B$6 | C5: Business resilience score | D5: =Dashboard!$B$31 -> 0 | E5: Active risks | F5: ='Risk Summary'!$A$5 -> 0
A8: Heatmap 1. Domain vs crisis scenario exposure
A9: Domain | B9: War / security crisis | C9: Physical site loss | D9: Cyberattack / ransomware | E9: Cloud / SaaS outage | F9: Supplier / logistics disruption | G9: Energy / utilities outage | H9: Financial liquidity crisis | I9: Demand shock | J9: Pandemic / health crisis | K9: Regulatory / legal shock | L9: Reputation crisis
A10: Company Geography | B10: =IFERROR(SUMIFS(_TECH_Crisis_Model!$D:$D,_TECH_Crisis_Model!$A:$A,B$9,_TECH_Crisis_Model!$B:$B,$A10),"") -> 1.6 | C10: =IFERROR(SUMIFS(_TECH_Crisis_Model!$D:$D,_TECH_Crisis_Model!$A:$A,C$9,_TECH_Crisis_Model!$B:$B,$A10),"") -> 1.3 | D10: =IFERROR(SUMIFS(_TECH_Crisis_Model!$D:$D,_TECH_Crisis_Model!$A:$A,D$9,_TECH_Crisis_Model!$B:$B,$A10),"") -> 1 | E10: =IFERROR(SUMIFS(_TECH_Crisis_Model!$D:$D,_TECH_Crisis_Model!$A:$A,E$9,_TECH_Crisis_Model!$B:$B,$A10),"") -> 1 | F10: =IFERROR(SUMIFS(_TECH_Crisis_Model!$D:$D,_TECH_Crisis_Model!$A:$A,F$9,_TECH_Crisis_Model!$B:$B,$A10),"") -> 1.3 | G10: =IFERROR(SUMIFS(_TECH_Crisis_Model!$D:$D,_TECH_Crisis_Model!$A:$A,G$9,_TECH_Crisis_Model!$B:$B,$A10),"") -> 1 | H10: =IFERROR(SUMIFS(_TECH_Crisis_Model!$D:$D,_TECH_Crisis_Model!$A:$A,H$9,_TECH_Crisis_Model!$B:$B,$A10),"") -> 1 | I10: =IFERROR(SUMIFS(_TECH_Crisis_Model!$D:$D,_TECH_Crisis_Model!$A:$A,I$9,_TECH_Crisis_Model!$B:$B,$A10),"") -> 1 | ... L10: =IFERROR(SUMIFS(_TECH_Crisis_Model!$D:$D,_TECH_Crisis_Model!$A:$A,L$9,_TECH_Crisis_Model!$B:$B,$A10),"") -> 1
A11: Strategy GTM | B11: =IFERROR(SUMIFS(_TECH_Crisis_Model!$D:$D,_TECH_Crisis_Model!$A:$A,B$9,_TECH_Crisis_Model!$B:$B,$A11),"") -> 1 | C11: =IFERROR(SUMIFS(_TECH_Crisis_Model!$D:$D,_TECH_Crisis_Model!$A:$A,C$9,_TECH_Crisis_Model!$B:$B,$A11),"") -> 1 | D11: =IFERROR(SUMIFS(_TECH_Crisis_Model!$D:$D,_TECH_Crisis_Model!$A:$A,D$9,_TECH_Crisis_Model!$B:$B,$A11),"") -> 1 | E11: =IFERROR(SUMIFS(_TECH_Crisis_Model!$D:$D,_TECH_Crisis_Model!$A:$A,E$9,_TECH_Crisis_Model!$B:$B,$A11),"") -> 1 | F11: =IFERROR(SUMIFS(_TECH_Crisis_Model!$D:$D,_TECH_Crisis_Model!$A:$A,F$9,_TECH_Crisis_Model!$B:$B,$A11),"") -> 1.2 | G11: =IFERROR(SUMIFS(_TECH_Crisis_Model!$D:$D,_TECH_Crisis_Model!$A:$A,G$9,_TECH_Crisis_Model!$B:$B,$A11),"") -> 1 | H11: =IFERROR(SUMIFS(_TECH_Crisis_Model!$D:$D,_TECH_Crisis_Model!$A:$A,H$9,_TECH_Crisis_Model!$B:$B,$A11),"") -> 1.8 | I11: =IFERROR(SUMIFS(_TECH_Crisis_Model!$D:$D,_TECH_Crisis_Model!$A:$A,I$9,_TECH_Crisis_Model!$B:$B,$A11),"") -> 2 | ... L11: =IFERROR(SUMIFS(_TECH_Crisis_Model!$D:$D,_TECH_Crisis_Model!$A:$A,L$9,_TECH_Crisis_Model!$B:$B,$A11),"") -> 1.3
A12: Governance Crisis | B12: =IFERROR(SUMIFS(_TECH_Crisis_Model!$D:$D,_TECH_Crisis_Model!$A:$A,B$9,_TECH_Crisis_Model!$B:$B,$A12),"") -> 1.4 | C12: =IFERROR(SUMIFS(_TECH_Crisis_Model!$D:$D,_TECH_Crisis_Model!$A:$A,C$9,_TECH_Crisis_Model!$B:$B,$A12),"") -> 1 | D12: =IFERROR(SUMIFS(_TECH_Crisis_Model!$D:$D,_TECH_Crisis_Model!$A:$A,D$9,_TECH_Crisis_Model!$B:$B,$A12),"") -> 1.2 | E12: =IFERROR(SUMIFS(_TECH_Crisis_Model!$D:$D,_TECH_Crisis_Model!$A:$A,E$9,_TECH_Crisis_Model!$B:$B,$A12),"") -> 1 | F12: =IFERROR(SUMIFS(_TECH_Crisis_Model!$D:$D,_TECH_Crisis_Model!$A:$A,F$9,_TECH_Crisis_Model!$B:$B,$A12),"") -> 1 | G12: =IFERROR(SUMIFS(_TECH_Crisis_Model!$D:$D,_TECH_Crisis_Model!$A:$A,G$9,_TECH_Crisis_Model!$B:$B,$A12),"") -> 1 | H12: =IFERROR(SUMIFS(_TECH_Crisis_Model!$D:$D,_TECH_Crisis_Model!$A:$A,H$9,_TECH_Crisis_Model!$B:$B,$A12),"") -> 1.4 | I12: =IFERROR(SUMIFS(_TECH_Crisis_Model!$D:$D,_TECH_Crisis_Model!$A:$A,I$9,_TECH_Crisis_Model!$B:$B,$A12),"") -> 1 | ... L12: =IFERROR(SUMIFS(_TECH_Crisis_Model!$D:$D,_TECH_Crisis_Model!$A:$A,L$9,_TECH_Crisis_Model!$B:$B,$A12),"") -> 1.5
A13: HR Workforce | B13: =IFERROR(SUMIFS(_TECH_Crisis_Model!$D:$D,_TECH_Crisis_Model!$A:$A,B$9,_TECH_Crisis_Model!$B:$B,$A13),"") -> 1.8 | C13: =IFERROR(SUMIFS(_TECH_Crisis_Model!$D:$D,_TECH_Crisis_Model!$A:$A,C$9,_TECH_Crisis_Model!$B:$B,$A13),"") -> 1.3 | D13: =IFERROR(SUMIFS(_TECH_Crisis_Model!$D:$D,_TECH_Crisis_Model!$A:$A,D$9,_TECH_Crisis_Model!$B:$B,$A13),"") -> 1 | E13: =IFERROR(SUMIFS(_TECH_Crisis_Model!$D:$D,_TECH_Crisis_Model!$A:$A,E$9,_TECH_Crisis_Model!$B:$B,$A13),"") -> 1 | F13: =IFERROR(SUMIFS(_TECH_Crisis_Model!$D:$D,_TECH_Crisis_Model!$A:$A,F$9,_TECH_Crisis_Model!$B:$B,$A13),"") -> 1 | G13: =IFERROR(SUMIFS(_TECH_Crisis_Model!$D:$D,_TECH_Crisis_Model!$A:$A,G$9,_TECH_Crisis_Model!$B:$B,$A13),"") -> 1.2 | H13: =IFERROR(SUMIFS(_TECH_Crisis_Model!$D:$D,_TECH_Crisis_Model!$A:$A,H$9,_TECH_Crisis_Model!$B:$B,$A13),"") -> 1.2 | I13: =IFERROR(SUMIFS(_TECH_Crisis_Model!$D:$D,_TECH_Crisis_Model!$A:$A,I$9,_TECH_Crisis_Model!$B:$B,$A13),"") -> 1 | ... L13: =IFERROR(SUMIFS(_TECH_Crisis_Model!$D:$D,_TECH_Crisis_Model!$A:$A,L$9,_TECH_Crisis_Model!$B:$B,$A13),"") -> 1.2
A14: Finance Procurement | B14: =IFERROR(SUMIFS(_TECH_Crisis_Model!$D:$D,_TECH_Crisis_Model!$A:$A,B$9,_TECH_Crisis_Model!$B:$B,$A14),"") -> 1.3 | C14: =IFERROR(SUMIFS(_TECH_Crisis_Model!$D:$D,_TECH_Crisis_Model!$A:$A,C$9,_TECH_Crisis_Model!$B:$B,$A14),"") -> 1 | D14: =IFERROR(SUMIFS(_TECH_Crisis_Model!$D:$D,_TECH_Crisis_Model!$A:$A,D$9,_TECH_Crisis_Model!$B:$B,$A14),"") -> 1.3 | E14: =IFERROR(SUMIFS(_TECH_Crisis_Model!$D:$D,_TECH_Crisis_Model!$A:$A,E$9,_TECH_Crisis_Model!$B:$B,$A14),"") -> 1.2 | F14: =IFERROR(SUMIFS(_TECH_Crisis_Model!$D:$D,_TECH_Crisis_Model!$A:$A,F$9,_TECH_Crisis_Model!$B:$B,$A14),"") -> 1.4 | G14: =IFERROR(SUMIFS(_TECH_Crisis_Model!$D:$D,_TECH_Crisis_Model!$A:$A,G$9,_TECH_Crisis_Model!$B:$B,$A14),"") -> 1 | H14: =IFERROR(SUMIFS(_TECH_Crisis_Model!$D:$D,_TECH_Crisis_Model!$A:$A,H$9,_TECH_Crisis_Model!$B:$B,$A14),"") -> 2 | I14: =IFERROR(SUMIFS(_TECH_Crisis_Model!$D:$D,_TECH_Crisis_Model!$A:$A,I$9,_TECH_Crisis_Model!$B:$B,$A14),"") -> 1.5 | ... L14: =IFERROR(SUMIFS(_TECH_Crisis_Model!$D:$D,_TECH_Crisis_Model!$A:$A,L$9,_TECH_Crisis_Model!$B:$B,$A14),"") -> 1
A15: Legal Risk | B15: =IFERROR(SUMIFS(_TECH_Crisis_Model!$D:$D,_TECH_Crisis_Model!$A:$A,B$9,_TECH_Crisis_Model!$B:$B,$A15),"") -> 1.4 | C15: =IFERROR(SUMIFS(_TECH_Crisis_Model!$D:$D,_TECH_Crisis_Model!$A:$A,C$9,_TECH_Crisis_Model!$B:$B,$A15),"") -> 1 | D15: =IFERROR(SUMIFS(_TECH_Crisis_Model!$D:$D,_TECH_Crisis_Model!$A:$A,D$9,_TECH_Crisis_Model!$B:$B,$A15),"") -> 1.5 | E15: =IFERROR(SUMIFS(_TECH_Crisis_Model!$D:$D,_TECH_Crisis_Model!$A:$A,E$9,_TECH_Crisis_Model!$B:$B,$A15),"") -> 1 | F15: =IFERROR(SUMIFS(_TECH_Crisis_Model!$D:$D,_TECH_Crisis_Model!$A:$A,F$9,_TECH_Crisis_Model!$B:$B,$A15),"") -> 1 | G15: =IFERROR(SUMIFS(_TECH_Crisis_Model!$D:$D,_TECH_Crisis_Model!$A:$A,G$9,_TECH_Crisis_Model!$B:$B,$A15),"") -> 1 | H15: =IFERROR(SUMIFS(_TECH_Crisis_Model!$D:$D,_TECH_Crisis_Model!$A:$A,H$9,_TECH_Crisis_Model!$B:$B,$A15),"") -> 1 | I15: =IFERROR(SUMIFS(_TECH_Crisis_Model!$D:$D,_TECH_Crisis_Model!$A:$A,I$9,_TECH_Crisis_Model!$B:$B,$A15),"") -> 1 | ... L15: =IFERROR(SUMIFS(_TECH_Crisis_Model!$D:$D,_TECH_Crisis_Model!$A:$A,L$9,_TECH_Crisis_Model!$B:$B,$A15),"") -> 1.4
A16: Physical Safety | B16: =IFERROR(SUMIFS(_TECH_Crisis_Model!$D:$D,_TECH_Crisis_Model!$A:$A,B$9,_TECH_Crisis_Model!$B:$B,$A16),"") -> 2 | C16: =IFERROR(SUMIFS(_TECH_Crisis_Model!$D:$D,_TECH_Crisis_Model!$A:$A,C$9,_TECH_Crisis_Model!$B:$B,$A16),"") -> 2 | D16: =IFERROR(SUMIFS(_TECH_Crisis_Model!$D:$D,_TECH_Crisis_Model!$A:$A,D$9,_TECH_Crisis_Model!$B:$B,$A16),"") -> 1 | E16: =IFERROR(SUMIFS(_TECH_Crisis_Model!$D:$D,_TECH_Crisis_Model!$A:$A,E$9,_TECH_Crisis_Model!$B:$B,$A16),"") -> 1 | F16: =IFERROR(SUMIFS(_TECH_Crisis_Model!$D:$D,_TECH_Crisis_Model!$A:$A,F$9,_TECH_Crisis_Model!$B:$B,$A16),"") -> 1.2 | G16: =IFERROR(SUMIFS(_TECH_Crisis_Model!$D:$D,_TECH_Crisis_Model!$A:$A,G$9,_TECH_Crisis_Model!$B:$B,$A16),"") -> 1.8 | H16: =IFERROR(SUMIFS(_TECH_Crisis_Model!$D:$D,_TECH_Crisis_Model!$A:$A,H$9,_TECH_Crisis_Model!$B:$B,$A16),"") -> 1 | I16: =IFERROR(SUMIFS(_TECH_Crisis_Model!$D:$D,_TECH_Crisis_Model!$A:$A,I$9,_TECH_Crisis_Model!$B:$B,$A16),"") -> 1 | ... L16: =IFERROR(SUMIFS(_TECH_Crisis_Model!$D:$D,_TECH_Crisis_Model!$A:$A,L$9,_TECH_Crisis_Model!$B:$B,$A16),"") -> 1
A17: Delivery Ops | B17: =IFERROR(SUMIFS(_TECH_Crisis_Model!$D:$D,_TECH_Crisis_Model!$A:$A,B$9,_TECH_Crisis_Model!$B:$B,$A17),"") -> 1.7 | C17: =IFERROR(SUMIFS(_TECH_Crisis_Model!$D:$D,_TECH_Crisis_Model!$A:$A,C$9,_TECH_Crisis_Model!$B:$B,$A17),"") -> 1.7 | D17: =IFERROR(SUMIFS(_TECH_Crisis_Model!$D:$D,_TECH_Crisis_Model!$A:$A,D$9,_TECH_Crisis_Model!$B:$B,$A17),"") -> 1 | E17: =IFERROR(SUMIFS(_TECH_Crisis_Model!$D:$D,_TECH_Crisis_Model!$A:$A,E$9,_TECH_Crisis_Model!$B:$B,$A17),"") -> 1.4 | F17: =IFERROR(SUMIFS(_TECH_Crisis_Model!$D:$D,_TECH_Crisis_Model!$A:$A,F$9,_TECH_Crisis_Model!$B:$B,$A17),"") -> 1.7 | G17: =IFERROR(SUMIFS(_TECH_Crisis_Model!$D:$D,_TECH_Crisis_Model!$A:$A,G$9,_TECH_Crisis_Model!$B:$B,$A17),"") -> 1.4 | H17: =IFERROR(SUMIFS(_TECH_Crisis_Model!$D:$D,_TECH_Crisis_Model!$A:$A,H$9,_TECH_Crisis_Model!$B:$B,$A17),"") -> 1 | I17: =IFERROR(SUMIFS(_TECH_Crisis_Model!$D:$D,_TECH_Crisis_Model!$A:$A,I$9,_TECH_Crisis_Model!$B:$B,$A17),"") -> 1.2 | ... L17: =IFERROR(SUMIFS(_TECH_Crisis_Model!$D:$D,_TECH_Crisis_Model!$A:$A,L$9,_TECH_Crisis_Model!$B:$B,$A17),"") -> 1
A18: Supply Chain | B18: =IFERROR(SUMIFS(_TECH_Crisis_Model!$D:$D,_TECH_Crisis_Model!$A:$A,B$9,_TECH_Crisis_Model!$B:$B,$A18),"") -> 1.7 | C18: =IFERROR(SUMIFS(_TECH_Crisis_Model!$D:$D,_TECH_Crisis_Model!$A:$A,C$9,_TECH_Crisis_Model!$B:$B,$A18),"") -> 1.5 | D18: =IFERROR(SUMIFS(_TECH_Crisis_Model!$D:$D,_TECH_Crisis_Model!$A:$A,D$9,_TECH_Crisis_Model!$B:$B,$A18),"") -> 1 | E18: =IFERROR(SUMIFS(_TECH_Crisis_Model!$D:$D,_TECH_Crisis_Model!$A:$A,E$9,_TECH_Crisis_Model!$B:$B,$A18),"") -> 1 | F18: =IFERROR(SUMIFS(_TECH_Crisis_Model!$D:$D,_TECH_Crisis_Model!$A:$A,F$9,_TECH_Crisis_Model!$B:$B,$A18),"") -> 2 | G18: =IFERROR(SUMIFS(_TECH_Crisis_Model!$D:$D,_TECH_Crisis_Model!$A:$A,G$9,_TECH_Crisis_Model!$B:$B,$A18),"") -> 1.3 | H18: =IFERROR(SUMIFS(_TECH_Crisis_Model!$D:$D,_TECH_Crisis_Model!$A:$A,H$9,_TECH_Crisis_Model!$B:$B,$A18),"") -> 1 | I18: =IFERROR(SUMIFS(_TECH_Crisis_Model!$D:$D,_TECH_Crisis_Model!$A:$A,I$9,_TECH_Crisis_Model!$B:$B,$A18),"") -> 1 | ... L18: =IFERROR(SUMIFS(_TECH_Crisis_Model!$D:$D,_TECH_Crisis_Model!$A:$A,L$9,_TECH_Crisis_Model!$B:$B,$A18),"") -> 1
A19: Manufacturing MES | B19: =IFERROR(SUMIFS(_TECH_Crisis_Model!$D:$D,_TECH_Crisis_Model!$A:$A,B$9,_TECH_Crisis_Model!$B:$B,$A19),"") -> 1.4 | C19: =IFERROR(SUMIFS(_TECH_Crisis_Model!$D:$D,_TECH_Crisis_Model!$A:$A,C$9,_TECH_Crisis_Model!$B:$B,$A19),"") -> 1.9 | D19: =IFERROR(SUMIFS(_TECH_Crisis_Model!$D:$D,_TECH_Crisis_Model!$A:$A,D$9,_TECH_Crisis_Model!$B:$B,$A19),"") -> 1 | E19: =IFERROR(SUMIFS(_TECH_Crisis_Model!$D:$D,_TECH_Crisis_Model!$A:$A,E$9,_TECH_Crisis_Model!$B:$B,$A19),"") -> 1 | F19: =IFERROR(SUMIFS(_TECH_Crisis_Model!$D:$D,_TECH_Crisis_Model!$A:$A,F$9,_TECH_Crisis_Model!$B:$B,$A19),"") -> 1.8 | G19: =IFERROR(SUMIFS(_TECH_Crisis_Model!$D:$D,_TECH_Crisis_Model!$A:$A,G$9,_TECH_Crisis_Model!$B:$B,$A19),"") -> 2 | H19: =IFERROR(SUMIFS(_TECH_Crisis_Model!$D:$D,_TECH_Crisis_Model!$A:$A,H$9,_TECH_Crisis_Model!$B:$B,$A19),"") -> 1 | I19: =IFERROR(SUMIFS(_TECH_Crisis_Model!$D:$D,_TECH_Crisis_Model!$A:$A,I$9,_TECH_Crisis_Model!$B:$B,$A19),"") -> 1 | ... L19: =IFERROR(SUMIFS(_TECH_Crisis_Model!$D:$D,_TECH_Crisis_Model!$A:$A,L$9,_TECH_Crisis_Model!$B:$B,$A19),"") -> 1
A20: Sales CRM | B20: =IFERROR(SUMIFS(_TECH_Crisis_Model!$D:$D,_TECH_Crisis_Model!$A:$A,B$9,_TECH_Crisis_Model!$B:$B,$A20),"") -> 1 | C20: =IFERROR(SUMIFS(_TECH_Crisis_Model!$D:$D,_TECH_Crisis_Model!$A:$A,C$9,_TECH_Crisis_Model!$B:$B,$A20),"") -> 1 | D20: =IFERROR(SUMIFS(_TECH_Crisis_Model!$D:$D,_TECH_Crisis_Model!$A:$A,D$9,_TECH_Crisis_Model!$B:$B,$A20),"") -> 1.2 | E20: =IFERROR(SUMIFS(_TECH_Crisis_Model!$D:$D,_TECH_Crisis_Model!$A:$A,E$9,_TECH_Crisis_Model!$B:$B,$A20),"") -> 1.5 | F20: =IFERROR(SUMIFS(_TECH_Crisis_Model!$D:$D,_TECH_Crisis_Model!$A:$A,F$9,_TECH_Crisis_Model!$B:$B,$A20),"") -> 1 | G20: =IFERROR(SUMIFS(_TECH_Crisis_Model!$D:$D,_TECH_Crisis_Model!$A:$A,G$9,_TECH_Crisis_Model!$B:$B,$A20),"") -> 1 | H20: =IFERROR(SUMIFS(_TECH_Crisis_Model!$D:$D,_TECH_Crisis_Model!$A:$A,H$9,_TECH_Crisis_Model!$B:$B,$A20),"") -> 1.6 | I20: =IFERROR(SUMIFS(_TECH_Crisis_Model!$D:$D,_TECH_Crisis_Model!$A:$A,I$9,_TECH_Crisis_Model!$B:$B,$A20),"") -> 1.9 | ... L20: =IFERROR(SUMIFS(_TECH_Crisis_Model!$D:$D,_TECH_Crisis_Model!$A:$A,L$9,_TECH_Crisis_Model!$B:$B,$A20),"") -> 1.8
A21: Marketing Comms | B21: =IFERROR(SUMIFS(_TECH_Crisis_Model!$D:$D,_TECH_Crisis_Model!$A:$A,B$9,_TECH_Crisis_Model!$B:$B,$A21),"") -> 1.2 | C21: =IFERROR(SUMIFS(_TECH_Crisis_Model!$D:$D,_TECH_Crisis_Model!$A:$A,C$9,_TECH_Crisis_Model!$B:$B,$A21),"") -> 1 | D21: =IFERROR(SUMIFS(_TECH_Crisis_Model!$D:$D,_TECH_Crisis_Model!$A:$A,D$9,_TECH_Crisis_Model!$B:$B,$A21),"") -> 1.4 | E21: =IFERROR(SUMIFS(_TECH_Crisis_Model!$D:$D,_TECH_Crisis_Model!$A:$A,E$9,_TECH_Crisis_Model!$B:$B,$A21),"") -> 1.3 | F21: =IFERROR(SUMIFS(_TECH_Crisis_Model!$D:$D,_TECH_Crisis_Model!$A:$A,F$9,_TECH_Crisis_Model!$B:$B,$A21),"") -> 1 | G21: =IFERROR(SUMIFS(_TECH_Crisis_Model!$D:$D,_TECH_Crisis_Model!$A:$A,G$9,_TECH_Crisis_Model!$B:$B,$A21),"") -> 1 | H21: =IFERROR(SUMIFS(_TECH_Crisis_Model!$D:$D,_TECH_Crisis_Model!$A:$A,H$9,_TECH_Crisis_Model!$B:$B,$A21),"") -> 1 | I21: =IFERROR(SUMIFS(_TECH_Crisis_Model!$D:$D,_TECH_Crisis_Model!$A:$A,I$9,_TECH_Crisis_Model!$B:$B,$A21),"") -> 1.7 | ... L21: =IFERROR(SUMIFS(_TECH_Crisis_Model!$D:$D,_TECH_Crisis_Model!$A:$A,L$9,_TECH_Crisis_Model!$B:$B,$A21),"") -> 2
... A26: Quality Portfolio | B26: =IFERROR(SUMIFS(_TECH_Crisis_Model!$D:$D,_TECH_Crisis_Model!$A:$A,B$9,_TECH_Crisis_Model!$B:$B,$A26),"") -> 1 | C26: =IFERROR(SUMIFS(_TECH_Crisis_Model!$D:$D,_TECH_Crisis_Model!$A:$A,C$9,_TECH_Crisis_Model!$B:$B,$A26),"") -> 1 | D26: =IFERROR(SUMIFS(_TECH_Crisis_Model!$D:$D,_TECH_Crisis_Model!$A:$A,D$9,_TECH_Crisis_Model!$B:$B,$A26),"") -> 1 | E26: =IFERROR(SUMIFS(_TECH_Crisis_Model!$D:$D,_TECH_Crisis_Model!$A:$A,E$9,_TECH_Crisis_Model!$B:$B,$A26),"") -> 1 | F26: =IFERROR(SUMIFS(_TECH_Crisis_Model!$D:$D,_TECH_Crisis_Model!$A:$A,F$9,_TECH_Crisis_Model!$B:$B,$A26),"") -> 1 | G26: =IFERROR(SUMIFS(_TECH_Crisis_Model!$D:$D,_TECH_Crisis_Model!$A:$A,G$9,_TECH_Crisis_Model!$B:$B,$A26),"") -> 1 | H26: =IFERROR(SUMIFS(_TECH_Crisis_Model!$D:$D,_TECH_Crisis_Model!$A:$A,H$9,_TECH_Crisis_Model!$B:$B,$A26),"") -> 1.3 | I26: =IFERROR(SUMIFS(_TECH_Crisis_Model!$D:$D,_TECH_Crisis_Model!$A:$A,I$9,_TECH_Crisis_Model!$B:$B,$A26),"") -> 1.2 | ... L26: =IFERROR(SUMIFS(_TECH_Crisis_Model!$D:$D,_TECH_Crisis_Model!$A:$A,L$9,_TECH_Crisis_Model!$B:$B,$A26),"") -> 1
A30: Heatmap 2. Domain vs active risk category score
A31: Domain | B31: Geographic, entity and market exposure | C31: Strategic and go-to-market resilience | D31: Crisis governance and decision-making | E31: People, critical roles and knowledge continuity | F31: Financial control and procurement resilience | G31: Legal, compliance and contractual exposure | H31: Physical safety, security and facility resilience | I31: Delivery, service continuity and operational execution | J31: Supply chain, logistics and supplier continuity | K31: Manufacturing, MES and production continuity | L31: Revenue, sales pipeline and CRM continuity | M31: Market communication and reputation resilience
A32: Company Geography | B32: =IFERROR(ROUND(AVERAGEIFS('Risk Summary'!$L$8:$L$414,'Risk Summary'!$B$8:$B$414,"Yes",'Risk Summary'!$C$8:$C$414,$A32,'Risk Summary'!$F$8:$F$414,B$31),1),"") | C32: =IFERROR(ROUND(AVERAGEIFS('Risk Summary'!$L$8:$L$414,'Risk Summary'!$B$8:$B$414,"Yes",'Risk Summary'!$C$8:$C$414,$A32,'Risk Summary'!$F$8:$F$414,C$31),1),"") | D32: =IFERROR(ROUND(AVERAGEIFS('Risk Summary'!$L$8:$L$414,'Risk Summary'!$B$8:$B$414,"Yes",'Risk Summary'!$C$8:$C$414,$A32,'Risk Summary'!$F$8:$F$414,D$31),1),"") | E32: =IFERROR(ROUND(AVERAGEIFS('Risk Summary'!$L$8:$L$414,'Risk Summary'!$B$8:$B$414,"Yes",'Risk Summary'!$C$8:$C$414,$A32,'Risk Summary'!$F$8:$F$414,E$31),1),"") | F32: =IFERROR(ROUND(AVERAGEIFS('Risk Summary'!$L$8:$L$414,'Risk Summary'!$B$8:$B$414,"Yes",'Risk Summary'!$C$8:$C$414,$A32,'Risk Summary'!$F$8:$F$414,F$31),1),"") | G32: =IFERROR(ROUND(AVERAGEIFS('Risk Summary'!$L$8:$L$414,'Risk Summary'!$B$8:$B$414,"Yes",'Risk Summary'!$C$8:$C$414,$A32,'Risk Summary'!$F$8:$F$414,G$31),1),"") | H32: =IFERROR(ROUND(AVERAGEIFS('Risk Summary'!$L$8:$L$414,'Risk Summary'!$B$8:$B$414,"Yes",'Risk Summary'!$C$8:$C$414,$A32,'Risk Summary'!$F$8:$F$414,H$31),1),"") | I32: =IFERROR(ROUND(AVERAGEIFS('Risk Summary'!$L$8:$L$414,'Risk Summary'!$B$8:$B$414,"Yes",'Risk Summary'!$C$8:$C$414,$A32,'Risk Summary'!$F$8:$F$414,I$31),1),"") | ... M32: =IFERROR(ROUND(AVERAGEIFS('Risk Summary'!$L$8:$L$414,'Risk Summary'!$B$8:$B$414,"Yes",'Risk Summary'!$C$8:$C$414,$A32,'Risk Summary'!$F$8:$F$414,M$31),1),"")
A33: Strategy GTM | B33: =IFERROR(ROUND(AVERAGEIFS('Risk Summary'!$L$8:$L$414,'Risk Summary'!$B$8:$B$414,"Yes",'Risk Summary'!$C$8:$C$414,$A33,'Risk Summary'!$F$8:$F$414,B$31),1),"") | C33: =IFERROR(ROUND(AVERAGEIFS('Risk Summary'!$L$8:$L$414,'Risk Summary'!$B$8:$B$414,"Yes",'Risk Summary'!$C$8:$C$414,$A33,'Risk Summary'!$F$8:$F$414,C$31),1),"") | D33: =IFERROR(ROUND(AVERAGEIFS('Risk Summary'!$L$8:$L$414,'Risk Summary'!$B$8:$B$414,"Yes",'Risk Summary'!$C$8:$C$414,$A33,'Risk Summary'!$F$8:$F$414,D$31),1),"") | E33: =IFERROR(ROUND(AVERAGEIFS('Risk Summary'!$L$8:$L$414,'Risk Summary'!$B$8:$B$414,"Yes",'Risk Summary'!$C$8:$C$414,$A33,'Risk Summary'!$F$8:$F$414,E$31),1),"") | F33: =IFERROR(ROUND(AVERAGEIFS('Risk Summary'!$L$8:$L$414,'Risk Summary'!$B$8:$B$414,"Yes",'Risk Summary'!$C$8:$C$414,$A33,'Risk Summary'!$F$8:$F$414,F$31),1),"") | G33: =IFERROR(ROUND(AVERAGEIFS('Risk Summary'!$L$8:$L$414,'Risk Summary'!$B$8:$B$414,"Yes",'Risk Summary'!$C$8:$C$414,$A33,'Risk Summary'!$F$8:$F$414,G$31),1),"") | H33: =IFERROR(ROUND(AVERAGEIFS('Risk Summary'!$L$8:$L$414,'Risk Summary'!$B$8:$B$414,"Yes",'Risk Summary'!$C$8:$C$414,$A33,'Risk Summary'!$F$8:$F$414,H$31),1),"") | I33: =IFERROR(ROUND(AVERAGEIFS('Risk Summary'!$L$8:$L$414,'Risk Summary'!$B$8:$B$414,"Yes",'Risk Summary'!$C$8:$C$414,$A33,'Risk Summary'!$F$8:$F$414,I$31),1),"") | ... M33: =IFERROR(ROUND(AVERAGEIFS('Risk Summary'!$L$8:$L$414,'Risk Summary'!$B$8:$B$414,"Yes",'Risk Summary'!$C$8:$C$414,$A33,'Risk Summary'!$F$8:$F$414,M$31),1),"")
A34: Governance Crisis | B34: =IFERROR(ROUND(AVERAGEIFS('Risk Summary'!$L$8:$L$414,'Risk Summary'!$B$8:$B$414,"Yes",'Risk Summary'!$C$8:$C$414,$A34,'Risk Summary'!$F$8:$F$414,B$31),1),"") | C34: =IFERROR(ROUND(AVERAGEIFS('Risk Summary'!$L$8:$L$414,'Risk Summary'!$B$8:$B$414,"Yes",'Risk Summary'!$C$8:$C$414,$A34,'Risk Summary'!$F$8:$F$414,C$31),1),"") | D34: =IFERROR(ROUND(AVERAGEIFS('Risk Summary'!$L$8:$L$414,'Risk Summary'!$B$8:$B$414,"Yes",'Risk Summary'!$C$8:$C$414,$A34,'Risk Summary'!$F$8:$F$414,D$31),1),"") | E34: =IFERROR(ROUND(AVERAGEIFS('Risk Summary'!$L$8:$L$414,'Risk Summary'!$B$8:$B$414,"Yes",'Risk Summary'!$C$8:$C$414,$A34,'Risk Summary'!$F$8:$F$414,E$31),1),"") | F34: =IFERROR(ROUND(AVERAGEIFS('Risk Summary'!$L$8:$L$414,'Risk Summary'!$B$8:$B$414,"Yes",'Risk Summary'!$C$8:$C$414,$A34,'Risk Summary'!$F$8:$F$414,F$31),1),"") | G34: =IFERROR(ROUND(AVERAGEIFS('Risk Summary'!$L$8:$L$414,'Risk Summary'!$B$8:$B$414,"Yes",'Risk Summary'!$C$8:$C$414,$A34,'Risk Summary'!$F$8:$F$414,G$31),1),"") | H34: =IFERROR(ROUND(AVERAGEIFS('Risk Summary'!$L$8:$L$414,'Risk Summary'!$B$8:$B$414,"Yes",'Risk Summary'!$C$8:$C$414,$A34,'Risk Summary'!$F$8:$F$414,H$31),1),"") | I34: =IFERROR(ROUND(AVERAGEIFS('Risk Summary'!$L$8:$L$414,'Risk Summary'!$B$8:$B$414,"Yes",'Risk Summary'!$C$8:$C$414,$A34,'Risk Summary'!$F$8:$F$414,I$31),1),"") | ... M34: =IFERROR(ROUND(AVERAGEIFS('Risk Summary'!$L$8:$L$414,'Risk Summary'!$B$8:$B$414,"Yes",'Risk Summary'!$C$8:$C$414,$A34,'Risk Summary'!$F$8:$F$414,M$31),1),"")
A35: HR Workforce | B35: =IFERROR(ROUND(AVERAGEIFS('Risk Summary'!$L$8:$L$414,'Risk Summary'!$B$8:$B$414,"Yes",'Risk Summary'!$C$8:$C$414,$A35,'Risk Summary'!$F$8:$F$414,B$31),1),"") | C35: =IFERROR(ROUND(AVERAGEIFS('Risk Summary'!$L$8:$L$414,'Risk Summary'!$B$8:$B$414,"Yes",'Risk Summary'!$C$8:$C$414,$A35,'Risk Summary'!$F$8:$F$414,C$31),1),"") | D35: =IFERROR(ROUND(AVERAGEIFS('Risk Summary'!$L$8:$L$414,'Risk Summary'!$B$8:$B$414,"Yes",'Risk Summary'!$C$8:$C$414,$A35,'Risk Summary'!$F$8:$F$414,D$31),1),"") | E35: =IFERROR(ROUND(AVERAGEIFS('Risk Summary'!$L$8:$L$414,'Risk Summary'!$B$8:$B$414,"Yes",'Risk Summary'!$C$8:$C$414,$A35,'Risk Summary'!$F$8:$F$414,E$31),1),"") | F35: =IFERROR(ROUND(AVERAGEIFS('Risk Summary'!$L$8:$L$414,'Risk Summary'!$B$8:$B$414,"Yes",'Risk Summary'!$C$8:$C$414,$A35,'Risk Summary'!$F$8:$F$414,F$31),1),"") | G35: =IFERROR(ROUND(AVERAGEIFS('Risk Summary'!$L$8:$L$414,'Risk Summary'!$B$8:$B$414,"Yes",'Risk Summary'!$C$8:$C$414,$A35,'Risk Summary'!$F$8:$F$414,G$31),1),"") | H35: =IFERROR(ROUND(AVERAGEIFS('Risk Summary'!$L$8:$L$414,'Risk Summary'!$B$8:$B$414,"Yes",'Risk Summary'!$C$8:$C$414,$A35,'Risk Summary'!$F$8:$F$414,H$31),1),"") | I35: =IFERROR(ROUND(AVERAGEIFS('Risk Summary'!$L$8:$L$414,'Risk Summary'!$B$8:$B$414,"Yes",'Risk Summary'!$C$8:$C$414,$A35,'Risk Summary'!$F$8:$F$414,I$31),1),"") | ... M35: =IFERROR(ROUND(AVERAGEIFS('Risk Summary'!$L$8:$L$414,'Risk Summary'!$B$8:$B$414,"Yes",'Risk Summary'!$C$8:$C$414,$A35,'Risk Summary'!$F$8:$F$414,M$31),1),"")
A36: Finance Procurement | B36: =IFERROR(ROUND(AVERAGEIFS('Risk Summary'!$L$8:$L$414,'Risk Summary'!$B$8:$B$414,"Yes",'Risk Summary'!$C$8:$C$414,$A36,'Risk Summary'!$F$8:$F$414,B$31),1),"") | C36: =IFERROR(ROUND(AVERAGEIFS('Risk Summary'!$L$8:$L$414,'Risk Summary'!$B$8:$B$414,"Yes",'Risk Summary'!$C$8:$C$414,$A36,'Risk Summary'!$F$8:$F$414,C$31),1),"") | D36: =IFERROR(ROUND(AVERAGEIFS('Risk Summary'!$L$8:$L$414,'Risk Summary'!$B$8:$B$414,"Yes",'Risk Summary'!$C$8:$C$414,$A36,'Risk Summary'!$F$8:$F$414,D$31),1),"") | E36: =IFERROR(ROUND(AVERAGEIFS('Risk Summary'!$L$8:$L$414,'Risk Summary'!$B$8:$B$414,"Yes",'Risk Summary'!$C$8:$C$414,$A36,'Risk Summary'!$F$8:$F$414,E$31),1),"") | F36: =IFERROR(ROUND(AVERAGEIFS('Risk Summary'!$L$8:$L$414,'Risk Summary'!$B$8:$B$414,"Yes",'Risk Summary'!$C$8:$C$414,$A36,'Risk Summary'!$F$8:$F$414,F$31),1),"") | G36: =IFERROR(ROUND(AVERAGEIFS('Risk Summary'!$L$8:$L$414,'Risk Summary'!$B$8:$B$414,"Yes",'Risk Summary'!$C$8:$C$414,$A36,'Risk Summary'!$F$8:$F$414,G$31),1),"") | H36: =IFERROR(ROUND(AVERAGEIFS('Risk Summary'!$L$8:$L$414,'Risk Summary'!$B$8:$B$414,"Yes",'Risk Summary'!$C$8:$C$414,$A36,'Risk Summary'!$F$8:$F$414,H$31),1),"") | I36: =IFERROR(ROUND(AVERAGEIFS('Risk Summary'!$L$8:$L$414,'Risk Summary'!$B$8:$B$414,"Yes",'Risk Summary'!$C$8:$C$414,$A36,'Risk Summary'!$F$8:$F$414,I$31),1),"") | ... M36: =IFERROR(ROUND(AVERAGEIFS('Risk Summary'!$L$8:$L$414,'Risk Summary'!$B$8:$B$414,"Yes",'Risk Summary'!$C$8:$C$414,$A36,'Risk Summary'!$F$8:$F$414,M$31),1),"")
A37: Legal Risk | B37: =IFERROR(ROUND(AVERAGEIFS('Risk Summary'!$L$8:$L$414,'Risk Summary'!$B$8:$B$414,"Yes",'Risk Summary'!$C$8:$C$414,$A37,'Risk Summary'!$F$8:$F$414,B$31),1),"") | C37: =IFERROR(ROUND(AVERAGEIFS('Risk Summary'!$L$8:$L$414,'Risk Summary'!$B$8:$B$414,"Yes",'Risk Summary'!$C$8:$C$414,$A37,'Risk Summary'!$F$8:$F$414,C$31),1),"") | D37: =IFERROR(ROUND(AVERAGEIFS('Risk Summary'!$L$8:$L$414,'Risk Summary'!$B$8:$B$414,"Yes",'Risk Summary'!$C$8:$C$414,$A37,'Risk Summary'!$F$8:$F$414,D$31),1),"") | E37: =IFERROR(ROUND(AVERAGEIFS('Risk Summary'!$L$8:$L$414,'Risk Summary'!$B$8:$B$414,"Yes",'Risk Summary'!$C$8:$C$414,$A37,'Risk Summary'!$F$8:$F$414,E$31),1),"") | F37: =IFERROR(ROUND(AVERAGEIFS('Risk Summary'!$L$8:$L$414,'Risk Summary'!$B$8:$B$414,"Yes",'Risk Summary'!$C$8:$C$414,$A37,'Risk Summary'!$F$8:$F$414,F$31),1),"") | G37: =IFERROR(ROUND(AVERAGEIFS('Risk Summary'!$L$8:$L$414,'Risk Summary'!$B$8:$B$414,"Yes",'Risk Summary'!$C$8:$C$414,$A37,'Risk Summary'!$F$8:$F$414,G$31),1),"") | H37: =IFERROR(ROUND(AVERAGEIFS('Risk Summary'!$L$8:$L$414,'Risk Summary'!$B$8:$B$414,"Yes",'Risk Summary'!$C$8:$C$414,$A37,'Risk Summary'!$F$8:$F$414,H$31),1),"") | I37: =IFERROR(ROUND(AVERAGEIFS('Risk Summary'!$L$8:$L$414,'Risk Summary'!$B$8:$B$414,"Yes",'Risk Summary'!$C$8:$C$414,$A37,'Risk Summary'!$F$8:$F$414,I$31),1),"") | ... M37: =IFERROR(ROUND(AVERAGEIFS('Risk Summary'!$L$8:$L$414,'Risk Summary'!$B$8:$B$414,"Yes",'Risk Summary'!$C$8:$C$414,$A37,'Risk Summary'!$F$8:$F$414,M$31),1),"")
A38: Physical Safety | B38: =IFERROR(ROUND(AVERAGEIFS('Risk Summary'!$L$8:$L$414,'Risk Summary'!$B$8:$B$414,"Yes",'Risk Summary'!$C$8:$C$414,$A38,'Risk Summary'!$F$8:$F$414,B$31),1),"") | C38: =IFERROR(ROUND(AVERAGEIFS('Risk Summary'!$L$8:$L$414,'Risk Summary'!$B$8:$B$414,"Yes",'Risk Summary'!$C$8:$C$414,$A38,'Risk Summary'!$F$8:$F$414,C$31),1),"") | D38: =IFERROR(ROUND(AVERAGEIFS('Risk Summary'!$L$8:$L$414,'Risk Summary'!$B$8:$B$414,"Yes",'Risk Summary'!$C$8:$C$414,$A38,'Risk Summary'!$F$8:$F$414,D$31),1),"") | E38: =IFERROR(ROUND(AVERAGEIFS('Risk Summary'!$L$8:$L$414,'Risk Summary'!$B$8:$B$414,"Yes",'Risk Summary'!$C$8:$C$414,$A38,'Risk Summary'!$F$8:$F$414,E$31),1),"") | F38: =IFERROR(ROUND(AVERAGEIFS('Risk Summary'!$L$8:$L$414,'Risk Summary'!$B$8:$B$414,"Yes",'Risk Summary'!$C$8:$C$414,$A38,'Risk Summary'!$F$8:$F$414,F$31),1),"") | G38: =IFERROR(ROUND(AVERAGEIFS('Risk Summary'!$L$8:$L$414,'Risk Summary'!$B$8:$B$414,"Yes",'Risk Summary'!$C$8:$C$414,$A38,'Risk Summary'!$F$8:$F$414,G$31),1),"") | H38: =IFERROR(ROUND(AVERAGEIFS('Risk Summary'!$L$8:$L$414,'Risk Summary'!$B$8:$B$414,"Yes",'Risk Summary'!$C$8:$C$414,$A38,'Risk Summary'!$F$8:$F$414,H$31),1),"") | I38: =IFERROR(ROUND(AVERAGEIFS('Risk Summary'!$L$8:$L$414,'Risk Summary'!$B$8:$B$414,"Yes",'Risk Summary'!$C$8:$C$414,$A38,'Risk Summary'!$F$8:$F$414,I$31),1),"") | ... M38: =IFERROR(ROUND(AVERAGEIFS('Risk Summary'!$L$8:$L$414,'Risk Summary'!$B$8:$B$414,"Yes",'Risk Summary'!$C$8:$C$414,$A38,'Risk Summary'!$F$8:$F$414,M$31),1),"")
A39: Delivery Ops | B39: =IFERROR(ROUND(AVERAGEIFS('Risk Summary'!$L$8:$L$414,'Risk Summary'!$B$8:$B$414,"Yes",'Risk Summary'!$C$8:$C$414,$A39,'Risk Summary'!$F$8:$F$414,B$31),1),"") | C39: =IFERROR(ROUND(AVERAGEIFS('Risk Summary'!$L$8:$L$414,'Risk Summary'!$B$8:$B$414,"Yes",'Risk Summary'!$C$8:$C$414,$A39,'Risk Summary'!$F$8:$F$414,C$31),1),"") | D39: =IFERROR(ROUND(AVERAGEIFS('Risk Summary'!$L$8:$L$414,'Risk Summary'!$B$8:$B$414,"Yes",'Risk Summary'!$C$8:$C$414,$A39,'Risk Summary'!$F$8:$F$414,D$31),1),"") | E39: =IFERROR(ROUND(AVERAGEIFS('Risk Summary'!$L$8:$L$414,'Risk Summary'!$B$8:$B$414,"Yes",'Risk Summary'!$C$8:$C$414,$A39,'Risk Summary'!$F$8:$F$414,E$31),1),"") | F39: =IFERROR(ROUND(AVERAGEIFS('Risk Summary'!$L$8:$L$414,'Risk Summary'!$B$8:$B$414,"Yes",'Risk Summary'!$C$8:$C$414,$A39,'Risk Summary'!$F$8:$F$414,F$31),1),"") | G39: =IFERROR(ROUND(AVERAGEIFS('Risk Summary'!$L$8:$L$414,'Risk Summary'!$B$8:$B$414,"Yes",'Risk Summary'!$C$8:$C$414,$A39,'Risk Summary'!$F$8:$F$414,G$31),1),"") | H39: =IFERROR(ROUND(AVERAGEIFS('Risk Summary'!$L$8:$L$414,'Risk Summary'!$B$8:$B$414,"Yes",'Risk Summary'!$C$8:$C$414,$A39,'Risk Summary'!$F$8:$F$414,H$31),1),"") | I39: =IFERROR(ROUND(AVERAGEIFS('Risk Summary'!$L$8:$L$414,'Risk Summary'!$B$8:$B$414,"Yes",'Risk Summary'!$C$8:$C$414,$A39,'Risk Summary'!$F$8:$F$414,I$31),1),"") | ... M39: =IFERROR(ROUND(AVERAGEIFS('Risk Summary'!$L$8:$L$414,'Risk Summary'!$B$8:$B$414,"Yes",'Risk Summary'!$C$8:$C$414,$A39,'Risk Summary'!$F$8:$F$414,M$31),1),"")
A40: Supply Chain | B40: =IFERROR(ROUND(AVERAGEIFS('Risk Summary'!$L$8:$L$414,'Risk Summary'!$B$8:$B$414,"Yes",'Risk Summary'!$C$8:$C$414,$A40,'Risk Summary'!$F$8:$F$414,B$31),1),"") | C40: =IFERROR(ROUND(AVERAGEIFS('Risk Summary'!$L$8:$L$414,'Risk Summary'!$B$8:$B$414,"Yes",'Risk Summary'!$C$8:$C$414,$A40,'Risk Summary'!$F$8:$F$414,C$31),1),"") | D40: =IFERROR(ROUND(AVERAGEIFS('Risk Summary'!$L$8:$L$414,'Risk Summary'!$B$8:$B$414,"Yes",'Risk Summary'!$C$8:$C$414,$A40,'Risk Summary'!$F$8:$F$414,D$31),1),"") | E40: =IFERROR(ROUND(AVERAGEIFS('Risk Summary'!$L$8:$L$414,'Risk Summary'!$B$8:$B$414,"Yes",'Risk Summary'!$C$8:$C$414,$A40,'Risk Summary'!$F$8:$F$414,E$31),1),"") | F40: =IFERROR(ROUND(AVERAGEIFS('Risk Summary'!$L$8:$L$414,'Risk Summary'!$B$8:$B$414,"Yes",'Risk Summary'!$C$8:$C$414,$A40,'Risk Summary'!$F$8:$F$414,F$31),1),"") | G40: =IFERROR(ROUND(AVERAGEIFS('Risk Summary'!$L$8:$L$414,'Risk Summary'!$B$8:$B$414,"Yes",'Risk Summary'!$C$8:$C$414,$A40,'Risk Summary'!$F$8:$F$414,G$31),1),"") | H40: =IFERROR(ROUND(AVERAGEIFS('Risk Summary'!$L$8:$L$414,'Risk Summary'!$B$8:$B$414,"Yes",'Risk Summary'!$C$8:$C$414,$A40,'Risk Summary'!$F$8:$F$414,H$31),1),"") | I40: =IFERROR(ROUND(AVERAGEIFS('Risk Summary'!$L$8:$L$414,'Risk Summary'!$B$8:$B$414,"Yes",'Risk Summary'!$C$8:$C$414,$A40,'Risk Summary'!$F$8:$F$414,I$31),1),"") | ... M40: =IFERROR(ROUND(AVERAGEIFS('Risk Summary'!$L$8:$L$414,'Risk Summary'!$B$8:$B$414,"Yes",'Risk Summary'!$C$8:$C$414,$A40,'Risk Summary'!$F$8:$F$414,M$31),1),"")
A41: Manufacturing MES | B41: =IFERROR(ROUND(AVERAGEIFS('Risk Summary'!$L$8:$L$414,'Risk Summary'!$B$8:$B$414,"Yes",'Risk Summary'!$C$8:$C$414,$A41,'Risk Summary'!$F$8:$F$414,B$31),1),"") | C41: =IFERROR(ROUND(AVERAGEIFS('Risk Summary'!$L$8:$L$414,'Risk Summary'!$B$8:$B$414,"Yes",'Risk Summary'!$C$8:$C$414,$A41,'Risk Summary'!$F$8:$F$414,C$31),1),"") | D41: =IFERROR(ROUND(AVERAGEIFS('Risk Summary'!$L$8:$L$414,'Risk Summary'!$B$8:$B$414,"Yes",'Risk Summary'!$C$8:$C$414,$A41,'Risk Summary'!$F$8:$F$414,D$31),1),"") | E41: =IFERROR(ROUND(AVERAGEIFS('Risk Summary'!$L$8:$L$414,'Risk Summary'!$B$8:$B$414,"Yes",'Risk Summary'!$C$8:$C$414,$A41,'Risk Summary'!$F$8:$F$414,E$31),1),"") | F41: =IFERROR(ROUND(AVERAGEIFS('Risk Summary'!$L$8:$L$414,'Risk Summary'!$B$8:$B$414,"Yes",'Risk Summary'!$C$8:$C$414,$A41,'Risk Summary'!$F$8:$F$414,F$31),1),"") | G41: =IFERROR(ROUND(AVERAGEIFS('Risk Summary'!$L$8:$L$414,'Risk Summary'!$B$8:$B$414,"Yes",'Risk Summary'!$C$8:$C$414,$A41,'Risk Summary'!$F$8:$F$414,G$31),1),"") | H41: =IFERROR(ROUND(AVERAGEIFS('Risk Summary'!$L$8:$L$414,'Risk Summary'!$B$8:$B$414,"Yes",'Risk Summary'!$C$8:$C$414,$A41,'Risk Summary'!$F$8:$F$414,H$31),1),"") | I41: =IFERROR(ROUND(AVERAGEIFS('Risk Summary'!$L$8:$L$414,'Risk Summary'!$B$8:$B$414,"Yes",'Risk Summary'!$C$8:$C$414,$A41,'Risk Summary'!$F$8:$F$414,I$31),1),"") | ... M41: =IFERROR(ROUND(AVERAGEIFS('Risk Summary'!$L$8:$L$414,'Risk Summary'!$B$8:$B$414,"Yes",'Risk Summary'!$C$8:$C$414,$A41,'Risk Summary'!$F$8:$F$414,M$31),1),"")
A42: Sales CRM | B42: =IFERROR(ROUND(AVERAGEIFS('Risk Summary'!$L$8:$L$414,'Risk Summary'!$B$8:$B$414,"Yes",'Risk Summary'!$C$8:$C$414,$A42,'Risk Summary'!$F$8:$F$414,B$31),1),"") | C42: =IFERROR(ROUND(AVERAGEIFS('Risk Summary'!$L$8:$L$414,'Risk Summary'!$B$8:$B$414,"Yes",'Risk Summary'!$C$8:$C$414,$A42,'Risk Summary'!$F$8:$F$414,C$31),1),"") | D42: =IFERROR(ROUND(AVERAGEIFS('Risk Summary'!$L$8:$L$414,'Risk Summary'!$B$8:$B$414,"Yes",'Risk Summary'!$C$8:$C$414,$A42,'Risk Summary'!$F$8:$F$414,D$31),1),"") | E42: =IFERROR(ROUND(AVERAGEIFS('Risk Summary'!$L$8:$L$414,'Risk Summary'!$B$8:$B$414,"Yes",'Risk Summary'!$C$8:$C$414,$A42,'Risk Summary'!$F$8:$F$414,E$31),1),"") | F42: =IFERROR(ROUND(AVERAGEIFS('Risk Summary'!$L$8:$L$414,'Risk Summary'!$B$8:$B$414,"Yes",'Risk Summary'!$C$8:$C$414,$A42,'Risk Summary'!$F$8:$F$414,F$31),1),"") | G42: =IFERROR(ROUND(AVERAGEIFS('Risk Summary'!$L$8:$L$414,'Risk Summary'!$B$8:$B$414,"Yes",'Risk Summary'!$C$8:$C$414,$A42,'Risk Summary'!$F$8:$F$414,G$31),1),"") | H42: =IFERROR(ROUND(AVERAGEIFS('Risk Summary'!$L$8:$L$414,'Risk Summary'!$B$8:$B$414,"Yes",'Risk Summary'!$C$8:$C$414,$A42,'Risk Summary'!$F$8:$F$414,H$31),1),"") | I42: =IFERROR(ROUND(AVERAGEIFS('Risk Summary'!$L$8:$L$414,'Risk Summary'!$B$8:$B$414,"Yes",'Risk Summary'!$C$8:$C$414,$A42,'Risk Summary'!$F$8:$F$414,I$31),1),"") | ... M42: =IFERROR(ROUND(AVERAGEIFS('Risk Summary'!$L$8:$L$414,'Risk Summary'!$B$8:$B$414,"Yes",'Risk Summary'!$C$8:$C$414,$A42,'Risk Summary'!$F$8:$F$414,M$31),1),"")
A43: Marketing Comms | B43: =IFERROR(ROUND(AVERAGEIFS('Risk Summary'!$L$8:$L$414,'Risk Summary'!$B$8:$B$414,"Yes",'Risk Summary'!$C$8:$C$414,$A43,'Risk Summary'!$F$8:$F$414,B$31),1),"") | C43: =IFERROR(ROUND(AVERAGEIFS('Risk Summary'!$L$8:$L$414,'Risk Summary'!$B$8:$B$414,"Yes",'Risk Summary'!$C$8:$C$414,$A43,'Risk Summary'!$F$8:$F$414,C$31),1),"") | D43: =IFERROR(ROUND(AVERAGEIFS('Risk Summary'!$L$8:$L$414,'Risk Summary'!$B$8:$B$414,"Yes",'Risk Summary'!$C$8:$C$414,$A43,'Risk Summary'!$F$8:$F$414,D$31),1),"") | E43: =IFERROR(ROUND(AVERAGEIFS('Risk Summary'!$L$8:$L$414,'Risk Summary'!$B$8:$B$414,"Yes",'Risk Summary'!$C$8:$C$414,$A43,'Risk Summary'!$F$8:$F$414,E$31),1),"") | F43: =IFERROR(ROUND(AVERAGEIFS('Risk Summary'!$L$8:$L$414,'Risk Summary'!$B$8:$B$414,"Yes",'Risk Summary'!$C$8:$C$414,$A43,'Risk Summary'!$F$8:$F$414,F$31),1),"") | G43: =IFERROR(ROUND(AVERAGEIFS('Risk Summary'!$L$8:$L$414,'Risk Summary'!$B$8:$B$414,"Yes",'Risk Summary'!$C$8:$C$414,$A43,'Risk Summary'!$F$8:$F$414,G$31),1),"") | H43: =IFERROR(ROUND(AVERAGEIFS('Risk Summary'!$L$8:$L$414,'Risk Summary'!$B$8:$B$414,"Yes",'Risk Summary'!$C$8:$C$414,$A43,'Risk Summary'!$F$8:$F$414,H$31),1),"") | I43: =IFERROR(ROUND(AVERAGEIFS('Risk Summary'!$L$8:$L$414,'Risk Summary'!$B$8:$B$414,"Yes",'Risk Summary'!$C$8:$C$414,$A43,'Risk Summary'!$F$8:$F$414,I$31),1),"") | ... M43: =IFERROR(ROUND(AVERAGEIFS('Risk Summary'!$L$8:$L$414,'Risk Summary'!$B$8:$B$414,"Yes",'Risk Summary'!$C$8:$C$414,$A43,'Risk Summary'!$F$8:$F$414,M$31),1),"")
... A48: Quality Portfolio | B48: =IFERROR(ROUND(AVERAGEIFS('Risk Summary'!$L$8:$L$414,'Risk Summary'!$B$8:$B$414,"Yes",'Risk Summary'!$C$8:$C$414,$A48,'Risk Summary'!$F$8:$F$414,B$31),1),"") | C48: =IFERROR(ROUND(AVERAGEIFS('Risk Summary'!$L$8:$L$414,'Risk Summary'!$B$8:$B$414,"Yes",'Risk Summary'!$C$8:$C$414,$A48,'Risk Summary'!$F$8:$F$414,C$31),1),"") | D48: =IFERROR(ROUND(AVERAGEIFS('Risk Summary'!$L$8:$L$414,'Risk Summary'!$B$8:$B$414,"Yes",'Risk Summary'!$C$8:$C$414,$A48,'Risk Summary'!$F$8:$F$414,D$31),1),"") | E48: =IFERROR(ROUND(AVERAGEIFS('Risk Summary'!$L$8:$L$414,'Risk Summary'!$B$8:$B$414,"Yes",'Risk Summary'!$C$8:$C$414,$A48,'Risk Summary'!$F$8:$F$414,E$31),1),"") | F48: =IFERROR(ROUND(AVERAGEIFS('Risk Summary'!$L$8:$L$414,'Risk Summary'!$B$8:$B$414,"Yes",'Risk Summary'!$C$8:$C$414,$A48,'Risk Summary'!$F$8:$F$414,F$31),1),"") | G48: =IFERROR(ROUND(AVERAGEIFS('Risk Summary'!$L$8:$L$414,'Risk Summary'!$B$8:$B$414,"Yes",'Risk Summary'!$C$8:$C$414,$A48,'Risk Summary'!$F$8:$F$414,G$31),1),"") | H48: =IFERROR(ROUND(AVERAGEIFS('Risk Summary'!$L$8:$L$414,'Risk Summary'!$B$8:$B$414,"Yes",'Risk Summary'!$C$8:$C$414,$A48,'Risk Summary'!$F$8:$F$414,H$31),1),"") | I48: =IFERROR(ROUND(AVERAGEIFS('Risk Summary'!$L$8:$L$414,'Risk Summary'!$B$8:$B$414,"Yes",'Risk Summary'!$C$8:$C$414,$A48,'Risk Summary'!$F$8:$F$414,I$31),1),"") | ... M48: =IFERROR(ROUND(AVERAGEIFS('Risk Summary'!$L$8:$L$414,'Risk Summary'!$B$8:$B$414,"Yes",'Risk Summary'!$C$8:$C$414,$A48,'Risk Summary'!$F$8:$F$414,M$31),1),"")
A52: Heatmap 3. Top 20 prioritized initiatives vs timeline
